<sdf version='1.7'>
  <world name='default'>
    <light name='sun' type='directional'>
      <cast_shadows>1</cast_shadows>
      <pose>0 0 10 0 -0 0</pose>
      <diffuse>0.8 0.8 0.8 1</diffuse>
      <specular>0.2 0.2 0.2 1</specular>
      <attenuation>
        <range>1000</range>
        <constant>0.9</constant>
        <linear>0.01</linear>
        <quadratic>0.001</quadratic>
      </attenuation>
      <direction>-0.5 0.1 -0.9</direction>
      <spot>
        <inner_angle>0</inner_angle>
        <outer_angle>0</outer_angle>
        <falloff>0</falloff>
      </spot>
    </light>
    <model name='ground_plane'>
      <static>1</static>
      <link name='link'>
        <collision name='collision'>
          <geometry>
            <plane>
              <normal>0 0 1</normal>
              <size>100 100</size>
            </plane>
          </geometry>
          <surface>
            <contact>
              <collide_bitmask>65535</collide_bitmask>
              <ode/>
            </contact>
            <friction>
              <ode>
                <mu>100</mu>
                <mu2>50</mu2>
              </ode>
              <torsional>
                <ode/>
              </torsional>
            </friction>
            <bounce/>
          </surface>
          <max_contacts>10</max_contacts>
        </collision>
        <visual name='visual'>
          <cast_shadows>0</cast_shadows>
          <geometry>
            <plane>
              <normal>0 0 1</normal>
              <size>100 100</size>
            </plane>
          </geometry>
          <material>
            <script>
              <uri>file://media/materials/scripts/gazebo.material</uri>
              <name>Gazebo/Grey</name>
            </script>
          </material>
        </visual>
        <self_collide>0</self_collide>
        <enable_wind>0</enable_wind>
        <kinematic>0</kinematic>
      </link>
    </model>
    <gravity>0 0 -9.8</gravity>
    <magnetic_field>6e-06 2.3e-05 -4.2e-05</magnetic_field>
    <atmosphere type='adiabatic'/>
    <physics name='default_physics' default='0' type='ode'>
      <max_step_size>0.001</max_step_size>
      <real_time_factor>1</real_time_factor>
      <real_time_update_rate>1000</real_time_update_rate>
    </physics>
    <scene>
      <ambient>0.4 0.4 0.4 1</ambient>
      <background>0.7 0.7 0.7 1</background>
      <shadows>1</shadows>
    </scene>
    <audio>
      <device>default</device>
    </audio>
    <wind/>
    <spherical_coordinates>
      <surface_model>EARTH_WGS84</surface_model>
      <latitude_deg>0</latitude_deg>
      <longitude_deg>0</longitude_deg>
      <elevation>0</elevation>
      <heading_deg>0</heading_deg>
    </spherical_coordinates>
    <state world_name='default'>
      <sim_time>2335 350000000</sim_time>
      <real_time>81 222772625</real_time>
      <wall_time>1695502498 95240538</wall_time>
      <iterations>71421</iterations>
      <model name='apple'>
        <pose>-0.141777 0.496344 1.01539 0.00362 -0.00059 0.010467</pose>
        <scale>1 1 1</scale>
        <link name='link'>
          <pose>-0.141777 0.496344 1.01539 0.00362 -0.00059 0.010467</pose>
          <velocity>0 0 0 0 -0 0</velocity>
          <acceleration>0.080438 -0.045391 14.3992 -1.80184 0.993272 2.90532</acceleration>
          <wrench>2e-05 -1.1e-05 0.003551 0 -0 0</wrench>
        </link>
      </model>
      <model name='banana'>
        <pose>-0.08901 0.704981 1.01571 -0.011588 -0.031451 -0.72891</pose>
        <scale>1 1 1</scale>
        <link name='link'>
          <pose>-0.08901 0.704981 1.01571 -0.011588 -0.031451 -0.72891</pose>
          <velocity>0 0 0 0 -0 0</velocity>
          <acceleration>0 0 -9.8 4.1e-05 2.3e-05 -0.000803</acceleration>
          <wrench>0 0 -0.01681 0 -0 0</wrench>
        </link>
      </model>
      <model name='dropbox'>
        <pose>0.3 -0.5 1.21 0 -0 1.5794</pose>
        <scale>1 1 1</scale>
        <link name='link_0'>
          <pose>0.3 -0.5 1.21 0 -0 0.01067</pose>
          <velocity>0 0 0 0 -0 0</velocity>
          <acceleration>0 0 0 0 -0 0</acceleration>
          <wrench>0 0 0 0 -0 0</wrench>
        </link>
      </model>
      <model name='dropbox_0'>
        <pose>-0.3 -0.5 1.21 0 -0 1.5794</pose>
        <scale>1 1 1</scale>
        <link name='link_0'>
          <pose>-0.3 -0.5 1.21 0 -0 0.01067</pose>
          <velocity>0 0 0 0 -0 0</velocity>
          <acceleration>0 0 0 0 -0 0</acceleration>
          <wrench>0 0 0 0 -0 0</wrench>
        </link>
      </model>
      <model name='ground_plane'>
        <pose>0 0 0 0 -0 0</pose>
        <scale>1 1 1</scale>
        <link name='link'>
          <pose>0 0 0 0 -0 0</pose>
          <velocity>0 0 0 0 -0 0</velocity>
          <acceleration>0 0 0 0 -0 0</acceleration>
          <wrench>0 0 0 0 -0 0</wrench>
        </link>
      </model>
      <model name='nist_elevated_floor_120'>
        <pose>0.005735 -0.482404 0 0 -0 0</pose>
        <scale>1 1 1</scale>
        <link name='nist_elevated_floor_120'>
          <pose>0.005735 -0.482404 0 0 -0 0</pose>
          <velocity>0 0 0 0 -0 0</velocity>
          <acceleration>0 0 0 0 -0 0</acceleration>
          <wrench>0 0 0 0 -0 0</wrench>
        </link>
      </model>
      <model name='phillips_screwdriver'>
        <pose>0.173259 0.564306 1.00292 0.804082 0.331608 -1.82957</pose>
        <scale>1.5 1.5 1.5</scale>
        <link name='link'>
          <pose>0.173259 0.564306 1.00292 0.804082 0.331608 -1.82957</pose>
          <velocity>0 0 0 0 -0 0</velocity>
          <acceleration>0 0 -9.8 -2e-06 -1.3e-05 -0.000262</acceleration>
          <wrench>0 0 -0.000755 0 -0 0</wrench>
        </link>
      </model>
      <model name='robot'>
        <pose>-0 0 1.21 0 -0 0</pose>
        <scale>1 1 1</scale>
        <link name='base_link'>
          <pose>-0 0 1.21 2.8e-05 -1e-06 -0</pose>
          <velocity>-2e-06 4e-06 6e-06 0.005402 -0.000188 0</velocity>
          <acceleration>-0.004363 0.007423 0.012054 -1.76288 -0.383974 -3.1e-05</acceleration>
          <wrench>-0.017452 0.029693 0.048218 0 -0 0</wrench>
        </link>
        <link name='camera_rgb_frame'>
          <pose>0 0.2 2.01 0 1.25 1.5708</pose>
          <velocity>0 0 -0 0 -0 0</velocity>
          <acceleration>0 0 0 0 -0 0</acceleration>
          <wrench>0 0 0 0 -0 0</wrench>
        </link>
        <link name='forearm_link'>
          <pose>0.423157 0.016644 1.25983 -3.14068 1.44466 -3.1395</pose>
          <velocity>0.000625 0.000448 0.007054 -0.022395 -0.007002 0.005763</velocity>
          <acceleration>1.58913 2.24644 16.8227 -1.23408 -1.35566 -2.17055</acceleration>
          <wrench>3.61528 5.11066 38.2717 0 -0 0</wrench>
        </link>
        <link name='robotiq_85_left_finger_tip_link'>
          <pose>0.849069 0.311064 1.09261 0.602444 0.000166 1.5581</pose>
          <velocity>0.005558 -0.0042 -0.001978 -0.054828 -0.032919 -0.030095</velocity>
          <acceleration>5.55752 -4.20027 -1.978 0.247045 -1.06464 1.07186</acceleration>
          <wrench>0.108677 -0.082136 -0.03868 0 -0 0</wrench>
        </link>
        <link name='robotiq_85_left_inner_knuckle_link'>
          <pose>0.825201 0.261658 1.10859 0.592919 -0.113748 1.72523</pose>
          <velocity>0.002974 -0.002695 -0.000393 -0.055187 -0.033031 -0.030047</velocity>
          <acceleration>2.97371 -2.69494 -0.392554 -0.489116 0.312578 1.53374</acceleration>
          <wrench>0.089065 -0.080716 -0.011757 0 -0 0</wrench>
        </link>
        <link name='robotiq_85_left_knuckle_link'>
          <pose>0.839866 0.254955 1.09845 0.592873 -0.113922 1.72532</pose>
          <velocity>0.003095 -0.003561 0.000442 0.058877 -0.037829 0.099819</velocity>
          <acceleration>6.735 -3.85924 2.14619 0.964511 0.724594 -1.48306</acceleration>
          <wrench>0.308463 -0.176753 0.098295 0 -0 0</wrench>
        </link>
        <link name='robotiq_85_right_finger_tip_link'>
          <pose>0.781673 0.311926 1.13896 -2.53917 0.000161 1.5581</pose>
          <velocity>0.003912 6e-06 -0.004249 -0.052903 -0.038295 -0.029256</velocity>
          <acceleration>3.91181 0.005649 -4.24862 -2.35044 -1.21967 -1.24035</acceleration>
          <wrench>0.076495 0.00011 -0.083082 0 -0 0</wrench>
        </link>
        <link name='robotiq_85_right_inner_knuckle_link'>
          <pose>0.804274 0.261926 1.12299 -2.54875 0.114069 1.39096</pose>
          <velocity>0.002473 -0.001417 -0.001072 -0.05326 -0.03818 -0.02921</velocity>
          <acceleration>2.47266 -1.41746 -1.07167 -1.60911 0.299011 -0.410941</acceleration>
          <wrench>0.074059 -0.042454 -0.032097 0 -0 0</wrench>
        </link>
        <link name='robotiq_85_right_knuckle_link'>
          <pose>0.789443 0.2556 1.13313 -2.54872 0.11399 1.39091</pose>
          <velocity>0.001887 -0.000527 -0.001305 -0.034227 -0.03448 -0.036855</velocity>
          <acceleration>1.57619 0.412098 -1.89503 -2.78282 1.1243 1.72971</acceleration>
          <wrench>0.07219 0.018874 -0.086793 0 -0 0</wrench>
        </link>
        <link name='shoulder_link'>
          <pose>0 -3e-06 1.29916 -5.1e-05 5e-06 0.001186</pose>
          <velocity>3.7e-05 -0.000584 -7e-06 -0.009813 0.000608 0.004708</velocity>
          <acceleration>0.075155 -1.16834 -0.014968 -0.769313 1.2274 -2.8123</acceleration>
          <wrench>0.278074 -4.32288 -0.055381 0 -0 0</wrench>
        </link>
        <link name='upper_arm_link'>
          <pose>-0.00016 0.135847 1.29915 -3.14065 1.4781 -3.13947</pose>
          <velocity>-0.000539 -0.000604 -0.001519 -0.016947 -0.0145 0.004584</velocity>
          <acceleration>-0.374173 0.561558 5.03754 -0.410063 1.28443 -2.5851</acceleration>
          <wrench>-3.14043 4.71316 42.2801 0 -0 0</wrench>
        </link>
        <link name='wrist_1_link'>
          <pose>0.81229 0.017102 1.21047 -3.14146 0.006601 -3.1404</pose>
          <velocity>0.000896 0.001671 0.007964 -0.025477 0.032749 0.006613</velocity>
          <acceleration>0.524316 3.61622 11.2007 2.6218 0.493455 -2.08447</acceleration>
          <wrench>0.639141 4.40817 13.6537 0 -0 0</wrench>
        </link>
        <link name='wrist_2_link'>
          <pose>0.812179 0.110098 1.21046 -3.14153 0.006603 3.12885</pose>
          <velocity>0.000272 0.000944 0.005455 -0.030058 0.032705 -0.036543</velocity>
          <acceleration>-5.68334 -3.56749 10.8734 -0.539805 0.579124 -0.364368</acceleration>
          <wrench>-6.92799 -4.34877 13.2547 0 -0 0</wrench>
        </link>
        <link name='wrist_3_link'>
          <pose>0.812804 0.110084 1.1158 -3.1415 -0.602436 3.1288</pose>
          <velocity>-0.002822 -0.001954 0.004571 -0.03343 -0.035256 -0.036554</velocity>
          <acceleration>0.465271 -3.68199 3.54681 1.2596 -0.81976 -0.230994</acceleration>
          <wrench>0.461945 -3.65567 3.52145 0 -0 0</wrench>
        </link>
      </model>
      <model name='table'>
        <pose>1.8e-05 0.659275 0 0 -0 0</pose>
        <scale>1 1 1</scale>
        <link name='link'>
          <pose>1.8e-05 0.659275 0 0 -0 0</pose>
          <velocity>0 0 0 0 -0 0</velocity>
          <acceleration>0 0 0 0 -0 0</acceleration>
          <wrench>0 0 0 0 -0 0</wrench>
        </link>
      </model>
      <light name='sun'>
        <pose>0 0 10 0 -0 0</pose>
      </light>
    </state>
    <gui fullscreen='0'>
      <camera name='user_camera'>
        <pose>0.154059 1.26572 2.70757 0 1.16974 -1.66326</pose>
        <view_controller>orbit</view_controller>
        <projection_type>perspective</projection_type>
      </camera>
    </gui>
    <model name='nist_elevated_floor_120'>
      <static>1</static>
      <link name='nist_elevated_floor_120'>
        <pose>0 0 0 0 -0 0</pose>
        <collision name='collision'>
          <geometry>
            <mesh>
              <uri>model://nist_elevated_floor_120/meshes/nist_elevated_floor_120.dae</uri>
              <scale>1 1 1</scale>
            </mesh>
          </geometry>
          <max_contacts>10</max_contacts>
          <surface>
            <contact>
              <ode/>
            </contact>
            <bounce/>
            <friction>
              <torsional>
                <ode/>
              </torsional>
              <ode/>
            </friction>
          </surface>
        </collision>
        <visual name='visual'>
          <geometry>
            <mesh>
              <uri>model://nist_elevated_floor_120/meshes/nist_elevated_floor_120.dae</uri>
              <scale>1 1 1</scale>
            </mesh>
          </geometry>
        </visual>
        <self_collide>0</self_collide>
        <enable_wind>0</enable_wind>
        <kinematic>0</kinematic>
      </link>
      <pose>0.297914 -0.687027 0 0 -0 0</pose>
    </model>
    <model name='table'>
      <static>1</static>
      <link name='link'>
        <collision name='surface'>
          <pose>0 0 1 0 -0 0</pose>
          <geometry>
            <box>
              <size>1.5 0.8 0.03</size>
            </box>
          </geometry>
          <surface>
            <friction>
              <ode>
                <mu>0.6</mu>
                <mu2>0.6</mu2>
              </ode>
              <torsional>
                <ode/>
              </torsional>
            </friction>
            <contact>
              <ode/>
            </contact>
            <bounce/>
          </surface>
          <max_contacts>10</max_contacts>
        </collision>
        <visual name='visual1'>
          <pose>0 0 1 0 -0 0</pose>
          <geometry>
            <box>
              <size>1.5 0.8 0.03</size>
            </box>
          </geometry>
          <material>
            <script>
              <uri>file://media/materials/scripts/gazebo.material</uri>
              <name>Gazebo/White</name>
            </script>
          </material>
        </visual>
        <collision name='front_left_leg'>
          <pose>0.68 0.38 0.5 0 -0 0</pose>
          <geometry>
            <cylinder>
              <radius>0.02</radius>
              <length>1</length>
            </cylinder>
          </geometry>
          <max_contacts>10</max_contacts>
          <surface>
            <contact>
              <ode/>
            </contact>
            <bounce/>
            <friction>
              <torsional>
                <ode/>
              </torsional>
              <ode/>
            </friction>
          </surface>
        </collision>
        <visual name='front_left_leg'>
          <pose>0.68 0.38 0.5 0 -0 0</pose>
          <geometry>
            <cylinder>
              <radius>0.02</radius>
              <length>1</length>
            </cylinder>
          </geometry>
          <material>
            <script>
              <uri>file://media/materials/scripts/gazebo.material</uri>
              <name>Gazebo/Grey</name>
            </script>
          </material>
        </visual>
        <collision name='front_right_leg'>
          <pose>0.68 -0.38 0.5 0 -0 0</pose>
          <geometry>
            <cylinder>
              <radius>0.02</radius>
              <length>1</length>
            </cylinder>
          </geometry>
          <max_contacts>10</max_contacts>
          <surface>
            <contact>
              <ode/>
            </contact>
            <bounce/>
            <friction>
              <torsional>
                <ode/>
              </torsional>
              <ode/>
            </friction>
          </surface>
        </collision>
        <visual name='front_right_leg'>
          <pose>0.68 -0.38 0.5 0 -0 0</pose>
          <geometry>
            <cylinder>
              <radius>0.02</radius>
              <length>1</length>
            </cylinder>
          </geometry>
          <material>
            <script>
              <uri>file://media/materials/scripts/gazebo.material</uri>
              <name>Gazebo/Grey</name>
            </script>
          </material>
        </visual>
        <collision name='back_right_leg'>
          <pose>-0.68 -0.38 0.5 0 -0 0</pose>
          <geometry>
            <cylinder>
              <radius>0.02</radius>
              <length>1</length>
            </cylinder>
          </geometry>
          <max_contacts>10</max_contacts>
          <surface>
            <contact>
              <ode/>
            </contact>
            <bounce/>
            <friction>
              <torsional>
                <ode/>
              </torsional>
              <ode/>
            </friction>
          </surface>
        </collision>
        <visual name='back_right_leg'>
          <pose>-0.68 -0.38 0.5 0 -0 0</pose>
          <geometry>
            <cylinder>
              <radius>0.02</radius>
              <length>1</length>
            </cylinder>
          </geometry>
          <material>
            <script>
              <uri>file://media/materials/scripts/gazebo.material</uri>
              <name>Gazebo/Grey</name>
            </script>
          </material>
        </visual>
        <collision name='back_left_leg'>
          <pose>-0.68 0.38 0.5 0 -0 0</pose>
          <geometry>
            <cylinder>
              <radius>0.02</radius>
              <length>1</length>
            </cylinder>
          </geometry>
          <max_contacts>10</max_contacts>
          <surface>
            <contact>
              <ode/>
            </contact>
            <bounce/>
            <friction>
              <torsional>
                <ode/>
              </torsional>
              <ode/>
            </friction>
          </surface>
        </collision>
        <visual name='back_left_leg'>
          <pose>-0.68 0.38 0.5 0 -0 0</pose>
          <geometry>
            <cylinder>
              <radius>0.02</radius>
              <length>1</length>
            </cylinder>
          </geometry>
          <material>
            <script>
              <uri>file://media/materials/scripts/gazebo.material</uri>
              <name>Gazebo/Grey</name>
            </script>
          </material>
        </visual>
        <self_collide>0</self_collide>
        <enable_wind>0</enable_wind>
        <kinematic>0</kinematic>
      </link>
      <pose>0.270759 1.80105 0 0 -0 0</pose>
    </model>
    <model name='dropbox'>
      <link name='link_0'>
        <pose>0 -0 0 0 0 -1.56873</pose>
        <inertial>
          <mass>1</mass>
          <inertia>
            <ixx>0.166667</ixx>
            <ixy>0</ixy>
            <ixz>0</ixz>
            <iyy>0.166667</iyy>
            <iyz>0</iyz>
            <izz>0.166667</izz>
          </inertia>
        </inertial>
        <visual name='visual'>
          <pose>0 0 0 0 -0 0</pose>
          <geometry>
            <mesh>
              <uri>model://dropbox/meshes/dropbox.dae</uri>
              <scale>1 1 1</scale>
            </mesh>
          </geometry>
          <material>
            <lighting>1</lighting>
            <script>
              <uri>file://media/materials/scripts/gazebo.material</uri>
              <name>Gazebo/Green</name>
            </script>
          </material>
          <transparency>0</transparency>
          <cast_shadows>1</cast_shadows>
        </visual>
        <collision name='collision'>
          <laser_retro>0</laser_retro>
          <max_contacts>10</max_contacts>
          <pose>0 0 0 0 -0 0</pose>
          <geometry>
            <mesh>
              <uri>model://dropbox/meshes/dropbox.dae</uri>
              <scale>1 1 1</scale>
            </mesh>
          </geometry>
          <surface>
            <friction>
              <ode>
                <mu>1</mu>
                <mu2>1</mu2>
                <fdir1>0 0 0</fdir1>
                <slip1>0</slip1>
                <slip2>0</slip2>
              </ode>
              <torsional>
                <coefficient>1</coefficient>
                <patch_radius>0</patch_radius>
                <surface_radius>0</surface_radius>
                <use_patch_radius>1</use_patch_radius>
                <ode>
                  <slip>0</slip>
                </ode>
              </torsional>
            </friction>
            <bounce>
              <restitution_coefficient>0</restitution_coefficient>
              <threshold>1e+06</threshold>
            </bounce>
            <contact>
              <collide_without_contact>0</collide_without_contact>
              <collide_without_contact_bitmask>1</collide_without_contact_bitmask>
              <collide_bitmask>1</collide_bitmask>
              <ode>
                <soft_cfm>0</soft_cfm>
                <soft_erp>0.2</soft_erp>
                <kp>1e+13</kp>
                <kd>1</kd>
                <max_vel>0.01</max_vel>
                <min_depth>0</min_depth>
              </ode>
              <bullet>
                <split_impulse>1</split_impulse>
                <split_impulse_penetration_threshold>-0.01</split_impulse_penetration_threshold>
                <soft_cfm>0</soft_cfm>
                <soft_erp>0.2</soft_erp>
                <kp>1e+13</kp>
                <kd>1</kd>
              </bullet>
            </contact>
          </surface>
        </collision>
        <self_collide>0</self_collide>
        <enable_wind>0</enable_wind>
        <kinematic>0</kinematic>
      </link>
      <static>1</static>
      <allow_auto_disable>1</allow_auto_disable>
      <pose>0.050723 -0.333588 0 0 -0 0</pose>
    </model>
    <model name='dropbox_0'>
      <link name='link_0'>
        <pose>0 -0 0 0 0 -1.56873</pose>
        <inertial>
          <mass>1</mass>
          <inertia>
            <ixx>0.166667</ixx>
            <ixy>0</ixy>
            <ixz>0</ixz>
            <iyy>0.166667</iyy>
            <iyz>0</iyz>
            <izz>0.166667</izz>
          </inertia>
        </inertial>
        <visual name='visual'>
          <pose>0 0 0 0 -0 0</pose>
          <geometry>
            <mesh>
              <uri>model://dropbox/meshes/dropbox.dae</uri>
              <scale>1 1 1</scale>
            </mesh>
          </geometry>
          <material>
            <lighting>1</lighting>
            <script>
              <uri>file://media/materials/scripts/gazebo.material</uri>
              <name>Gazebo/Blue</name>
            </script>
            <ambient>0.3 0.3 0.3 1</ambient>
            <diffuse>0.7 0.7 0.7 1</diffuse>
            <specular>0.01 0.01 0.01 1</specular>
            <emissive>0 0 1 1</emissive>
          </material>
          <transparency>0</transparency>
          <cast_shadows>1</cast_shadows>
        </visual>
        <collision name='collision'>
          <laser_retro>0</laser_retro>
          <max_contacts>10</max_contacts>
          <pose>0 0 0 0 -0 0</pose>
          <geometry>
            <mesh>
              <uri>model://dropbox/meshes/dropbox.dae</uri>
              <scale>1 1 1</scale>
            </mesh>
          </geometry>
          <surface>
            <friction>
              <ode>
                <mu>1</mu>
                <mu2>1</mu2>
                <fdir1>0 0 0</fdir1>
                <slip1>0</slip1>
                <slip2>0</slip2>
              </ode>
              <torsional>
                <coefficient>1</coefficient>
                <patch_radius>0</patch_radius>
                <surface_radius>0</surface_radius>
                <use_patch_radius>1</use_patch_radius>
                <ode>
                  <slip>0</slip>
                </ode>
              </torsional>
            </friction>
            <bounce>
              <restitution_coefficient>0</restitution_coefficient>
              <threshold>1e+06</threshold>
            </bounce>
            <contact>
              <collide_without_contact>0</collide_without_contact>
              <collide_without_contact_bitmask>1</collide_without_contact_bitmask>
              <collide_bitmask>1</collide_bitmask>
              <ode>
                <soft_cfm>0</soft_cfm>
                <soft_erp>0.2</soft_erp>
                <kp>1e+13</kp>
                <kd>1</kd>
                <max_vel>0.01</max_vel>
                <min_depth>0</min_depth>
              </ode>
              <bullet>
                <split_impulse>1</split_impulse>
                <split_impulse_penetration_threshold>-0.01</split_impulse_penetration_threshold>
                <soft_cfm>0</soft_cfm>
                <soft_erp>0.2</soft_erp>
                <kp>1e+13</kp>
                <kd>1</kd>
              </bullet>
            </contact>
          </surface>
        </collision>
        <self_collide>0</self_collide>
        <enable_wind>0</enable_wind>
        <kinematic>0</kinematic>
      </link>
      <static>1</static>
      <allow_auto_disable>1</allow_auto_disable>
      <pose>-2.64764 -2.53009 0 0 -0 0</pose>
    </model>
    <model name='banana'>
      <static>0</static>
      <link name='link'>
        <inertial>
          <pose>-0.009936 0.004073 0.017127 -1.58732 1.3697 2.8053</pose>
          <mass>0.00171533</mass>
          <inertia>
            <ixx>0.00427199</ixx>
            <ixy>-1.32349e-19</ixy>
            <ixz>7.8608e-19</ixz>
            <iyy>0.00410766</iyy>
            <iyz>2.40496e-19</iyz>
            <izz>0.000407539</izz>
          </inertia>
        </inertial>
        <collision name='collision'>
          <geometry>
            <mesh>
              <uri>model://011_banana/google_16k/textured.obj</uri>
            </mesh>
          </geometry>
          <surface>
            <contact>
              <ode/>
            </contact>
            <bounce/>
            <friction>
              <torsional>
                <ode/>
              </torsional>
              <ode/>
            </friction>
          </surface>
          <max_contacts>10</max_contacts>
        </collision>
        <visual name='visual'>
          <geometry>
            <mesh>
              <uri>model://011_banana/google_16k/textured.obj</uri>
            </mesh>
          </geometry>
          <material>
            <script>
              <uri>model://011_banana/banana.material</uri>
              <name>banana</name>
            </script>
          </material>
        </visual>
        <self_collide>0</self_collide>
        <enable_wind>0</enable_wind>
        <kinematic>0</kinematic>
      </link>
      <pose>-1.05619 -0.369241 0 0 -0 0</pose>
    </model>
    <model name='apple'>
      <static>0</static>
      <link name='link'>
        <inertial>
          <pose>0.001311 -0.003861 0.036337 1.28659 -0.495792 -1.57796</pose>
          <mass>0.000246595</mass>
          <inertia>
            <ixx>1.53466e-07</ixx>
            <ixy>-2.64698e-23</ixy>
            <ixz>0</ixz>
            <iyy>1.52372e-07</iyy>
            <iyz>0</iyz>
            <izz>1.50583e-07</izz>
          </inertia>
        </inertial>
        <collision name='collision'>
          <geometry>
            <mesh>
              <uri>model://013_apple/google_16k/textured.obj</uri>
            </mesh>
          </geometry>
          <surface>
            <contact>
              <ode/>
            </contact>
            <bounce/>
            <friction>
              <torsional>
                <ode/>
              </torsional>
              <ode/>
            </friction>
          </surface>
          <max_contacts>10</max_contacts>
        </collision>
        <visual name='visual'>
          <geometry>
            <mesh>
              <uri>model://013_apple/google_16k/textured.obj</uri>
            </mesh>
          </geometry>
          <material>
            <script>
              <uri>model://013_apple/apple.material</uri>
              <name>apple</name>
            </script>
          </material>
        </visual>
        <self_collide>0</self_collide>
        <enable_wind>0</enable_wind>
        <kinematic>0</kinematic>
      </link>
      <pose>-1.71301 1.00919 0 0 -0 0</pose>
    </model>
    <model name='phillips_screwdriver'>
      <static>0</static>
      <link name='link'>
        <inertial>
          <pose>0.002663 0.022224 0.016372 1.65222 -1.00568 -1.17449</pose>
          <mass>7.70055e-05</mass>
          <inertia>
            <ixx>1.08681e-07</ixx>
            <ixy>-8.47264e-24</ixy>
            <ixz>4.22641e-24</ixz>
            <iyy>1.08634e-07</iyy>
            <iyz>-1.00542e-23</iyz>
            <izz>8.53822e-09</izz>
          </inertia>
        </inertial>
        <collision name='collision'>
          <geometry>
            <mesh>
              <uri>model://043_phillips_screwdriver/google_16k/textured.obj</uri>
              <scale>1.5 1.5 1.5</scale>
            </mesh>
          </geometry>
          <surface>
            <contact>
              <ode/>
            </contact>
            <bounce/>
            <friction>
              <torsional>
                <ode/>
              </torsional>
              <ode/>
            </friction>
          </surface>
          <max_contacts>10</max_contacts>
        </collision>
        <visual name='visual'>
          <geometry>
            <mesh>
              <uri>model://043_phillips_screwdriver/google_16k/textured.obj</uri>
              <scale>1.5 1.5 1.5</scale>
            </mesh>
          </geometry>
          <material>
            <script>
              <uri>model://043_phillips_screwdriver/phillips_screwdriver.material</uri>
              <name>phillips_screwdriver</name>
            </script>
          </material>
        </visual>
        <self_collide>0</self_collide>
        <enable_wind>0</enable_wind>
        <kinematic>0</kinematic>
      </link>
      <pose>-0.237107 0.645908 0 0 -0 0</pose>
    </model>
    <model name='robot'>
      <joint name='camera_rgb_joint' type='fixed'>
        <pose relative_to='__model__'>0 0.2 0.8 0 1.25 1.5708</pose>
        <parent>world</parent>
        <child>camera_rgb_frame</child>
      </joint>
      <link name='camera_rgb_frame'>
        <pose relative_to='camera_rgb_joint'>0 0 0 0 -0 0</pose>
        <inertial>
          <pose>-0.0062 0 -0.0032 0 -0 0</pose>
          <mass>0.005</mass>
          <inertia>
            <ixx>0.000500205</ixx>
            <ixy>0</ixy>
            <ixz>-3.968e-07</ixz>
            <iyy>0.000500974</iyy>
            <iyz>0</iyz>
            <izz>0.000500769</izz>
          </inertia>
        </inertial>
        <collision name='camera_rgb_frame_fixed_joint_lump__camera_link_collision'>
          <pose>-0.031 0 -0.016 0 -0 0</pose>
          <geometry>
            <box>
              <size>0.07271 0.27794 0.073</size>
            </box>
          </geometry>
          <max_contacts>10</max_contacts>
          <surface>
            <contact>
              <ode/>
            </contact>
            <bounce/>
            <friction>
              <torsional>
                <ode/>
              </torsional>
              <ode/>
            </friction>
          </surface>
        </collision>
        <visual name='camera_rgb_frame_fixed_joint_lump__camera_link_visual'>
          <pose>-0.031 0 -0.016 0 -0 1.5708</pose>
          <geometry>
            <mesh>
              <scale>1 1 1</scale>
              <uri>/home/dylan/catkin_ws/src/common-sensors/common_sensors/meshes/sensors/kinect.dae</uri>
            </mesh>
          </geometry>
        </visual>
        <sensor name='camera1' type='depth'>
          <always_on>1</always_on>
          <update_rate>20</update_rate>
          <camera>
            <horizontal_fov>1.0472</horizontal_fov>
            <image>
              <format>R8G8B8</format>
              <width>640</width>
              <height>480</height>
            </image>
            <clip>
              <near>0.05</near>
              <far>8</far>
            </clip>
          </camera>
          <plugin name='camera_depth_frame_kinect_controller' filename='libgazebo_ros_openni_kinect.so'>
            <baseline>0.1</baseline>
            <alwaysOn>1</alwaysOn>
            <updateRate>10</updateRate>
            <cameraName>camera1</cameraName>
            <imageTopicName>rgb/image_raw</imageTopicName>
            <cameraInfoTopicName>rgb/camera_info</cameraInfoTopicName>
            <depthImageTopicName>depth/image_raw</depthImageTopicName>
            <depthImageCameraInfoTopicName>depth/camera_info</depthImageCameraInfoTopicName>
            <pointCloudTopicName>depth/points</pointCloudTopicName>
            <frameName>camera_depth_optical_frame</frameName>
            <pointCloudCutoff>0.3</pointCloudCutoff>
            <distortion_k1>0.0</distortion_k1>
            <distortion_k2>0.0</distortion_k2>
            <distortion_k3>0.0</distortion_k3>
            <distortion_t1>0.0</distortion_t1>
            <distortion_t2>0.0</distortion_t2>
            <robotNamespace>/</robotNamespace>
          </plugin>
          <pose>0 0 0 0 -0 0</pose>
        </sensor>
        <self_collide>0</self_collide>
        <enable_wind>0</enable_wind>
        <kinematic>0</kinematic>
      </link>
      <joint name='world_joint' type='fixed'>
        <pose relative_to='__model__'>0 0 0 0 -0 0</pose>
        <parent>world</parent>
        <child>base_link</child>
      </joint>
      <link name='base_link'>
        <pose relative_to='world_joint'>0 0 0 0 -0 0</pose>
        <inertial>
          <pose>0 0 0 0 -0 0</pose>
          <mass>4</mass>
          <inertia>
            <ixx>0.00443333</ixx>
            <ixy>0</ixy>
            <ixz>0</ixz>
            <iyy>0.00443333</iyy>
            <iyz>0</iyz>
            <izz>0.0072</izz>
          </inertia>
        </inertial>
        <collision name='base_link_collision'>
          <pose>0 0 0 0 -0 0</pose>
          <geometry>
            <mesh>
              <scale>1 1 1</scale>
              <uri>/home/dylan/catkin_ws/src/universal_robot/ur_description/meshes/ur5/collision/base.stl</uri>
            </mesh>
          </geometry>
          <max_contacts>10</max_contacts>
          <surface>
            <contact>
              <ode/>
            </contact>
            <bounce/>
            <friction>
              <torsional>
                <ode/>
              </torsional>
              <ode/>
            </friction>
          </surface>
        </collision>
        <visual name='base_link_visual'>
          <pose>0 0 0 0 -0 0</pose>
          <geometry>
            <mesh>
              <scale>1 1 1</scale>
              <uri>/home/dylan/catkin_ws/src/universal_robot/ur_description/meshes/ur5/visual/base.dae</uri>
            </mesh>
          </geometry>
        </visual>
        <self_collide>0</self_collide>
        <enable_wind>0</enable_wind>
        <kinematic>0</kinematic>
      </link>
      <joint name='shoulder_pan_joint' type='revolute'>
        <pose relative_to='base_link'>0 0 0.089159 0 -0 0</pose>
        <parent>base_link</parent>
        <child>shoulder_link</child>
        <axis>
          <xyz>0 0 1</xyz>
          <limit>
            <lower>-3.14159</lower>
            <upper>3.14159</upper>
            <effort>150</effort>
            <velocity>3.15</velocity>
          </limit>
          <dynamics>
            <damping>0</damping>
            <friction>0</friction>
            <spring_reference>0</spring_reference>
            <spring_stiffness>0</spring_stiffness>
          </dynamics>
        </axis>
      </joint>
      <link name='shoulder_link'>
        <pose relative_to='shoulder_pan_joint'>0 0 0 0 -0 0</pose>
        <inertial>
          <pose>0 0 0 0 -0 0</pose>
          <mass>3.7</mass>
          <inertia>
            <ixx>0.0102675</ixx>
            <ixy>0</ixy>
            <ixz>0</ixz>
            <iyy>0.0102675</iyy>
            <iyz>0</iyz>
            <izz>0.00666</izz>
          </inertia>
        </inertial>
        <collision name='shoulder_link_collision'>
          <pose>0 0 0 0 -0 0</pose>
          <geometry>
            <mesh>
              <scale>1 1 1</scale>
              <uri>/home/dylan/catkin_ws/src/universal_robot/ur_description/meshes/ur5/collision/shoulder.stl</uri>
            </mesh>
          </geometry>
          <surface>
            <contact>
              <ode/>
            </contact>
            <friction>
              <ode/>
              <torsional>
                <ode/>
              </torsional>
            </friction>
            <bounce/>
          </surface>
          <max_contacts>10</max_contacts>
        </collision>
        <visual name='shoulder_link_visual'>
          <pose>0 0 0 0 -0 0</pose>
          <geometry>
            <mesh>
              <scale>1 1 1</scale>
              <uri>/home/dylan/catkin_ws/src/universal_robot/ur_description/meshes/ur5/visual/shoulder.dae</uri>
            </mesh>
          </geometry>
        </visual>
        <self_collide>1</self_collide>
        <enable_wind>0</enable_wind>
        <kinematic>0</kinematic>
      </link>
      <joint name='shoulder_lift_joint' type='revolute'>
        <pose relative_to='shoulder_link'>0 0.13585 0 3.14159 1.57079 3.14159</pose>
        <parent>shoulder_link</parent>
        <child>upper_arm_link</child>
        <axis>
          <xyz>0 1 0</xyz>
          <limit>
            <lower>-3.14159</lower>
            <upper>3.14159</upper>
            <effort>150</effort>
            <velocity>3.15</velocity>
          </limit>
          <dynamics>
            <damping>0</damping>
            <friction>0</friction>
            <spring_reference>0</spring_reference>
            <spring_stiffness>0</spring_stiffness>
          </dynamics>
        </axis>
      </joint>
      <link name='upper_arm_link'>
        <pose relative_to='shoulder_lift_joint'>0 0 0 0 -0 0</pose>
        <inertial>
          <pose>0 0 0.28 0 -0 0</pose>
          <mass>8.393</mass>
          <inertia>
            <ixx>0.226891</ixx>
            <ixy>0</ixy>
            <ixz>0</ixz>
            <iyy>0.226891</iyy>
            <iyz>0</iyz>
            <izz>0.0151074</izz>
          </inertia>
        </inertial>
        <collision name='upper_arm_link_collision'>
          <pose>0 0 0 0 -0 0</pose>
          <geometry>
            <mesh>
              <scale>1 1 1</scale>
              <uri>/home/dylan/catkin_ws/src/universal_robot/ur_description/meshes/ur5/collision/upperarm.stl</uri>
            </mesh>
          </geometry>
          <surface>
            <contact>
              <ode/>
            </contact>
            <friction>
              <ode/>
              <torsional>
                <ode/>
              </torsional>
            </friction>
            <bounce/>
          </surface>
          <max_contacts>10</max_contacts>
        </collision>
        <visual name='upper_arm_link_visual'>
          <pose>0 0 0 0 -0 0</pose>
          <geometry>
            <mesh>
              <scale>1 1 1</scale>
              <uri>/home/dylan/catkin_ws/src/universal_robot/ur_description/meshes/ur5/visual/upperarm.dae</uri>
            </mesh>
          </geometry>
        </visual>
        <self_collide>1</self_collide>
        <enable_wind>0</enable_wind>
        <kinematic>0</kinematic>
      </link>
      <joint name='elbow_joint' type='revolute'>
        <pose relative_to='upper_arm_link'>0 -0.1197 0.425 0 -0 0</pose>
        <parent>upper_arm_link</parent>
        <child>forearm_link</child>
        <axis>
          <xyz>0 1 0</xyz>
          <limit>
            <lower>-3.14159</lower>
            <upper>3.14159</upper>
            <effort>150</effort>
            <velocity>3.15</velocity>
          </limit>
          <dynamics>
            <damping>0</damping>
            <friction>0</friction>
            <spring_reference>0</spring_reference>
            <spring_stiffness>0</spring_stiffness>
          </dynamics>
        </axis>
      </joint>
      <link name='forearm_link'>
        <pose relative_to='elbow_joint'>0 0 0 0 -0 0</pose>
        <inertial>
          <pose>0 0 0.196125 0 -0 0</pose>
          <mass>2.275</mass>
          <inertia>
            <ixx>0.0312168</ixx>
            <ixy>0</ixy>
            <ixz>0</ixz>
            <iyy>0.0312168</iyy>
            <iyz>0</iyz>
            <izz>0.004095</izz>
          </inertia>
        </inertial>
        <collision name='forearm_link_collision'>
          <pose>0 0 0 0 -0 0</pose>
          <geometry>
            <mesh>
              <scale>1 1 1</scale>
              <uri>/home/dylan/catkin_ws/src/universal_robot/ur_description/meshes/ur5/collision/forearm.stl</uri>
            </mesh>
          </geometry>
          <surface>
            <contact>
              <ode/>
            </contact>
            <friction>
              <ode/>
              <torsional>
                <ode/>
              </torsional>
            </friction>
            <bounce/>
          </surface>
          <max_contacts>10</max_contacts>
        </collision>
        <visual name='forearm_link_visual'>
          <pose>0 0 0 0 -0 0</pose>
          <geometry>
            <mesh>
              <scale>1 1 1</scale>
              <uri>/home/dylan/catkin_ws/src/universal_robot/ur_description/meshes/ur5/visual/forearm.dae</uri>
            </mesh>
          </geometry>
        </visual>
        <self_collide>1</self_collide>
        <enable_wind>0</enable_wind>
        <kinematic>0</kinematic>
      </link>
      <joint name='wrist_1_joint' type='revolute'>
        <pose relative_to='forearm_link'>0 0 0.39225 3.14159 1.57079 3.14159</pose>
        <parent>forearm_link</parent>
        <child>wrist_1_link</child>
        <axis>
          <xyz>0 1 0</xyz>
          <limit>
            <lower>-3.14159</lower>
            <upper>3.14159</upper>
            <effort>28</effort>
            <velocity>3.2</velocity>
          </limit>
          <dynamics>
            <damping>0</damping>
            <friction>0</friction>
            <spring_reference>0</spring_reference>
            <spring_stiffness>0</spring_stiffness>
          </dynamics>
        </axis>
      </joint>
      <link name='wrist_1_link'>
        <pose relative_to='wrist_1_joint'>0 0 0 0 -0 0</pose>
        <inertial>
          <pose>0 0.093 0 0 -0 0</pose>
          <mass>1.219</mass>
          <inertia>
            <ixx>0.0025599</ixx>
            <ixy>0</ixy>
            <ixz>0</ixz>
            <iyy>0.0025599</iyy>
            <iyz>0</iyz>
            <izz>0.0021942</izz>
          </inertia>
        </inertial>
        <collision name='wrist_1_link_collision'>
          <pose>0 0 0 0 -0 0</pose>
          <geometry>
            <mesh>
              <scale>1 1 1</scale>
              <uri>/home/dylan/catkin_ws/src/universal_robot/ur_description/meshes/ur5/collision/wrist1.stl</uri>
            </mesh>
          </geometry>
          <surface>
            <contact>
              <ode/>
            </contact>
            <friction>
              <ode/>
              <torsional>
                <ode/>
              </torsional>
            </friction>
            <bounce/>
          </surface>
          <max_contacts>10</max_contacts>
        </collision>
        <visual name='wrist_1_link_visual'>
          <pose>0 0 0 0 -0 0</pose>
          <geometry>
            <mesh>
              <scale>1 1 1</scale>
              <uri>/home/dylan/catkin_ws/src/universal_robot/ur_description/meshes/ur5/visual/wrist1.dae</uri>
            </mesh>
          </geometry>
        </visual>
        <self_collide>1</self_collide>
        <enable_wind>0</enable_wind>
        <kinematic>0</kinematic>
      </link>
      <joint name='wrist_2_joint' type='revolute'>
        <pose relative_to='wrist_1_link'>0 0.093 0 0 -0 0</pose>
        <parent>wrist_1_link</parent>
        <child>wrist_2_link</child>
        <axis>
          <xyz>0 0 1</xyz>
          <limit>
            <lower>-3.14159</lower>
            <upper>3.14159</upper>
            <effort>28</effort>
            <velocity>3.2</velocity>
          </limit>
          <dynamics>
            <damping>0</damping>
            <friction>0</friction>
            <spring_reference>0</spring_reference>
            <spring_stiffness>0</spring_stiffness>
          </dynamics>
        </axis>
      </joint>
      <link name='wrist_2_link'>
        <pose relative_to='wrist_2_joint'>0 0 0 0 -0 0</pose>
        <inertial>
          <pose>0 0 0.09465 0 -0 0</pose>
          <mass>1.219</mass>
          <inertia>
            <ixx>0.0025599</ixx>
            <ixy>0</ixy>
            <ixz>0</ixz>
            <iyy>0.0025599</iyy>
            <iyz>0</iyz>
            <izz>0.0021942</izz>
          </inertia>
        </inertial>
        <collision name='wrist_2_link_collision'>
          <pose>0 0 0 0 -0 0</pose>
          <geometry>
            <mesh>
              <scale>1 1 1</scale>
              <uri>/home/dylan/catkin_ws/src/universal_robot/ur_description/meshes/ur5/collision/wrist2.stl</uri>
            </mesh>
          </geometry>
          <surface>
            <contact>
              <ode/>
            </contact>
            <friction>
              <ode/>
              <torsional>
                <ode/>
              </torsional>
            </friction>
            <bounce/>
          </surface>
          <max_contacts>10</max_contacts>
        </collision>
        <visual name='wrist_2_link_visual'>
          <pose>0 0 0 0 -0 0</pose>
          <geometry>
            <mesh>
              <scale>1 1 1</scale>
              <uri>/home/dylan/catkin_ws/src/universal_robot/ur_description/meshes/ur5/visual/wrist2.dae</uri>
            </mesh>
          </geometry>
        </visual>
        <self_collide>1</self_collide>
        <enable_wind>0</enable_wind>
        <kinematic>0</kinematic>
      </link>
      <joint name='wrist_3_joint' type='revolute'>
        <pose relative_to='wrist_2_link'>0 0 0.09465 0 -0 0</pose>
        <parent>wrist_2_link</parent>
        <child>wrist_3_link</child>
        <axis>
          <xyz>0 1 0</xyz>
          <limit>
            <lower>-3.14159</lower>
            <upper>3.14159</upper>
            <effort>28</effort>
            <velocity>3.2</velocity>
          </limit>
          <dynamics>
            <damping>0</damping>
            <friction>0</friction>
            <spring_reference>0</spring_reference>
            <spring_stiffness>0</spring_stiffness>
          </dynamics>
        </axis>
        <physics>
          <provide_feedback>1</provide_feedback>
          <ode>
            <limit>
              <cfm>0</cfm>
              <erp>0.2</erp>
            </limit>
            <provide_feedback>1</provide_feedback>
          </ode>
        </physics>
      </joint>
      <link name='wrist_3_link'>
        <pose relative_to='wrist_3_joint'>0 0 0 0 -0 0</pose>
        <inertial>
          <pose>0.000246 0.084658 4e-06 1.5708 -0 0</pose>
          <mass>0.992851</mass>
          <inertia>
            <ixx>0.00136577</ixx>
            <ixy>1.01149e-09</ixy>
            <ixz>-4.09903e-07</ixz>
            <iyy>0.00141553</iyy>
            <iyz>2.93103e-08</iyz>
            <izz>0.000654232</izz>
          </inertia>
        </inertial>
        <collision name='wrist_3_link_collision'>
          <pose>0 0 0 0 -0 0</pose>
          <geometry>
            <mesh>
              <scale>1 1 1</scale>
              <uri>/home/dylan/catkin_ws/src/universal_robot/ur_description/meshes/ur5/collision/wrist3.stl</uri>
            </mesh>
          </geometry>
          <surface>
            <contact>
              <ode/>
            </contact>
            <friction>
              <ode/>
              <torsional>
                <ode/>
              </torsional>
            </friction>
            <bounce/>
          </surface>
          <max_contacts>10</max_contacts>
        </collision>
        <collision name='wrist_3_link_fixed_joint_lump__ee_link_collision_1'>
          <pose>-0 0.0723 0 0 -0 1.5708</pose>
          <geometry>
            <box>
              <size>0.01 0.01 0.01</size>
            </box>
          </geometry>
          <surface>
            <contact>
              <ode/>
            </contact>
            <friction>
              <ode/>
              <torsional>
                <ode/>
              </torsional>
            </friction>
            <bounce/>
          </surface>
          <max_contacts>10</max_contacts>
        </collision>
        <collision name='wrist_3_link_fixed_joint_lump__robotiq_coupler_collision_2'>
          <pose>0 0.0863 0 1.57079 -1.57079 3.14159</pose>
          <geometry>
            <mesh>
              <scale>1 1 1</scale>
              <uri>/home/dylan/catkin_ws/src/robotiq/robotiq_description/meshes/robotiq_85_coupler.stl</uri>
            </mesh>
          </geometry>
          <surface>
            <contact>
              <ode/>
            </contact>
            <friction>
              <ode>
                <mu>0.9</mu>
                <mu2>0.9</mu2>
              </ode>
              <torsional>
                <ode/>
              </torsional>
            </friction>
            <bounce/>
          </surface>
          <max_contacts>10</max_contacts>
        </collision>
        <collision name='wrist_3_link_fixed_joint_lump__robotiq_85_base_link_collision_3'>
          <pose>0 0.0903 0 0 -0 1.5708</pose>
          <geometry>
            <mesh>
              <scale>1 1 1</scale>
              <uri>/home/dylan/catkin_ws/src/robotiq/robotiq_description/meshes/collision/robotiq_85_base_link.stl</uri>
            </mesh>
          </geometry>
          <max_contacts>10</max_contacts>
          <surface>
            <contact>
              <ode/>
            </contact>
            <bounce/>
            <friction>
              <torsional>
                <ode/>
              </torsional>
              <ode/>
            </friction>
          </surface>
        </collision>
        <visual name='wrist_3_link_visual'>
          <pose>0 0 0 0 -0 0</pose>
          <geometry>
            <mesh>
              <scale>1 1 1</scale>
              <uri>/home/dylan/catkin_ws/src/universal_robot/ur_description/meshes/ur5/visual/wrist3.dae</uri>
            </mesh>
          </geometry>
        </visual>
        <visual name='wrist_3_link_fixed_joint_lump__robotiq_coupler_visual_1'>
          <pose>0 0.0863 0 1.57079 -1.57079 3.14159</pose>
          <geometry>
            <mesh>
              <scale>1 1 1</scale>
              <uri>/home/dylan/catkin_ws/src/robotiq/robotiq_description/meshes/robotiq_85_coupler.stl</uri>
            </mesh>
          </geometry>
          <material>
            <script>
              <name>Gazebo/FlatBlack</name>
              <uri>file://media/materials/scripts/gazebo.material</uri>
            </script>
          </material>
        </visual>
        <visual name='wrist_3_link_fixed_joint_lump__robotiq_85_base_link_visual_2'>
          <pose>0 0.0903 0 0 -0 1.5708</pose>
          <geometry>
            <mesh>
              <scale>1 1 1</scale>
              <uri>/home/dylan/catkin_ws/src/robotiq/robotiq_description/meshes/visual/robotiq_85_base_link.dae</uri>
            </mesh>
          </geometry>
        </visual>
        <self_collide>1</self_collide>
        <enable_wind>0</enable_wind>
        <kinematic>0</kinematic>
      </link>
      <joint name='robotiq_85_left_inner_knuckle_joint' type='revolute'>
        <pose relative_to='wrist_3_link'>-0.0127 0.15172 0 3.14159 -0 1.5708</pose>
        <parent>wrist_3_link</parent>
        <child>robotiq_85_left_inner_knuckle_link</child>
        <axis>
          <xyz>0 0 1</xyz>
          <limit>
            <effort>0.1</effort>
            <velocity>100</velocity>
            <lower>-1e+16</lower>
            <upper>1e+16</upper>
          </limit>
          <dynamics>
            <spring_reference>0</spring_reference>
            <spring_stiffness>0</spring_stiffness>
          </dynamics>
        </axis>
      </joint>
      <link name='robotiq_85_left_inner_knuckle_link'>
        <pose relative_to='robotiq_85_left_inner_knuckle_joint'>0 0 0 0 -0 0</pose>
        <inertial>
          <pose>0 0 0 0 -0 0</pose>
          <mass>0.029951</mass>
          <inertia>
            <ixx>3.9e-05</ixx>
            <ixy>0</ixy>
            <ixz>0</ixz>
            <iyy>5e-06</iyy>
            <iyz>0</iyz>
            <izz>3.5e-05</izz>
          </inertia>
        </inertial>
        <collision name='robotiq_85_left_inner_knuckle_link_collision'>
          <pose>0 0 0 0 -0 0</pose>
          <geometry>
            <mesh>
              <scale>1 1 1</scale>
              <uri>/home/dylan/catkin_ws/src/robotiq/robotiq_description/meshes/collision/robotiq_85_inner_knuckle_link.stl</uri>
            </mesh>
          </geometry>
          <max_contacts>10</max_contacts>
          <surface>
            <contact>
              <ode/>
            </contact>
            <bounce/>
            <friction>
              <torsional>
                <ode/>
              </torsional>
              <ode/>
            </friction>
          </surface>
        </collision>
        <visual name='robotiq_85_left_inner_knuckle_link_visual'>
          <pose>0 0 0 0 -0 0</pose>
          <geometry>
            <mesh>
              <scale>1 1 1</scale>
              <uri>/home/dylan/catkin_ws/src/robotiq/robotiq_description/meshes/visual/robotiq_85_inner_knuckle_link.dae</uri>
            </mesh>
          </geometry>
        </visual>
        <self_collide>0</self_collide>
        <enable_wind>0</enable_wind>
        <kinematic>0</kinematic>
      </link>
      <joint name='robotiq_85_left_finger_tip_joint' type='revolute'>
        <pose relative_to='robotiq_85_left_inner_knuckle_link'>0.04304 -0.037599 0 0 -0 0</pose>
        <parent>robotiq_85_left_inner_knuckle_link</parent>
        <child>robotiq_85_left_finger_tip_link</child>
        <axis>
          <xyz>0 0 1</xyz>
          <limit>
            <effort>0.1</effort>
            <velocity>100</velocity>
            <lower>-1e+16</lower>
            <upper>1e+16</upper>
          </limit>
          <dynamics>
            <spring_reference>0</spring_reference>
            <spring_stiffness>0</spring_stiffness>
          </dynamics>
        </axis>
      </joint>
      <link name='robotiq_85_left_finger_tip_link'>
        <pose relative_to='robotiq_85_left_finger_tip_joint'>0 0 0 0 -0 0</pose>
        <inertial>
          <pose>0 0 0 0 -0 0</pose>
          <mass>0.019555</mass>
          <inertia>
            <ixx>2e-06</ixx>
            <ixy>0</ixy>
            <ixz>0</ixz>
            <iyy>5e-06</iyy>
            <iyz>0</iyz>
            <izz>6e-06</izz>
          </inertia>
        </inertial>
        <collision name='robotiq_85_left_finger_tip_link_collision'>
          <pose>0 0 0 0 -0 0</pose>
          <geometry>
            <mesh>
              <scale>1 1 1</scale>
              <uri>/home/dylan/catkin_ws/src/robotiq/robotiq_description/meshes/collision/robotiq_85_finger_tip_link.stl</uri>
            </mesh>
          </geometry>
          <surface>
            <contact>
              <ode>
                <kp>1e+06</kp>
                <kd>1</kd>
                <min_depth>0.001</min_depth>
              </ode>
            </contact>
            <friction>
              <ode>
                <mu>1</mu>
                <mu2>1</mu2>
              </ode>
              <torsional>
                <ode/>
              </torsional>
            </friction>
            <bounce/>
          </surface>
          <max_contacts>10</max_contacts>
        </collision>
        <visual name='robotiq_85_left_finger_tip_link_visual'>
          <pose>0 0 0 0 -0 0</pose>
          <geometry>
            <mesh>
              <scale>1 1 1</scale>
              <uri>/home/dylan/catkin_ws/src/robotiq/robotiq_description/meshes/visual/robotiq_85_finger_tip_link.dae</uri>
            </mesh>
          </geometry>
        </visual>
        <self_collide>0</self_collide>
        <enable_wind>0</enable_wind>
        <kinematic>0</kinematic>
      </link>
      <joint name='robotiq_85_left_knuckle_joint' type='revolute'>
        <pose relative_to='wrist_3_link'>-0.030601 0.145205 0 3.14159 -0 1.5708</pose>
        <parent>wrist_3_link</parent>
        <child>robotiq_85_left_knuckle_link</child>
        <axis>
          <xyz>0 0 1</xyz>
          <limit>
            <lower>0</lower>
            <upper>0.80285</upper>
            <effort>1000</effort>
            <velocity>0.5</velocity>
          </limit>
          <dynamics>
            <spring_reference>0</spring_reference>
            <spring_stiffness>0</spring_stiffness>
          </dynamics>
        </axis>
      </joint>
      <link name='robotiq_85_left_knuckle_link'>
        <pose relative_to='robotiq_85_left_knuckle_joint'>0 0 0 0 -0 0</pose>
        <inertial>
          <pose>-0.002436 -0.018774 0 0 -0 0</pose>
          <mass>0.0458</mass>
          <inertia>
            <ixx>2.29304e-05</ixx>
            <ixy>-4.4183e-06</ixy>
            <ixz>0</ixz>
            <iyy>2.2184e-05</iyy>
            <iyz>0</iyz>
            <izz>4.11145e-05</izz>
          </inertia>
        </inertial>
        <collision name='robotiq_85_left_knuckle_link_collision'>
          <pose>0 0 0 0 -0 0</pose>
          <geometry>
            <mesh>
              <scale>1 1 1</scale>
              <uri>/home/dylan/catkin_ws/src/robotiq/robotiq_description/meshes/collision/robotiq_85_knuckle_link.stl</uri>
            </mesh>
          </geometry>
          <max_contacts>10</max_contacts>
          <surface>
            <contact>
              <ode/>
            </contact>
            <bounce/>
            <friction>
              <torsional>
                <ode/>
              </torsional>
              <ode/>
            </friction>
          </surface>
        </collision>
        <collision name='robotiq_85_left_knuckle_link_fixed_joint_lump__robotiq_85_left_finger_link_collision_1'>
          <pose>-0.004086 -0.031486 0 0 -0 0</pose>
          <geometry>
            <mesh>
              <scale>1 1 1</scale>
              <uri>/home/dylan/catkin_ws/src/robotiq/robotiq_description/meshes/collision/robotiq_85_finger_link.stl</uri>
            </mesh>
          </geometry>
          <max_contacts>10</max_contacts>
          <surface>
            <contact>
              <ode/>
            </contact>
            <bounce/>
            <friction>
              <torsional>
                <ode/>
              </torsional>
              <ode/>
            </friction>
          </surface>
        </collision>
        <visual name='robotiq_85_left_knuckle_link_visual'>
          <pose>0 0 0 0 -0 0</pose>
          <geometry>
            <mesh>
              <scale>1 1 1</scale>
              <uri>/home/dylan/catkin_ws/src/robotiq/robotiq_description/meshes/visual/robotiq_85_knuckle_link.dae</uri>
            </mesh>
          </geometry>
        </visual>
        <visual name='robotiq_85_left_knuckle_link_fixed_joint_lump__robotiq_85_left_finger_link_visual_1'>
          <pose>-0.004086 -0.031486 0 0 -0 0</pose>
          <geometry>
            <mesh>
              <scale>1 1 1</scale>
              <uri>/home/dylan/catkin_ws/src/robotiq/robotiq_description/meshes/visual/robotiq_85_finger_link.dae</uri>
            </mesh>
          </geometry>
        </visual>
        <self_collide>0</self_collide>
        <enable_wind>0</enable_wind>
        <kinematic>0</kinematic>
      </link>
      <joint name='robotiq_85_right_inner_knuckle_joint' type='revolute'>
        <pose relative_to='wrist_3_link'>0.0127 0.15172 0 0 -0 1.5708</pose>
        <parent>wrist_3_link</parent>
        <child>robotiq_85_right_inner_knuckle_link</child>
        <axis>
          <xyz>0 0 1</xyz>
          <limit>
            <effort>0.1</effort>
            <velocity>100</velocity>
            <lower>-1e+16</lower>
            <upper>1e+16</upper>
          </limit>
          <dynamics>
            <spring_reference>0</spring_reference>
            <spring_stiffness>0</spring_stiffness>
          </dynamics>
        </axis>
      </joint>
      <link name='robotiq_85_right_inner_knuckle_link'>
        <pose relative_to='robotiq_85_right_inner_knuckle_joint'>0 0 0 0 -0 0</pose>
        <inertial>
          <pose>0 0 0 0 -0 0</pose>
          <mass>0.029951</mass>
          <inertia>
            <ixx>3.9e-05</ixx>
            <ixy>0</ixy>
            <ixz>0</ixz>
            <iyy>5e-06</iyy>
            <iyz>0</iyz>
            <izz>3.5e-05</izz>
          </inertia>
        </inertial>
        <collision name='robotiq_85_right_inner_knuckle_link_collision'>
          <pose>0 0 0 0 -0 0</pose>
          <geometry>
            <mesh>
              <scale>1 1 1</scale>
              <uri>/home/dylan/catkin_ws/src/robotiq/robotiq_description/meshes/collision/robotiq_85_inner_knuckle_link.stl</uri>
            </mesh>
          </geometry>
          <max_contacts>10</max_contacts>
          <surface>
            <contact>
              <ode/>
            </contact>
            <bounce/>
            <friction>
              <torsional>
                <ode/>
              </torsional>
              <ode/>
            </friction>
          </surface>
        </collision>
        <visual name='robotiq_85_right_inner_knuckle_link_visual'>
          <pose>0 0 0 0 -0 0</pose>
          <geometry>
            <mesh>
              <scale>1 1 1</scale>
              <uri>/home/dylan/catkin_ws/src/robotiq/robotiq_description/meshes/visual/robotiq_85_inner_knuckle_link.dae</uri>
            </mesh>
          </geometry>
        </visual>
        <self_collide>0</self_collide>
        <enable_wind>0</enable_wind>
        <kinematic>0</kinematic>
      </link>
      <joint name='robotiq_85_right_finger_tip_joint' type='revolute'>
        <pose relative_to='robotiq_85_right_inner_knuckle_link'>0.04304 -0.037599 0 0 -0 0</pose>
        <parent>robotiq_85_right_inner_knuckle_link</parent>
        <child>robotiq_85_right_finger_tip_link</child>
        <axis>
          <xyz>0 0 1</xyz>
          <limit>
            <effort>0.1</effort>
            <velocity>100</velocity>
            <lower>-1e+16</lower>
            <upper>1e+16</upper>
          </limit>
          <dynamics>
            <spring_reference>0</spring_reference>
            <spring_stiffness>0</spring_stiffness>
          </dynamics>
        </axis>
      </joint>
      <link name='robotiq_85_right_finger_tip_link'>
        <pose relative_to='robotiq_85_right_finger_tip_joint'>0 0 0 0 -0 0</pose>
        <inertial>
          <pose>0 0 0 0 -0 0</pose>
          <mass>0.019555</mass>
          <inertia>
            <ixx>2e-06</ixx>
            <ixy>0</ixy>
            <ixz>0</ixz>
            <iyy>5e-06</iyy>
            <iyz>0</iyz>
            <izz>6e-06</izz>
          </inertia>
        </inertial>
        <collision name='robotiq_85_right_finger_tip_link_collision'>
          <pose>0 0 0 0 -0 0</pose>
          <geometry>
            <mesh>
              <scale>1 1 1</scale>
              <uri>/home/dylan/catkin_ws/src/robotiq/robotiq_description/meshes/collision/robotiq_85_finger_tip_link.stl</uri>
            </mesh>
          </geometry>
          <surface>
            <contact>
              <ode>
                <kp>1e+06</kp>
                <kd>1</kd>
                <min_depth>0.001</min_depth>
              </ode>
            </contact>
            <friction>
              <ode>
                <mu>1</mu>
                <mu2>1</mu2>
              </ode>
              <torsional>
                <ode/>
              </torsional>
            </friction>
            <bounce/>
          </surface>
          <max_contacts>10</max_contacts>
        </collision>
        <visual name='robotiq_85_right_finger_tip_link_visual'>
          <pose>0 0 0 0 -0 0</pose>
          <geometry>
            <mesh>
              <scale>1 1 1</scale>
              <uri>/home/dylan/catkin_ws/src/robotiq/robotiq_description/meshes/visual/robotiq_85_finger_tip_link.dae</uri>
            </mesh>
          </geometry>
        </visual>
        <self_collide>0</self_collide>
        <enable_wind>0</enable_wind>
        <kinematic>0</kinematic>
      </link>
      <joint name='robotiq_85_right_knuckle_joint' type='revolute'>
        <pose relative_to='wrist_3_link'>0.030601 0.145205 0 0 -0 1.5708</pose>
        <parent>wrist_3_link</parent>
        <child>robotiq_85_right_knuckle_link</child>
        <axis>
          <xyz>0 0 1</xyz>
          <limit>
            <effort>1000</effort>
            <velocity>100</velocity>
            <lower>-1e+16</lower>
            <upper>1e+16</upper>
          </limit>
          <dynamics>
            <spring_reference>0</spring_reference>
            <spring_stiffness>0</spring_stiffness>
          </dynamics>
        </axis>
      </joint>
      <link name='robotiq_85_right_knuckle_link'>
        <pose relative_to='robotiq_85_right_knuckle_joint'>0 0 0 0 -0 0</pose>
        <inertial>
          <pose>-0.002436 -0.018774 0 0 -0 0</pose>
          <mass>0.0458</mass>
          <inertia>
            <ixx>2.29304e-05</ixx>
            <ixy>-4.4183e-06</ixy>
            <ixz>0</ixz>
            <iyy>2.2184e-05</iyy>
            <iyz>0</iyz>
            <izz>4.11145e-05</izz>
          </inertia>
        </inertial>
        <collision name='robotiq_85_right_knuckle_link_collision'>
          <pose>0 0 0 0 -0 0</pose>
          <geometry>
            <mesh>
              <scale>1 1 1</scale>
              <uri>/home/dylan/catkin_ws/src/robotiq/robotiq_description/meshes/collision/robotiq_85_knuckle_link.stl</uri>
            </mesh>
          </geometry>
          <max_contacts>10</max_contacts>
          <surface>
            <contact>
              <ode/>
            </contact>
            <bounce/>
            <friction>
              <torsional>
                <ode/>
              </torsional>
              <ode/>
            </friction>
          </surface>
        </collision>
        <collision name='robotiq_85_right_knuckle_link_fixed_joint_lump__robotiq_85_right_finger_link_collision_1'>
          <pose>-0.004086 -0.031486 0 0 -0 0</pose>
          <geometry>
            <mesh>
              <scale>1 1 1</scale>
              <uri>/home/dylan/catkin_ws/src/robotiq/robotiq_description/meshes/collision/robotiq_85_finger_link.stl</uri>
            </mesh>
          </geometry>
          <max_contacts>10</max_contacts>
          <surface>
            <contact>
              <ode/>
            </contact>
            <bounce/>
            <friction>
              <torsional>
                <ode/>
              </torsional>
              <ode/>
            </friction>
          </surface>
        </collision>
        <visual name='robotiq_85_right_knuckle_link_visual'>
          <pose>0 0 0 0 -0 0</pose>
          <geometry>
            <mesh>
              <scale>1 1 1</scale>
              <uri>/home/dylan/catkin_ws/src/robotiq/robotiq_description/meshes/visual/robotiq_85_knuckle_link.dae</uri>
            </mesh>
          </geometry>
        </visual>
        <visual name='robotiq_85_right_knuckle_link_fixed_joint_lump__robotiq_85_right_finger_link_visual_1'>
          <pose>-0.004086 -0.031486 0 0 -0 0</pose>
          <geometry>
            <mesh>
              <scale>1 1 1</scale>
              <uri>/home/dylan/catkin_ws/src/robotiq/robotiq_description/meshes/visual/robotiq_85_finger_link.dae</uri>
            </mesh>
          </geometry>
        </visual>
        <self_collide>0</self_collide>
        <enable_wind>0</enable_wind>
        <kinematic>0</kinematic>
      </link>
      <plugin name='ros_control' filename='libgazebo_ros_control.so'>
        <robotNamespace>/</robotNamespace>
      </plugin>
      <plugin name='mimic_robotiq_85_1' filename='libgazebo_mimic_joint_plugin.so'>
        <joint>robotiq_85_left_knuckle_joint</joint>
        <mimicJoint>robotiq_85_right_knuckle_joint</mimicJoint>
        <robotNamespace>/</robotNamespace>
      </plugin>
      <plugin name='mimic_robotiq_85_2' filename='libgazebo_mimic_joint_plugin.so'>
        <joint>robotiq_85_left_knuckle_joint</joint>
        <mimicJoint>robotiq_85_left_inner_knuckle_joint</mimicJoint>
        <robotNamespace>/</robotNamespace>
      </plugin>
      <plugin name='mimic_robotiq_85_3' filename='libgazebo_mimic_joint_plugin.so'>
        <joint>robotiq_85_left_knuckle_joint</joint>
        <mimicJoint>robotiq_85_right_inner_knuckle_joint</mimicJoint>
        <robotNamespace>/</robotNamespace>
      </plugin>
      <plugin name='mimic_robotiq_85_4' filename='libgazebo_mimic_joint_plugin.so'>
        <joint>robotiq_85_left_knuckle_joint</joint>
        <mimicJoint>robotiq_85_left_finger_tip_joint</mimicJoint>
        <multiplier>-1.0</multiplier>
        <offset>0.0</offset>
        <robotNamespace>/</robotNamespace>
      </plugin>
      <plugin name='mimic_robotiq_85_5' filename='libgazebo_mimic_joint_plugin.so'>
        <joint>robotiq_85_left_knuckle_joint</joint>
        <mimicJoint>robotiq_85_right_finger_tip_joint</mimicJoint>
        <multiplier>-1.0</multiplier>
        <offset>0.0</offset>
        <robotNamespace>/</robotNamespace>
      </plugin>
      <plugin name='ft_sensor_plugin' filename='libgazebo_ros_ft_sensor.so'>
        <updateRate>250.0</updateRate>
        <topicName>ft_sensor/raw</topicName>
        <gaussianNoise>0.0</gaussianNoise>
        <jointName>wrist_3_joint</jointName>
        <robotNamespace>/</robotNamespace>
      </plugin>
      <static>0</static>
      <gripper name='gazebo_gripper'>
        <grasp_check>
          <attach_steps>2</attach_steps>
          <detach_steps>2</detach_steps>
          <min_contact_count>3</min_contact_count>
        </grasp_check>
        <gripper_link>robotiq_85_left_finger_tip_link</gripper_link>
        <gripper_link>robotiq_85_right_finger_tip_link</gripper_link>
        <palm_link>wrist_3_link</palm_link>
      </gripper>
      <pose>0 0 1.21 0 -0 0</pose>
    </model>
  </world>
</sdf>
