<sdf version='1.7'>
  <world name='default'>
    <light name='sun' type='directional'>
      <cast_shadows>1</cast_shadows>
      <pose>0 0 10 0 -0 0</pose>
      <diffuse>0.8 0.8 0.8 1</diffuse>
      <specular>0.2 0.2 0.2 1</specular>
      <attenuation>
        <range>1000</range>
        <constant>0.9</constant>
        <linear>0.01</linear>
        <quadratic>0.001</quadratic>
      </attenuation>
      <direction>-0.5 0.1 -0.9</direction>
      <spot>
        <inner_angle>0</inner_angle>
        <outer_angle>0</outer_angle>
        <falloff>0</falloff>
      </spot>
    </light>
    <model name='ground_plane'>
      <static>1</static>
      <link name='link'>
        <collision name='collision'>
          <geometry>
            <plane>
              <normal>0 0 1</normal>
              <size>100 100</size>
            </plane>
          </geometry>
          <surface>
            <contact>
              <collide_bitmask>65535</collide_bitmask>
              <ode/>
            </contact>
            <friction>
              <ode>
                <mu>100</mu>
                <mu2>50</mu2>
              </ode>
              <torsional>
                <ode/>
              </torsional>
            </friction>
            <bounce/>
          </surface>
          <max_contacts>10</max_contacts>
        </collision>
        <visual name='visual'>
          <cast_shadows>0</cast_shadows>
          <geometry>
            <plane>
              <normal>0 0 1</normal>
              <size>100 100</size>
            </plane>
          </geometry>
          <material>
            <script>
              <uri>file://media/materials/scripts/gazebo.material</uri>
              <name>Gazebo/Grey</name>
            </script>
          </material>
        </visual>
        <self_collide>0</self_collide>
        <enable_wind>0</enable_wind>
        <kinematic>0</kinematic>
      </link>
    </model>
    <gravity>0 0 -9.8</gravity>
    <magnetic_field>6e-06 2.3e-05 -4.2e-05</magnetic_field>
    <atmosphere type='adiabatic'/>
    <physics name='default_physics' default='0' type='ode'>
      <max_step_size>0.001</max_step_size>
      <real_time_factor>1</real_time_factor>
      <real_time_update_rate>1000</real_time_update_rate>
    </physics>
    <scene>
      <ambient>0.4 0.4 0.4 1</ambient>
      <background>0.7 0.7 0.7 1</background>
      <shadows>1</shadows>
    </scene>
    <audio>
      <device>default</device>
    </audio>
    <wind/>
    <spherical_coordinates>
      <surface_model>EARTH_WGS84</surface_model>
      <latitude_deg>0</latitude_deg>
      <longitude_deg>0</longitude_deg>
      <elevation>0</elevation>
      <heading_deg>0</heading_deg>
    </spherical_coordinates>
    <state world_name='default'>
      <sim_time>2315 58000000</sim_time>
      <real_time>58 360696844</real_time>
      <wall_time>1695491043 301981110</wall_time>
      <iterations>51129</iterations>
      <model name='apple'>
        <pose>0.240926 0.655406 1.01539 0.003618 -0.000595 0.004996</pose>
        <scale>1 1 1</scale>
        <link name='link'>
          <pose>0.240926 0.655406 1.01539 0.003618 -0.000595 0.004996</pose>
          <velocity>0 0 0 0 -0 0</velocity>
          <acceleration>2.83871 -1.48741 0.770966 -2.41182 1.34804 -0.065257</acceleration>
          <wrench>0.0007 -0.000367 0.00019 0 -0 0</wrench>
        </link>
      </model>
      <model name='coke_can'>
        <pose>0.037914 0.437916 1.0471 -1.56645 -0.527882 0.325771</pose>
        <scale>1 1 1</scale>
        <link name='link'>
          <pose>0.037914 0.437916 1.0471 -1.56645 -0.527882 0.325771</pose>
          <velocity>0 0 0 0 -0 0</velocity>
          <acceleration>0.000209 5.8e-05 3e-06 -0.006349 0.019874 7.7e-05</acceleration>
          <wrench>8.1e-05 2.2e-05 1e-06 0 -0 0</wrench>
        </link>
      </model>
      <model name='dropbox'>
        <pose>0.3 -0.5 1.21 0 -0 1.5794</pose>
        <scale>1 1 1</scale>
        <link name='link_0'>
          <pose>0.3 -0.5 1.21 0 -0 0.01067</pose>
          <velocity>0 0 0 0 -0 0</velocity>
          <acceleration>0 0 0 0 -0 0</acceleration>
          <wrench>0 0 0 0 -0 0</wrench>
        </link>
      </model>
      <model name='dropbox_0'>
        <pose>-0.3 -0.5 1.21 0 -0 1.5794</pose>
        <scale>1 1 1</scale>
        <link name='link_0'>
          <pose>-0.3 -0.5 1.21 0 -0 0.01067</pose>
          <velocity>0 0 0 0 -0 0</velocity>
          <acceleration>0 0 0 0 -0 0</acceleration>
          <wrench>0 0 0 0 -0 0</wrench>
        </link>
      </model>
      <model name='ground_plane'>
        <pose>0 0 0 0 -0 0</pose>
        <scale>1 1 1</scale>
        <link name='link'>
          <pose>0 0 0 0 -0 0</pose>
          <velocity>0 0 0 0 -0 0</velocity>
          <acceleration>0 0 0 0 -0 0</acceleration>
          <wrench>0 0 0 0 -0 0</wrench>
        </link>
      </model>
      <model name='nist_elevated_floor_120'>
        <pose>0.005735 -0.482404 0 0 -0 0</pose>
        <scale>1 1 1</scale>
        <link name='nist_elevated_floor_120'>
          <pose>0.005735 -0.482404 0 0 -0 0</pose>
          <velocity>0 0 0 0 -0 0</velocity>
          <acceleration>0 0 0 0 -0 0</acceleration>
          <wrench>0 0 0 0 -0 0</wrench>
        </link>
      </model>
      <model name='phillips_screwdriver'>
        <pose>-0.229016 0.696911 1.01576 -0.01977 -0.010768 3.13525</pose>
        <scale>1.5 1.5 1.5</scale>
        <link name='link'>
          <pose>-0.229016 0.696911 1.01576 -0.01977 -0.010768 3.13525</pose>
          <velocity>0.00011 -4.3e-05 0.005077 0.03847 0.074081 -0.00232</velocity>
          <acceleration>0.797735 -0.337829 9.08442 -1.7874 -0.420836 -0.57829</acceleration>
          <wrench>6.1e-05 -2.6e-05 0.0007 0 -0 0</wrench>
        </link>
      </model>
      <model name='robot'>
        <pose>-0 0 1.21 0 -0 0</pose>
        <scale>1 1 1</scale>
        <link name='base_link'>
          <pose>-0 0 1.21 2.8e-05 -1e-06 -0</pose>
          <velocity>-2e-06 3e-06 6e-06 0.005415 -0.000204 0</velocity>
          <acceleration>-0.004843 0.007505 0.012094 -1.76532 -0.423914 -2.6e-05</acceleration>
          <wrench>-0.019371 0.03002 0.048376 0 -0 0</wrench>
        </link>
        <link name='camera_rgb_frame'>
          <pose>0 0.2 2.01 0 1.25 1.5708</pose>
          <velocity>0 0 -0 0 -0 0</velocity>
          <acceleration>0 0 0 0 -0 0</acceleration>
          <wrench>0 0 0 0 -0 0</wrench>
        </link>
        <link name='forearm_link'>
          <pose>0.423169 0.016645 1.25996 -3.14072 1.44391 -3.13954</pose>
          <velocity>0.000622 0.000458 0.007016 -0.024106 -0.007104 0.00632</velocity>
          <acceleration>1.60507 2.05764 16.7842 -2.70424 -1.23765 -1.81967</acceleration>
          <wrench>3.65153 4.68112 38.184 0 -0 0</wrench>
        </link>
        <link name='robotiq_85_left_finger_tip_link'>
          <pose>0.849416 0.310831 1.09214 0.603164 0.000137 1.55991</pose>
          <velocity>0.005555 -0.004028 -0.001901 -0.054514 -0.033728 -0.030648</velocity>
          <acceleration>5.55503 -4.02787 -1.90149 -2.63998 -0.118393 -2.66766</acceleration>
          <wrench>0.108629 -0.078765 -0.037184 0 -0 0</wrench>
        </link>
        <link name='robotiq_85_left_inner_knuckle_link'>
          <pose>0.825225 0.261682 1.10844 0.594593 -0.108056 1.71826</pose>
          <velocity>0.00293 -0.00249 -0.000374 -0.054875 -0.033834 -0.0306</velocity>
          <acceleration>2.92995 -2.48959 -0.373895 -0.484596 0.441609 2.43754</acceleration>
          <wrench>0.087755 -0.074566 -0.011199 0 -0 0</wrench>
        </link>
        <link name='robotiq_85_left_knuckle_link'>
          <pose>0.839896 0.255006 1.09828 0.59455 -0.10822 1.71833</pose>
          <velocity>0.003057 -0.003361 0.000469 0.047909 -0.038316 0.082848</velocity>
          <acceleration>6.94144 -3.97557 2.27296 1.54232 -1.18012 -2.88836</acceleration>
          <wrench>0.317918 -0.182081 0.104101 0 -0 0</wrench>
        </link>
        <link name='robotiq_85_right_finger_tip_link'>
          <pose>0.781199 0.311578 1.13913 -2.53845 0.000131 1.55991</pose>
          <velocity>0.003849 0.000259 -0.004252 -0.05262 -0.039026 -0.029833</velocity>
          <acceleration>3.84855 0.258619 -4.2516 -2.08891 0.546467 -1.86288</acceleration>
          <wrench>0.075258 0.005057 -0.08314 0 -0 0</wrench>
        </link>
        <link name='robotiq_85_right_inner_knuckle_link'>
          <pose>0.804309 0.261912 1.12285 -2.54706 0.108319 1.40156</pose>
          <velocity>0.002416 -0.001205 -0.001068 -0.052979 -0.038917 -0.029788</velocity>
          <acceleration>2.41553 -1.20513 -1.06794 -2.47052 -0.0067 0.886743</acceleration>
          <wrench>0.072348 -0.036095 -0.031986 0 -0 0</wrench>
        </link>
        <link name='robotiq_85_right_knuckle_link'>
          <pose>0.789496 0.255559 1.133 -2.54703 0.10824 1.40151</pose>
          <velocity>0.001817 -0.00031 -0.001313 -0.034001 -0.035271 -0.037343</velocity>
          <acceleration>1.48962 0.634972 -1.90754 0.775742 1.34136 -2.03691</acceleration>
          <wrench>0.068225 0.029082 -0.087366 0 -0 0</wrench>
        </link>
        <link name='shoulder_link'>
          <pose>0 -3e-06 1.29916 -5.1e-05 4e-06 0.001188</pose>
          <velocity>3.9e-05 -0.000578 -7e-06 -0.009868 0.000652 0.004956</velocity>
          <acceleration>0.083565 -1.17019 -0.015017 -0.755201 1.35908 -3.07812</acceleration>
          <wrench>0.309191 -4.3297 -0.055562 0 -0 0</wrench>
        </link>
        <link name='upper_arm_link'>
          <pose>-0.000161 0.135847 1.29915 -3.14065 1.47842 -3.13946</pose>
          <velocity>-0.00057 -0.000598 -0.001525 -0.016986 -0.014384 0.00483</velocity>
          <acceleration>-0.319155 0.480564 4.99755 -0.231383 1.13759 -2.77096</acceleration>
          <wrench>-2.67867 4.03338 41.9444 0 -0 0</wrench>
        </link>
        <link name='wrist_1_link'>
          <pose>0.812265 0.017103 1.21031 -3.14146 0.010081 -3.14039</pose>
          <velocity>0.000904 0.001868 0.00796 -0.025533 0.033968 0.006901</velocity>
          <acceleration>0.576726 3.38213 11.2104 -0.5068 -1.5491 0.908924</acceleration>
          <wrench>0.703029 4.12282 13.6654 0 -0 0</wrench>
        </link>
        <link name='wrist_2_link'>
          <pose>0.812154 0.1101 1.2103 -3.14156 0.010082 3.13066</pose>
          <velocity>0.000259 0.001144 0.005446 -0.029931 0.033932 -0.037025</velocity>
          <acceleration>-5.82333 -3.75492 10.859 -0.19318 -1.50771 -2.08199</acceleration>
          <wrench>-7.09864 -4.57725 13.2372 0 -0 0</wrench>
        </link>
        <link name='wrist_3_link'>
          <pose>0.813108 0.110086 1.11565 -3.14154 -0.603157 3.13063</pose>
          <velocity>-0.002948 -0.001754 0.004553 -0.033192 -0.036037 -0.037044</velocity>
          <acceleration>0.481104 -3.85374 3.57602 1.88783 1.05315 -2.03534</acceleration>
          <wrench>0.477665 -3.82619 3.55045 0 -0 0</wrench>
        </link>
      </model>
      <model name='table'>
        <pose>1.8e-05 0.659275 0 0 -0 0</pose>
        <scale>1 1 1</scale>
        <link name='link'>
          <pose>1.8e-05 0.659275 0 0 -0 0</pose>
          <velocity>0 0 0 0 -0 0</velocity>
          <acceleration>0 0 0 0 -0 0</acceleration>
          <wrench>0 0 0 0 -0 0</wrench>
        </link>
      </model>
      <light name='sun'>
        <pose>0 0 10 0 -0 0</pose>
      </light>
    </state>
    <gui fullscreen='0'>
      <camera name='user_camera'>
        <pose>-0.158606 0.427926 2.95139 0 1.44174 1.90873</pose>
        <view_controller>orbit</view_controller>
        <projection_type>perspective</projection_type>
      </camera>
    </gui>
    <model name='nist_elevated_floor_120'>
      <static>1</static>
      <link name='nist_elevated_floor_120'>
        <pose>0 0 0 0 -0 0</pose>
        <collision name='collision'>
          <geometry>
            <mesh>
              <uri>model://nist_elevated_floor_120/meshes/nist_elevated_floor_120.dae</uri>
              <scale>1 1 1</scale>
            </mesh>
          </geometry>
          <max_contacts>10</max_contacts>
          <surface>
            <contact>
              <ode/>
            </contact>
            <bounce/>
            <friction>
              <torsional>
                <ode/>
              </torsional>
              <ode/>
            </friction>
          </surface>
        </collision>
        <visual name='visual'>
          <geometry>
            <mesh>
              <uri>model://nist_elevated_floor_120/meshes/nist_elevated_floor_120.dae</uri>
              <scale>1 1 1</scale>
            </mesh>
          </geometry>
        </visual>
        <self_collide>0</self_collide>
        <enable_wind>0</enable_wind>
        <kinematic>0</kinematic>
      </link>
      <pose>0.297914 -0.687027 0 0 -0 0</pose>
    </model>
    <model name='table'>
      <static>1</static>
      <link name='link'>
        <collision name='surface'>
          <pose>0 0 1 0 -0 0</pose>
          <geometry>
            <box>
              <size>1.5 0.8 0.03</size>
            </box>
          </geometry>
          <surface>
            <friction>
              <ode>
                <mu>0.6</mu>
                <mu2>0.6</mu2>
              </ode>
              <torsional>
                <ode/>
              </torsional>
            </friction>
            <contact>
              <ode/>
            </contact>
            <bounce/>
          </surface>
          <max_contacts>10</max_contacts>
        </collision>
        <visual name='visual1'>
          <pose>0 0 1 0 -0 0</pose>
          <geometry>
            <box>
              <size>1.5 0.8 0.03</size>
            </box>
          </geometry>
          <material>
            <script>
              <uri>file://media/materials/scripts/gazebo.material</uri>
              <name>Gazebo/White</name>
            </script>
          </material>
        </visual>
        <collision name='front_left_leg'>
          <pose>0.68 0.38 0.5 0 -0 0</pose>
          <geometry>
            <cylinder>
              <radius>0.02</radius>
              <length>1</length>
            </cylinder>
          </geometry>
          <max_contacts>10</max_contacts>
          <surface>
            <contact>
              <ode/>
            </contact>
            <bounce/>
            <friction>
              <torsional>
                <ode/>
              </torsional>
              <ode/>
            </friction>
          </surface>
        </collision>
        <visual name='front_left_leg'>
          <pose>0.68 0.38 0.5 0 -0 0</pose>
          <geometry>
            <cylinder>
              <radius>0.02</radius>
              <length>1</length>
            </cylinder>
          </geometry>
          <material>
            <script>
              <uri>file://media/materials/scripts/gazebo.material</uri>
              <name>Gazebo/Grey</name>
            </script>
          </material>
        </visual>
        <collision name='front_right_leg'>
          <pose>0.68 -0.38 0.5 0 -0 0</pose>
          <geometry>
            <cylinder>
              <radius>0.02</radius>
              <length>1</length>
            </cylinder>
          </geometry>
          <max_contacts>10</max_contacts>
          <surface>
            <contact>
              <ode/>
            </contact>
            <bounce/>
            <friction>
              <torsional>
                <ode/>
              </torsional>
              <ode/>
            </friction>
          </surface>
        </collision>
        <visual name='front_right_leg'>
          <pose>0.68 -0.38 0.5 0 -0 0</pose>
          <geometry>
            <cylinder>
              <radius>0.02</radius>
              <length>1</length>
            </cylinder>
          </geometry>
          <material>
            <script>
              <uri>file://media/materials/scripts/gazebo.material</uri>
              <name>Gazebo/Grey</name>
            </script>
          </material>
        </visual>
        <collision name='back_right_leg'>
          <pose>-0.68 -0.38 0.5 0 -0 0</pose>
          <geometry>
            <cylinder>
              <radius>0.02</radius>
              <length>1</length>
            </cylinder>
          </geometry>
          <max_contacts>10</max_contacts>
          <surface>
            <contact>
              <ode/>
            </contact>
            <bounce/>
            <friction>
              <torsional>
                <ode/>
              </torsional>
              <ode/>
            </friction>
          </surface>
        </collision>
        <visual name='back_right_leg'>
          <pose>-0.68 -0.38 0.5 0 -0 0</pose>
          <geometry>
            <cylinder>
              <radius>0.02</radius>
              <length>1</length>
            </cylinder>
          </geometry>
          <material>
            <script>
              <uri>file://media/materials/scripts/gazebo.material</uri>
              <name>Gazebo/Grey</name>
            </script>
          </material>
        </visual>
        <collision name='back_left_leg'>
          <pose>-0.68 0.38 0.5 0 -0 0</pose>
          <geometry>
            <cylinder>
              <radius>0.02</radius>
              <length>1</length>
            </cylinder>
          </geometry>
          <max_contacts>10</max_contacts>
          <surface>
            <contact>
              <ode/>
            </contact>
            <bounce/>
            <friction>
              <torsional>
                <ode/>
              </torsional>
              <ode/>
            </friction>
          </surface>
        </collision>
        <visual name='back_left_leg'>
          <pose>-0.68 0.38 0.5 0 -0 0</pose>
          <geometry>
            <cylinder>
              <radius>0.02</radius>
              <length>1</length>
            </cylinder>
          </geometry>
          <material>
            <script>
              <uri>file://media/materials/scripts/gazebo.material</uri>
              <name>Gazebo/Grey</name>
            </script>
          </material>
        </visual>
        <self_collide>0</self_collide>
        <enable_wind>0</enable_wind>
        <kinematic>0</kinematic>
      </link>
      <pose>0.270759 1.80105 0 0 -0 0</pose>
    </model>
    <model name='dropbox'>
      <link name='link_0'>
        <pose>0 -0 0 0 0 -1.56873</pose>
        <inertial>
          <mass>1</mass>
          <inertia>
            <ixx>0.166667</ixx>
            <ixy>0</ixy>
            <ixz>0</ixz>
            <iyy>0.166667</iyy>
            <iyz>0</iyz>
            <izz>0.166667</izz>
          </inertia>
        </inertial>
        <visual name='visual'>
          <pose>0 0 0 0 -0 0</pose>
          <geometry>
            <mesh>
              <uri>model://dropbox/meshes/dropbox.dae</uri>
              <scale>1 1 1</scale>
            </mesh>
          </geometry>
          <material>
            <lighting>1</lighting>
            <script>
              <uri>file://media/materials/scripts/gazebo.material</uri>
              <name>Gazebo/Green</name>
            </script>
          </material>
          <transparency>0</transparency>
          <cast_shadows>1</cast_shadows>
        </visual>
        <collision name='collision'>
          <laser_retro>0</laser_retro>
          <max_contacts>10</max_contacts>
          <pose>0 0 0 0 -0 0</pose>
          <geometry>
            <mesh>
              <uri>model://dropbox/meshes/dropbox.dae</uri>
              <scale>1 1 1</scale>
            </mesh>
          </geometry>
          <surface>
            <friction>
              <ode>
                <mu>1</mu>
                <mu2>1</mu2>
                <fdir1>0 0 0</fdir1>
                <slip1>0</slip1>
                <slip2>0</slip2>
              </ode>
              <torsional>
                <coefficient>1</coefficient>
                <patch_radius>0</patch_radius>
                <surface_radius>0</surface_radius>
                <use_patch_radius>1</use_patch_radius>
                <ode>
                  <slip>0</slip>
                </ode>
              </torsional>
            </friction>
            <bounce>
              <restitution_coefficient>0</restitution_coefficient>
              <threshold>1e+06</threshold>
            </bounce>
            <contact>
              <collide_without_contact>0</collide_without_contact>
              <collide_without_contact_bitmask>1</collide_without_contact_bitmask>
              <collide_bitmask>1</collide_bitmask>
              <ode>
                <soft_cfm>0</soft_cfm>
                <soft_erp>0.2</soft_erp>
                <kp>1e+13</kp>
                <kd>1</kd>
                <max_vel>0.01</max_vel>
                <min_depth>0</min_depth>
              </ode>
              <bullet>
                <split_impulse>1</split_impulse>
                <split_impulse_penetration_threshold>-0.01</split_impulse_penetration_threshold>
                <soft_cfm>0</soft_cfm>
                <soft_erp>0.2</soft_erp>
                <kp>1e+13</kp>
                <kd>1</kd>
              </bullet>
            </contact>
          </surface>
        </collision>
        <self_collide>0</self_collide>
        <enable_wind>0</enable_wind>
        <kinematic>0</kinematic>
      </link>
      <static>1</static>
      <allow_auto_disable>1</allow_auto_disable>
      <pose>0.050723 -0.333588 0 0 -0 0</pose>
    </model>
    <model name='dropbox_0'>
      <link name='link_0'>
        <pose>0 -0 0 0 0 -1.56873</pose>
        <inertial>
          <mass>1</mass>
          <inertia>
            <ixx>0.166667</ixx>
            <ixy>0</ixy>
            <ixz>0</ixz>
            <iyy>0.166667</iyy>
            <iyz>0</iyz>
            <izz>0.166667</izz>
          </inertia>
        </inertial>
        <visual name='visual'>
          <pose>0 0 0 0 -0 0</pose>
          <geometry>
            <mesh>
              <uri>model://dropbox/meshes/dropbox.dae</uri>
              <scale>1 1 1</scale>
            </mesh>
          </geometry>
          <material>
            <lighting>1</lighting>
            <script>
              <uri>file://media/materials/scripts/gazebo.material</uri>
              <name>Gazebo/Blue</name>
            </script>
            <ambient>0.3 0.3 0.3 1</ambient>
            <diffuse>0.7 0.7 0.7 1</diffuse>
            <specular>0.01 0.01 0.01 1</specular>
            <emissive>0 0 1 1</emissive>
          </material>
          <transparency>0</transparency>
          <cast_shadows>1</cast_shadows>
        </visual>
        <collision name='collision'>
          <laser_retro>0</laser_retro>
          <max_contacts>10</max_contacts>
          <pose>0 0 0 0 -0 0</pose>
          <geometry>
            <mesh>
              <uri>model://dropbox/meshes/dropbox.dae</uri>
              <scale>1 1 1</scale>
            </mesh>
          </geometry>
          <surface>
            <friction>
              <ode>
                <mu>1</mu>
                <mu2>1</mu2>
                <fdir1>0 0 0</fdir1>
                <slip1>0</slip1>
                <slip2>0</slip2>
              </ode>
              <torsional>
                <coefficient>1</coefficient>
                <patch_radius>0</patch_radius>
                <surface_radius>0</surface_radius>
                <use_patch_radius>1</use_patch_radius>
                <ode>
                  <slip>0</slip>
                </ode>
              </torsional>
            </friction>
            <bounce>
              <restitution_coefficient>0</restitution_coefficient>
              <threshold>1e+06</threshold>
            </bounce>
            <contact>
              <collide_without_contact>0</collide_without_contact>
              <collide_without_contact_bitmask>1</collide_without_contact_bitmask>
              <collide_bitmask>1</collide_bitmask>
              <ode>
                <soft_cfm>0</soft_cfm>
                <soft_erp>0.2</soft_erp>
                <kp>1e+13</kp>
                <kd>1</kd>
                <max_vel>0.01</max_vel>
                <min_depth>0</min_depth>
              </ode>
              <bullet>
                <split_impulse>1</split_impulse>
                <split_impulse_penetration_threshold>-0.01</split_impulse_penetration_threshold>
                <soft_cfm>0</soft_cfm>
                <soft_erp>0.2</soft_erp>
                <kp>1e+13</kp>
                <kd>1</kd>
              </bullet>
            </contact>
          </surface>
        </collision>
        <self_collide>0</self_collide>
        <enable_wind>0</enable_wind>
        <kinematic>0</kinematic>
      </link>
      <static>1</static>
      <allow_auto_disable>1</allow_auto_disable>
      <pose>-2.64764 -2.53009 0 0 -0 0</pose>
    </model>
    <model name='phillips_screwdriver'>
      <static>0</static>
      <link name='link'>
        <inertial>
          <pose>0.002663 0.022224 0.016372 1.65222 -1.00568 -1.17449</pose>
          <mass>7.70055e-05</mass>
          <inertia>
            <ixx>1.08681e-07</ixx>
            <ixy>-8.47264e-24</ixy>
            <ixz>4.22641e-24</ixz>
            <iyy>1.08634e-07</iyy>
            <iyz>-1.00542e-23</iyz>
            <izz>8.53822e-09</izz>
          </inertia>
        </inertial>
        <collision name='collision'>
          <geometry>
            <mesh>
              <uri>model://043_phillips_screwdriver/google_16k/textured.obj</uri>
              <scale>1.5 1.5 1.5</scale>
            </mesh>
          </geometry>
          <surface>
            <contact>
              <ode/>
            </contact>
            <bounce/>
            <friction>
              <torsional>
                <ode/>
              </torsional>
              <ode/>
            </friction>
          </surface>
          <max_contacts>10</max_contacts>
        </collision>
        <visual name='visual'>
          <geometry>
            <mesh>
              <uri>model://043_phillips_screwdriver/google_16k/textured.obj</uri>
              <scale>1.5 1.5 1.5</scale>
            </mesh>
          </geometry>
          <material>
            <script>
              <uri>model://043_phillips_screwdriver/phillips_screwdriver.material</uri>
              <name>phillips_screwdriver</name>
            </script>
          </material>
        </visual>
        <self_collide>0</self_collide>
        <enable_wind>0</enable_wind>
        <kinematic>0</kinematic>
      </link>
      <pose>-0.237107 0.645908 0 0 -0 0</pose>
    </model>
    <model name='coke_can'>
      <link name='link'>
        <inertial>
          <pose>0 0 0.06 0 -0 0</pose>
          <mass>0.39</mass>
          <inertia>
            <ixx>0.00055575</ixx>
            <ixy>0</ixy>
            <ixz>0</ixz>
            <iyy>0.00055575</iyy>
            <iyz>0</iyz>
            <izz>0.0001755</izz>
          </inertia>
        </inertial>
        <collision name='collision'>
          <pose>0.003937 0.004724 -0.18 0 -0 0</pose>
          <geometry>
            <mesh>
              <uri>model://coke_can/meshes/coke_can.dae</uri>
            </mesh>
          </geometry>
          <surface>
            <friction>
              <ode>
                <mu>1</mu>
                <mu2>1</mu2>
              </ode>
              <torsional>
                <ode/>
              </torsional>
            </friction>
            <contact>
              <ode>
                <kp>1e+07</kp>
                <kd>1</kd>
                <min_depth>0.001</min_depth>
                <max_vel>0.1</max_vel>
              </ode>
            </contact>
            <bounce/>
          </surface>
          <max_contacts>10</max_contacts>
        </collision>
        <visual name='visual'>
          <pose>0.003937 0.004724 -0.18 0 -0 0</pose>
          <geometry>
            <mesh>
              <uri>model://coke_can/meshes/coke_can.dae</uri>
            </mesh>
          </geometry>
        </visual>
        <self_collide>0</self_collide>
        <enable_wind>0</enable_wind>
        <kinematic>0</kinematic>
      </link>
      <pose>1.02847 0.762003 0 0 -0 0</pose>
    </model>
    <model name='apple'>
      <static>0</static>
      <link name='link'>
        <inertial>
          <pose>0.001311 -0.003861 0.036337 1.28659 -0.495792 -1.57796</pose>
          <mass>0.000246595</mass>
          <inertia>
            <ixx>1.53466e-07</ixx>
            <ixy>-2.64698e-23</ixy>
            <ixz>0</ixz>
            <iyy>1.52372e-07</iyy>
            <iyz>0</iyz>
            <izz>1.50583e-07</izz>
          </inertia>
        </inertial>
        <collision name='collision'>
          <geometry>
            <mesh>
              <uri>model://013_apple/google_16k/textured.obj</uri>
            </mesh>
          </geometry>
          <surface>
            <contact>
              <ode/>
            </contact>
            <bounce/>
            <friction>
              <torsional>
                <ode/>
              </torsional>
              <ode/>
            </friction>
          </surface>
          <max_contacts>10</max_contacts>
        </collision>
        <visual name='visual'>
          <geometry>
            <mesh>
              <uri>model://013_apple/google_16k/textured.obj</uri>
            </mesh>
          </geometry>
          <material>
            <script>
              <uri>model://013_apple/apple.material</uri>
              <name>apple</name>
            </script>
          </material>
        </visual>
        <self_collide>0</self_collide>
        <enable_wind>0</enable_wind>
        <kinematic>0</kinematic>
      </link>
      <pose>-1.71301 1.00919 0 0 -0 0</pose>
    </model>
    <model name='robot'>
      <joint name='camera_rgb_joint' type='fixed'>
        <pose relative_to='__model__'>0 0.2 0.8 0 1.25 1.5708</pose>
        <parent>world</parent>
        <child>camera_rgb_frame</child>
      </joint>
      <link name='camera_rgb_frame'>
        <pose relative_to='camera_rgb_joint'>0 0 0 0 -0 0</pose>
        <inertial>
          <pose>-0.0062 0 -0.0032 0 -0 0</pose>
          <mass>0.005</mass>
          <inertia>
            <ixx>0.000500205</ixx>
            <ixy>0</ixy>
            <ixz>-3.968e-07</ixz>
            <iyy>0.000500974</iyy>
            <iyz>0</iyz>
            <izz>0.000500769</izz>
          </inertia>
        </inertial>
        <collision name='camera_rgb_frame_fixed_joint_lump__camera_link_collision'>
          <pose>-0.031 0 -0.016 0 -0 0</pose>
          <geometry>
            <box>
              <size>0.07271 0.27794 0.073</size>
            </box>
          </geometry>
          <max_contacts>10</max_contacts>
          <surface>
            <contact>
              <ode/>
            </contact>
            <bounce/>
            <friction>
              <torsional>
                <ode/>
              </torsional>
              <ode/>
            </friction>
          </surface>
        </collision>
        <visual name='camera_rgb_frame_fixed_joint_lump__camera_link_visual'>
          <pose>-0.031 0 -0.016 0 -0 1.5708</pose>
          <geometry>
            <mesh>
              <scale>1 1 1</scale>
              <uri>/home/dylan/catkin_ws/src/common-sensors/common_sensors/meshes/sensors/kinect.dae</uri>
            </mesh>
          </geometry>
        </visual>
        <sensor name='camera1' type='depth'>
          <always_on>1</always_on>
          <update_rate>20</update_rate>
          <camera>
            <horizontal_fov>1.0472</horizontal_fov>
            <image>
              <format>R8G8B8</format>
              <width>640</width>
              <height>480</height>
            </image>
            <clip>
              <near>0.05</near>
              <far>8</far>
            </clip>
          </camera>
          <plugin name='camera_depth_frame_kinect_controller' filename='libgazebo_ros_openni_kinect.so'>
            <baseline>0.1</baseline>
            <alwaysOn>1</alwaysOn>
            <updateRate>10</updateRate>
            <cameraName>camera1</cameraName>
            <imageTopicName>rgb/image_raw</imageTopicName>
            <cameraInfoTopicName>rgb/camera_info</cameraInfoTopicName>
            <depthImageTopicName>depth/image_raw</depthImageTopicName>
            <depthImageCameraInfoTopicName>depth/camera_info</depthImageCameraInfoTopicName>
            <pointCloudTopicName>depth/points</pointCloudTopicName>
            <frameName>camera_depth_optical_frame</frameName>
            <pointCloudCutoff>0.3</pointCloudCutoff>
            <distortion_k1>0.0</distortion_k1>
            <distortion_k2>0.0</distortion_k2>
            <distortion_k3>0.0</distortion_k3>
            <distortion_t1>0.0</distortion_t1>
            <distortion_t2>0.0</distortion_t2>
            <robotNamespace>/</robotNamespace>
          </plugin>
          <pose>0 0 0 0 -0 0</pose>
        </sensor>
        <self_collide>0</self_collide>
        <enable_wind>0</enable_wind>
        <kinematic>0</kinematic>
      </link>
      <joint name='world_joint' type='fixed'>
        <pose relative_to='__model__'>0 0 0 0 -0 0</pose>
        <parent>world</parent>
        <child>base_link</child>
      </joint>
      <link name='base_link'>
        <pose relative_to='world_joint'>0 0 0 0 -0 0</pose>
        <inertial>
          <pose>0 0 0 0 -0 0</pose>
          <mass>4</mass>
          <inertia>
            <ixx>0.00443333</ixx>
            <ixy>0</ixy>
            <ixz>0</ixz>
            <iyy>0.00443333</iyy>
            <iyz>0</iyz>
            <izz>0.0072</izz>
          </inertia>
        </inertial>
        <collision name='base_link_collision'>
          <pose>0 0 0 0 -0 0</pose>
          <geometry>
            <mesh>
              <scale>1 1 1</scale>
              <uri>/home/dylan/catkin_ws/src/universal_robot/ur_description/meshes/ur5/collision/base.stl</uri>
            </mesh>
          </geometry>
          <max_contacts>10</max_contacts>
          <surface>
            <contact>
              <ode/>
            </contact>
            <bounce/>
            <friction>
              <torsional>
                <ode/>
              </torsional>
              <ode/>
            </friction>
          </surface>
        </collision>
        <visual name='base_link_visual'>
          <pose>0 0 0 0 -0 0</pose>
          <geometry>
            <mesh>
              <scale>1 1 1</scale>
              <uri>/home/dylan/catkin_ws/src/universal_robot/ur_description/meshes/ur5/visual/base.dae</uri>
            </mesh>
          </geometry>
        </visual>
        <self_collide>0</self_collide>
        <enable_wind>0</enable_wind>
        <kinematic>0</kinematic>
      </link>
      <joint name='shoulder_pan_joint' type='revolute'>
        <pose relative_to='base_link'>0 0 0.089159 0 -0 0</pose>
        <parent>base_link</parent>
        <child>shoulder_link</child>
        <axis>
          <xyz>0 0 1</xyz>
          <limit>
            <lower>-3.14159</lower>
            <upper>3.14159</upper>
            <effort>150</effort>
            <velocity>3.15</velocity>
          </limit>
          <dynamics>
            <damping>0</damping>
            <friction>0</friction>
            <spring_reference>0</spring_reference>
            <spring_stiffness>0</spring_stiffness>
          </dynamics>
        </axis>
      </joint>
      <link name='shoulder_link'>
        <pose relative_to='shoulder_pan_joint'>0 0 0 0 -0 0</pose>
        <inertial>
          <pose>0 0 0 0 -0 0</pose>
          <mass>3.7</mass>
          <inertia>
            <ixx>0.0102675</ixx>
            <ixy>0</ixy>
            <ixz>0</ixz>
            <iyy>0.0102675</iyy>
            <iyz>0</iyz>
            <izz>0.00666</izz>
          </inertia>
        </inertial>
        <collision name='shoulder_link_collision'>
          <pose>0 0 0 0 -0 0</pose>
          <geometry>
            <mesh>
              <scale>1 1 1</scale>
              <uri>/home/dylan/catkin_ws/src/universal_robot/ur_description/meshes/ur5/collision/shoulder.stl</uri>
            </mesh>
          </geometry>
          <surface>
            <contact>
              <ode/>
            </contact>
            <friction>
              <ode/>
              <torsional>
                <ode/>
              </torsional>
            </friction>
            <bounce/>
          </surface>
          <max_contacts>10</max_contacts>
        </collision>
        <visual name='shoulder_link_visual'>
          <pose>0 0 0 0 -0 0</pose>
          <geometry>
            <mesh>
              <scale>1 1 1</scale>
              <uri>/home/dylan/catkin_ws/src/universal_robot/ur_description/meshes/ur5/visual/shoulder.dae</uri>
            </mesh>
          </geometry>
        </visual>
        <self_collide>1</self_collide>
        <enable_wind>0</enable_wind>
        <kinematic>0</kinematic>
      </link>
      <joint name='shoulder_lift_joint' type='revolute'>
        <pose relative_to='shoulder_link'>0 0.13585 0 3.14159 1.57079 3.14159</pose>
        <parent>shoulder_link</parent>
        <child>upper_arm_link</child>
        <axis>
          <xyz>0 1 0</xyz>
          <limit>
            <lower>-3.14159</lower>
            <upper>3.14159</upper>
            <effort>150</effort>
            <velocity>3.15</velocity>
          </limit>
          <dynamics>
            <damping>0</damping>
            <friction>0</friction>
            <spring_reference>0</spring_reference>
            <spring_stiffness>0</spring_stiffness>
          </dynamics>
        </axis>
      </joint>
      <link name='upper_arm_link'>
        <pose relative_to='shoulder_lift_joint'>0 0 0 0 -0 0</pose>
        <inertial>
          <pose>0 0 0.28 0 -0 0</pose>
          <mass>8.393</mass>
          <inertia>
            <ixx>0.226891</ixx>
            <ixy>0</ixy>
            <ixz>0</ixz>
            <iyy>0.226891</iyy>
            <iyz>0</iyz>
            <izz>0.0151074</izz>
          </inertia>
        </inertial>
        <collision name='upper_arm_link_collision'>
          <pose>0 0 0 0 -0 0</pose>
          <geometry>
            <mesh>
              <scale>1 1 1</scale>
              <uri>/home/dylan/catkin_ws/src/universal_robot/ur_description/meshes/ur5/collision/upperarm.stl</uri>
            </mesh>
          </geometry>
          <surface>
            <contact>
              <ode/>
            </contact>
            <friction>
              <ode/>
              <torsional>
                <ode/>
              </torsional>
            </friction>
            <bounce/>
          </surface>
          <max_contacts>10</max_contacts>
        </collision>
        <visual name='upper_arm_link_visual'>
          <pose>0 0 0 0 -0 0</pose>
          <geometry>
            <mesh>
              <scale>1 1 1</scale>
              <uri>/home/dylan/catkin_ws/src/universal_robot/ur_description/meshes/ur5/visual/upperarm.dae</uri>
            </mesh>
          </geometry>
        </visual>
        <self_collide>1</self_collide>
        <enable_wind>0</enable_wind>
        <kinematic>0</kinematic>
      </link>
      <joint name='elbow_joint' type='revolute'>
        <pose relative_to='upper_arm_link'>0 -0.1197 0.425 0 -0 0</pose>
        <parent>upper_arm_link</parent>
        <child>forearm_link</child>
        <axis>
          <xyz>0 1 0</xyz>
          <limit>
            <lower>-3.14159</lower>
            <upper>3.14159</upper>
            <effort>150</effort>
            <velocity>3.15</velocity>
          </limit>
          <dynamics>
            <damping>0</damping>
            <friction>0</friction>
            <spring_reference>0</spring_reference>
            <spring_stiffness>0</spring_stiffness>
          </dynamics>
        </axis>
      </joint>
      <link name='forearm_link'>
        <pose relative_to='elbow_joint'>0 0 0 0 -0 0</pose>
        <inertial>
          <pose>0 0 0.196125 0 -0 0</pose>
          <mass>2.275</mass>
          <inertia>
            <ixx>0.0312168</ixx>
            <ixy>0</ixy>
            <ixz>0</ixz>
            <iyy>0.0312168</iyy>
            <iyz>0</iyz>
            <izz>0.004095</izz>
          </inertia>
        </inertial>
        <collision name='forearm_link_collision'>
          <pose>0 0 0 0 -0 0</pose>
          <geometry>
            <mesh>
              <scale>1 1 1</scale>
              <uri>/home/dylan/catkin_ws/src/universal_robot/ur_description/meshes/ur5/collision/forearm.stl</uri>
            </mesh>
          </geometry>
          <surface>
            <contact>
              <ode/>
            </contact>
            <friction>
              <ode/>
              <torsional>
                <ode/>
              </torsional>
            </friction>
            <bounce/>
          </surface>
          <max_contacts>10</max_contacts>
        </collision>
        <visual name='forearm_link_visual'>
          <pose>0 0 0 0 -0 0</pose>
          <geometry>
            <mesh>
              <scale>1 1 1</scale>
              <uri>/home/dylan/catkin_ws/src/universal_robot/ur_description/meshes/ur5/visual/forearm.dae</uri>
            </mesh>
          </geometry>
        </visual>
        <self_collide>1</self_collide>
        <enable_wind>0</enable_wind>
        <kinematic>0</kinematic>
      </link>
      <joint name='wrist_1_joint' type='revolute'>
        <pose relative_to='forearm_link'>0 0 0.39225 3.14159 1.57079 3.14159</pose>
        <parent>forearm_link</parent>
        <child>wrist_1_link</child>
        <axis>
          <xyz>0 1 0</xyz>
          <limit>
            <lower>-3.14159</lower>
            <upper>3.14159</upper>
            <effort>28</effort>
            <velocity>3.2</velocity>
          </limit>
          <dynamics>
            <damping>0</damping>
            <friction>0</friction>
            <spring_reference>0</spring_reference>
            <spring_stiffness>0</spring_stiffness>
          </dynamics>
        </axis>
      </joint>
      <link name='wrist_1_link'>
        <pose relative_to='wrist_1_joint'>0 0 0 0 -0 0</pose>
        <inertial>
          <pose>0 0.093 0 0 -0 0</pose>
          <mass>1.219</mass>
          <inertia>
            <ixx>0.0025599</ixx>
            <ixy>0</ixy>
            <ixz>0</ixz>
            <iyy>0.0025599</iyy>
            <iyz>0</iyz>
            <izz>0.0021942</izz>
          </inertia>
        </inertial>
        <collision name='wrist_1_link_collision'>
          <pose>0 0 0 0 -0 0</pose>
          <geometry>
            <mesh>
              <scale>1 1 1</scale>
              <uri>/home/dylan/catkin_ws/src/universal_robot/ur_description/meshes/ur5/collision/wrist1.stl</uri>
            </mesh>
          </geometry>
          <surface>
            <contact>
              <ode/>
            </contact>
            <friction>
              <ode/>
              <torsional>
                <ode/>
              </torsional>
            </friction>
            <bounce/>
          </surface>
          <max_contacts>10</max_contacts>
        </collision>
        <visual name='wrist_1_link_visual'>
          <pose>0 0 0 0 -0 0</pose>
          <geometry>
            <mesh>
              <scale>1 1 1</scale>
              <uri>/home/dylan/catkin_ws/src/universal_robot/ur_description/meshes/ur5/visual/wrist1.dae</uri>
            </mesh>
          </geometry>
        </visual>
        <self_collide>1</self_collide>
        <enable_wind>0</enable_wind>
        <kinematic>0</kinematic>
      </link>
      <joint name='wrist_2_joint' type='revolute'>
        <pose relative_to='wrist_1_link'>0 0.093 0 0 -0 0</pose>
        <parent>wrist_1_link</parent>
        <child>wrist_2_link</child>
        <axis>
          <xyz>0 0 1</xyz>
          <limit>
            <lower>-3.14159</lower>
            <upper>3.14159</upper>
            <effort>28</effort>
            <velocity>3.2</velocity>
          </limit>
          <dynamics>
            <damping>0</damping>
            <friction>0</friction>
            <spring_reference>0</spring_reference>
            <spring_stiffness>0</spring_stiffness>
          </dynamics>
        </axis>
      </joint>
      <link name='wrist_2_link'>
        <pose relative_to='wrist_2_joint'>0 0 0 0 -0 0</pose>
        <inertial>
          <pose>0 0 0.09465 0 -0 0</pose>
          <mass>1.219</mass>
          <inertia>
            <ixx>0.0025599</ixx>
            <ixy>0</ixy>
            <ixz>0</ixz>
            <iyy>0.0025599</iyy>
            <iyz>0</iyz>
            <izz>0.0021942</izz>
          </inertia>
        </inertial>
        <collision name='wrist_2_link_collision'>
          <pose>0 0 0 0 -0 0</pose>
          <geometry>
            <mesh>
              <scale>1 1 1</scale>
              <uri>/home/dylan/catkin_ws/src/universal_robot/ur_description/meshes/ur5/collision/wrist2.stl</uri>
            </mesh>
          </geometry>
          <surface>
            <contact>
              <ode/>
            </contact>
            <friction>
              <ode/>
              <torsional>
                <ode/>
              </torsional>
            </friction>
            <bounce/>
          </surface>
          <max_contacts>10</max_contacts>
        </collision>
        <visual name='wrist_2_link_visual'>
          <pose>0 0 0 0 -0 0</pose>
          <geometry>
            <mesh>
              <scale>1 1 1</scale>
              <uri>/home/dylan/catkin_ws/src/universal_robot/ur_description/meshes/ur5/visual/wrist2.dae</uri>
            </mesh>
          </geometry>
        </visual>
        <self_collide>1</self_collide>
        <enable_wind>0</enable_wind>
        <kinematic>0</kinematic>
      </link>
      <joint name='wrist_3_joint' type='revolute'>
        <pose relative_to='wrist_2_link'>0 0 0.09465 0 -0 0</pose>
        <parent>wrist_2_link</parent>
        <child>wrist_3_link</child>
        <axis>
          <xyz>0 1 0</xyz>
          <limit>
            <lower>-3.14159</lower>
            <upper>3.14159</upper>
            <effort>28</effort>
            <velocity>3.2</velocity>
          </limit>
          <dynamics>
            <damping>0</damping>
            <friction>0</friction>
            <spring_reference>0</spring_reference>
            <spring_stiffness>0</spring_stiffness>
          </dynamics>
        </axis>
        <physics>
          <provide_feedback>1</provide_feedback>
          <ode>
            <limit>
              <cfm>0</cfm>
              <erp>0.2</erp>
            </limit>
            <provide_feedback>1</provide_feedback>
          </ode>
        </physics>
      </joint>
      <link name='wrist_3_link'>
        <pose relative_to='wrist_3_joint'>0 0 0 0 -0 0</pose>
        <inertial>
          <pose>0.000246 0.084658 4e-06 1.5708 -0 0</pose>
          <mass>0.992851</mass>
          <inertia>
            <ixx>0.00136577</ixx>
            <ixy>1.01149e-09</ixy>
            <ixz>-4.09903e-07</ixz>
            <iyy>0.00141553</iyy>
            <iyz>2.93103e-08</iyz>
            <izz>0.000654232</izz>
          </inertia>
        </inertial>
        <collision name='wrist_3_link_collision'>
          <pose>0 0 0 0 -0 0</pose>
          <geometry>
            <mesh>
              <scale>1 1 1</scale>
              <uri>/home/dylan/catkin_ws/src/universal_robot/ur_description/meshes/ur5/collision/wrist3.stl</uri>
            </mesh>
          </geometry>
          <surface>
            <contact>
              <ode/>
            </contact>
            <friction>
              <ode/>
              <torsional>
                <ode/>
              </torsional>
            </friction>
            <bounce/>
          </surface>
          <max_contacts>10</max_contacts>
        </collision>
        <collision name='wrist_3_link_fixed_joint_lump__ee_link_collision_1'>
          <pose>-0 0.0723 0 0 -0 1.5708</pose>
          <geometry>
            <box>
              <size>0.01 0.01 0.01</size>
            </box>
          </geometry>
          <surface>
            <contact>
              <ode/>
            </contact>
            <friction>
              <ode/>
              <torsional>
                <ode/>
              </torsional>
            </friction>
            <bounce/>
          </surface>
          <max_contacts>10</max_contacts>
        </collision>
        <collision name='wrist_3_link_fixed_joint_lump__robotiq_coupler_collision_2'>
          <pose>0 0.0863 0 1.57079 -1.57079 3.14159</pose>
          <geometry>
            <mesh>
              <scale>1 1 1</scale>
              <uri>/home/dylan/catkin_ws/src/robotiq/robotiq_description/meshes/robotiq_85_coupler.stl</uri>
            </mesh>
          </geometry>
          <surface>
            <contact>
              <ode/>
            </contact>
            <friction>
              <ode>
                <mu>0.9</mu>
                <mu2>0.9</mu2>
              </ode>
              <torsional>
                <ode/>
              </torsional>
            </friction>
            <bounce/>
          </surface>
          <max_contacts>10</max_contacts>
        </collision>
        <collision name='wrist_3_link_fixed_joint_lump__robotiq_85_base_link_collision_3'>
          <pose>0 0.0903 0 0 -0 1.5708</pose>
          <geometry>
            <mesh>
              <scale>1 1 1</scale>
              <uri>/home/dylan/catkin_ws/src/robotiq/robotiq_description/meshes/collision/robotiq_85_base_link.stl</uri>
            </mesh>
          </geometry>
          <max_contacts>10</max_contacts>
          <surface>
            <contact>
              <ode/>
            </contact>
            <bounce/>
            <friction>
              <torsional>
                <ode/>
              </torsional>
              <ode/>
            </friction>
          </surface>
        </collision>
        <visual name='wrist_3_link_visual'>
          <pose>0 0 0 0 -0 0</pose>
          <geometry>
            <mesh>
              <scale>1 1 1</scale>
              <uri>/home/dylan/catkin_ws/src/universal_robot/ur_description/meshes/ur5/visual/wrist3.dae</uri>
            </mesh>
          </geometry>
        </visual>
        <visual name='wrist_3_link_fixed_joint_lump__robotiq_coupler_visual_1'>
          <pose>0 0.0863 0 1.57079 -1.57079 3.14159</pose>
          <geometry>
            <mesh>
              <scale>1 1 1</scale>
              <uri>/home/dylan/catkin_ws/src/robotiq/robotiq_description/meshes/robotiq_85_coupler.stl</uri>
            </mesh>
          </geometry>
          <material>
            <script>
              <name>Gazebo/FlatBlack</name>
              <uri>file://media/materials/scripts/gazebo.material</uri>
            </script>
          </material>
        </visual>
        <visual name='wrist_3_link_fixed_joint_lump__robotiq_85_base_link_visual_2'>
          <pose>0 0.0903 0 0 -0 1.5708</pose>
          <geometry>
            <mesh>
              <scale>1 1 1</scale>
              <uri>/home/dylan/catkin_ws/src/robotiq/robotiq_description/meshes/visual/robotiq_85_base_link.dae</uri>
            </mesh>
          </geometry>
        </visual>
        <self_collide>1</self_collide>
        <enable_wind>0</enable_wind>
        <kinematic>0</kinematic>
      </link>
      <joint name='robotiq_85_left_inner_knuckle_joint' type='revolute'>
        <pose relative_to='wrist_3_link'>-0.0127 0.15172 0 3.14159 -0 1.5708</pose>
        <parent>wrist_3_link</parent>
        <child>robotiq_85_left_inner_knuckle_link</child>
        <axis>
          <xyz>0 0 1</xyz>
          <limit>
            <effort>0.1</effort>
            <velocity>100</velocity>
            <lower>-1e+16</lower>
            <upper>1e+16</upper>
          </limit>
          <dynamics>
            <spring_reference>0</spring_reference>
            <spring_stiffness>0</spring_stiffness>
          </dynamics>
        </axis>
      </joint>
      <link name='robotiq_85_left_inner_knuckle_link'>
        <pose relative_to='robotiq_85_left_inner_knuckle_joint'>0 0 0 0 -0 0</pose>
        <inertial>
          <pose>0 0 0 0 -0 0</pose>
          <mass>0.029951</mass>
          <inertia>
            <ixx>3.9e-05</ixx>
            <ixy>0</ixy>
            <ixz>0</ixz>
            <iyy>5e-06</iyy>
            <iyz>0</iyz>
            <izz>3.5e-05</izz>
          </inertia>
        </inertial>
        <collision name='robotiq_85_left_inner_knuckle_link_collision'>
          <pose>0 0 0 0 -0 0</pose>
          <geometry>
            <mesh>
              <scale>1 1 1</scale>
              <uri>/home/dylan/catkin_ws/src/robotiq/robotiq_description/meshes/collision/robotiq_85_inner_knuckle_link.stl</uri>
            </mesh>
          </geometry>
          <max_contacts>10</max_contacts>
          <surface>
            <contact>
              <ode/>
            </contact>
            <bounce/>
            <friction>
              <torsional>
                <ode/>
              </torsional>
              <ode/>
            </friction>
          </surface>
        </collision>
        <visual name='robotiq_85_left_inner_knuckle_link_visual'>
          <pose>0 0 0 0 -0 0</pose>
          <geometry>
            <mesh>
              <scale>1 1 1</scale>
              <uri>/home/dylan/catkin_ws/src/robotiq/robotiq_description/meshes/visual/robotiq_85_inner_knuckle_link.dae</uri>
            </mesh>
          </geometry>
        </visual>
        <self_collide>0</self_collide>
        <enable_wind>0</enable_wind>
        <kinematic>0</kinematic>
      </link>
      <joint name='robotiq_85_left_finger_tip_joint' type='revolute'>
        <pose relative_to='robotiq_85_left_inner_knuckle_link'>0.04304 -0.037599 0 0 -0 0</pose>
        <parent>robotiq_85_left_inner_knuckle_link</parent>
        <child>robotiq_85_left_finger_tip_link</child>
        <axis>
          <xyz>0 0 1</xyz>
          <limit>
            <effort>0.1</effort>
            <velocity>100</velocity>
            <lower>-1e+16</lower>
            <upper>1e+16</upper>
          </limit>
          <dynamics>
            <spring_reference>0</spring_reference>
            <spring_stiffness>0</spring_stiffness>
          </dynamics>
        </axis>
      </joint>
      <link name='robotiq_85_left_finger_tip_link'>
        <pose relative_to='robotiq_85_left_finger_tip_joint'>0 0 0 0 -0 0</pose>
        <inertial>
          <pose>0 0 0 0 -0 0</pose>
          <mass>0.019555</mass>
          <inertia>
            <ixx>2e-06</ixx>
            <ixy>0</ixy>
            <ixz>0</ixz>
            <iyy>5e-06</iyy>
            <iyz>0</iyz>
            <izz>6e-06</izz>
          </inertia>
        </inertial>
        <collision name='robotiq_85_left_finger_tip_link_collision'>
          <pose>0 0 0 0 -0 0</pose>
          <geometry>
            <mesh>
              <scale>1 1 1</scale>
              <uri>/home/dylan/catkin_ws/src/robotiq/robotiq_description/meshes/collision/robotiq_85_finger_tip_link.stl</uri>
            </mesh>
          </geometry>
          <surface>
            <contact>
              <ode>
                <kp>1e+06</kp>
                <kd>1</kd>
                <min_depth>0.001</min_depth>
              </ode>
            </contact>
            <friction>
              <ode>
                <mu>1</mu>
                <mu2>1</mu2>
              </ode>
              <torsional>
                <ode/>
              </torsional>
            </friction>
            <bounce/>
          </surface>
          <max_contacts>10</max_contacts>
        </collision>
        <visual name='robotiq_85_left_finger_tip_link_visual'>
          <pose>0 0 0 0 -0 0</pose>
          <geometry>
            <mesh>
              <scale>1 1 1</scale>
              <uri>/home/dylan/catkin_ws/src/robotiq/robotiq_description/meshes/visual/robotiq_85_finger_tip_link.dae</uri>
            </mesh>
          </geometry>
        </visual>
        <self_collide>0</self_collide>
        <enable_wind>0</enable_wind>
        <kinematic>0</kinematic>
      </link>
      <joint name='robotiq_85_left_knuckle_joint' type='revolute'>
        <pose relative_to='wrist_3_link'>-0.030601 0.145205 0 3.14159 -0 1.5708</pose>
        <parent>wrist_3_link</parent>
        <child>robotiq_85_left_knuckle_link</child>
        <axis>
          <xyz>0 0 1</xyz>
          <limit>
            <lower>0</lower>
            <upper>0.80285</upper>
            <effort>1000</effort>
            <velocity>0.5</velocity>
          </limit>
          <dynamics>
            <spring_reference>0</spring_reference>
            <spring_stiffness>0</spring_stiffness>
          </dynamics>
        </axis>
      </joint>
      <link name='robotiq_85_left_knuckle_link'>
        <pose relative_to='robotiq_85_left_knuckle_joint'>0 0 0 0 -0 0</pose>
        <inertial>
          <pose>-0.002436 -0.018774 0 0 -0 0</pose>
          <mass>0.0458</mass>
          <inertia>
            <ixx>2.29304e-05</ixx>
            <ixy>-4.4183e-06</ixy>
            <ixz>0</ixz>
            <iyy>2.2184e-05</iyy>
            <iyz>0</iyz>
            <izz>4.11145e-05</izz>
          </inertia>
        </inertial>
        <collision name='robotiq_85_left_knuckle_link_collision'>
          <pose>0 0 0 0 -0 0</pose>
          <geometry>
            <mesh>
              <scale>1 1 1</scale>
              <uri>/home/dylan/catkin_ws/src/robotiq/robotiq_description/meshes/collision/robotiq_85_knuckle_link.stl</uri>
            </mesh>
          </geometry>
          <max_contacts>10</max_contacts>
          <surface>
            <contact>
              <ode/>
            </contact>
            <bounce/>
            <friction>
              <torsional>
                <ode/>
              </torsional>
              <ode/>
            </friction>
          </surface>
        </collision>
        <collision name='robotiq_85_left_knuckle_link_fixed_joint_lump__robotiq_85_left_finger_link_collision_1'>
          <pose>-0.004086 -0.031486 0 0 -0 0</pose>
          <geometry>
            <mesh>
              <scale>1 1 1</scale>
              <uri>/home/dylan/catkin_ws/src/robotiq/robotiq_description/meshes/collision/robotiq_85_finger_link.stl</uri>
            </mesh>
          </geometry>
          <max_contacts>10</max_contacts>
          <surface>
            <contact>
              <ode/>
            </contact>
            <bounce/>
            <friction>
              <torsional>
                <ode/>
              </torsional>
              <ode/>
            </friction>
          </surface>
        </collision>
        <visual name='robotiq_85_left_knuckle_link_visual'>
          <pose>0 0 0 0 -0 0</pose>
          <geometry>
            <mesh>
              <scale>1 1 1</scale>
              <uri>/home/dylan/catkin_ws/src/robotiq/robotiq_description/meshes/visual/robotiq_85_knuckle_link.dae</uri>
            </mesh>
          </geometry>
        </visual>
        <visual name='robotiq_85_left_knuckle_link_fixed_joint_lump__robotiq_85_left_finger_link_visual_1'>
          <pose>-0.004086 -0.031486 0 0 -0 0</pose>
          <geometry>
            <mesh>
              <scale>1 1 1</scale>
              <uri>/home/dylan/catkin_ws/src/robotiq/robotiq_description/meshes/visual/robotiq_85_finger_link.dae</uri>
            </mesh>
          </geometry>
        </visual>
        <self_collide>0</self_collide>
        <enable_wind>0</enable_wind>
        <kinematic>0</kinematic>
      </link>
      <joint name='robotiq_85_right_inner_knuckle_joint' type='revolute'>
        <pose relative_to='wrist_3_link'>0.0127 0.15172 0 0 -0 1.5708</pose>
        <parent>wrist_3_link</parent>
        <child>robotiq_85_right_inner_knuckle_link</child>
        <axis>
          <xyz>0 0 1</xyz>
          <limit>
            <effort>0.1</effort>
            <velocity>100</velocity>
            <lower>-1e+16</lower>
            <upper>1e+16</upper>
          </limit>
          <dynamics>
            <spring_reference>0</spring_reference>
            <spring_stiffness>0</spring_stiffness>
          </dynamics>
        </axis>
      </joint>
      <link name='robotiq_85_right_inner_knuckle_link'>
        <pose relative_to='robotiq_85_right_inner_knuckle_joint'>0 0 0 0 -0 0</pose>
        <inertial>
          <pose>0 0 0 0 -0 0</pose>
          <mass>0.029951</mass>
          <inertia>
            <ixx>3.9e-05</ixx>
            <ixy>0</ixy>
            <ixz>0</ixz>
            <iyy>5e-06</iyy>
            <iyz>0</iyz>
            <izz>3.5e-05</izz>
          </inertia>
        </inertial>
        <collision name='robotiq_85_right_inner_knuckle_link_collision'>
          <pose>0 0 0 0 -0 0</pose>
          <geometry>
            <mesh>
              <scale>1 1 1</scale>
              <uri>/home/dylan/catkin_ws/src/robotiq/robotiq_description/meshes/collision/robotiq_85_inner_knuckle_link.stl</uri>
            </mesh>
          </geometry>
          <max_contacts>10</max_contacts>
          <surface>
            <contact>
              <ode/>
            </contact>
            <bounce/>
            <friction>
              <torsional>
                <ode/>
              </torsional>
              <ode/>
            </friction>
          </surface>
        </collision>
        <visual name='robotiq_85_right_inner_knuckle_link_visual'>
          <pose>0 0 0 0 -0 0</pose>
          <geometry>
            <mesh>
              <scale>1 1 1</scale>
              <uri>/home/dylan/catkin_ws/src/robotiq/robotiq_description/meshes/visual/robotiq_85_inner_knuckle_link.dae</uri>
            </mesh>
          </geometry>
        </visual>
        <self_collide>0</self_collide>
        <enable_wind>0</enable_wind>
        <kinematic>0</kinematic>
      </link>
      <joint name='robotiq_85_right_finger_tip_joint' type='revolute'>
        <pose relative_to='robotiq_85_right_inner_knuckle_link'>0.04304 -0.037599 0 0 -0 0</pose>
        <parent>robotiq_85_right_inner_knuckle_link</parent>
        <child>robotiq_85_right_finger_tip_link</child>
        <axis>
          <xyz>0 0 1</xyz>
          <limit>
            <effort>0.1</effort>
            <velocity>100</velocity>
            <lower>-1e+16</lower>
            <upper>1e+16</upper>
          </limit>
          <dynamics>
            <spring_reference>0</spring_reference>
            <spring_stiffness>0</spring_stiffness>
          </dynamics>
        </axis>
      </joint>
      <link name='robotiq_85_right_finger_tip_link'>
        <pose relative_to='robotiq_85_right_finger_tip_joint'>0 0 0 0 -0 0</pose>
        <inertial>
          <pose>0 0 0 0 -0 0</pose>
          <mass>0.019555</mass>
          <inertia>
            <ixx>2e-06</ixx>
            <ixy>0</ixy>
            <ixz>0</ixz>
            <iyy>5e-06</iyy>
            <iyz>0</iyz>
            <izz>6e-06</izz>
          </inertia>
        </inertial>
        <collision name='robotiq_85_right_finger_tip_link_collision'>
          <pose>0 0 0 0 -0 0</pose>
          <geometry>
            <mesh>
              <scale>1 1 1</scale>
              <uri>/home/dylan/catkin_ws/src/robotiq/robotiq_description/meshes/collision/robotiq_85_finger_tip_link.stl</uri>
            </mesh>
          </geometry>
          <surface>
            <contact>
              <ode>
                <kp>1e+06</kp>
                <kd>1</kd>
                <min_depth>0.001</min_depth>
              </ode>
            </contact>
            <friction>
              <ode>
                <mu>1</mu>
                <mu2>1</mu2>
              </ode>
              <torsional>
                <ode/>
              </torsional>
            </friction>
            <bounce/>
          </surface>
          <max_contacts>10</max_contacts>
        </collision>
        <visual name='robotiq_85_right_finger_tip_link_visual'>
          <pose>0 0 0 0 -0 0</pose>
          <geometry>
            <mesh>
              <scale>1 1 1</scale>
              <uri>/home/dylan/catkin_ws/src/robotiq/robotiq_description/meshes/visual/robotiq_85_finger_tip_link.dae</uri>
            </mesh>
          </geometry>
        </visual>
        <self_collide>0</self_collide>
        <enable_wind>0</enable_wind>
        <kinematic>0</kinematic>
      </link>
      <joint name='robotiq_85_right_knuckle_joint' type='revolute'>
        <pose relative_to='wrist_3_link'>0.030601 0.145205 0 0 -0 1.5708</pose>
        <parent>wrist_3_link</parent>
        <child>robotiq_85_right_knuckle_link</child>
        <axis>
          <xyz>0 0 1</xyz>
          <limit>
            <effort>1000</effort>
            <velocity>100</velocity>
            <lower>-1e+16</lower>
            <upper>1e+16</upper>
          </limit>
          <dynamics>
            <spring_reference>0</spring_reference>
            <spring_stiffness>0</spring_stiffness>
          </dynamics>
        </axis>
      </joint>
      <link name='robotiq_85_right_knuckle_link'>
        <pose relative_to='robotiq_85_right_knuckle_joint'>0 0 0 0 -0 0</pose>
        <inertial>
          <pose>-0.002436 -0.018774 0 0 -0 0</pose>
          <mass>0.0458</mass>
          <inertia>
            <ixx>2.29304e-05</ixx>
            <ixy>-4.4183e-06</ixy>
            <ixz>0</ixz>
            <iyy>2.2184e-05</iyy>
            <iyz>0</iyz>
            <izz>4.11145e-05</izz>
          </inertia>
        </inertial>
        <collision name='robotiq_85_right_knuckle_link_collision'>
          <pose>0 0 0 0 -0 0</pose>
          <geometry>
            <mesh>
              <scale>1 1 1</scale>
              <uri>/home/dylan/catkin_ws/src/robotiq/robotiq_description/meshes/collision/robotiq_85_knuckle_link.stl</uri>
            </mesh>
          </geometry>
          <max_contacts>10</max_contacts>
          <surface>
            <contact>
              <ode/>
            </contact>
            <bounce/>
            <friction>
              <torsional>
                <ode/>
              </torsional>
              <ode/>
            </friction>
          </surface>
        </collision>
        <collision name='robotiq_85_right_knuckle_link_fixed_joint_lump__robotiq_85_right_finger_link_collision_1'>
          <pose>-0.004086 -0.031486 0 0 -0 0</pose>
          <geometry>
            <mesh>
              <scale>1 1 1</scale>
              <uri>/home/dylan/catkin_ws/src/robotiq/robotiq_description/meshes/collision/robotiq_85_finger_link.stl</uri>
            </mesh>
          </geometry>
          <max_contacts>10</max_contacts>
          <surface>
            <contact>
              <ode/>
            </contact>
            <bounce/>
            <friction>
              <torsional>
                <ode/>
              </torsional>
              <ode/>
            </friction>
          </surface>
        </collision>
        <visual name='robotiq_85_right_knuckle_link_visual'>
          <pose>0 0 0 0 -0 0</pose>
          <geometry>
            <mesh>
              <scale>1 1 1</scale>
              <uri>/home/dylan/catkin_ws/src/robotiq/robotiq_description/meshes/visual/robotiq_85_knuckle_link.dae</uri>
            </mesh>
          </geometry>
        </visual>
        <visual name='robotiq_85_right_knuckle_link_fixed_joint_lump__robotiq_85_right_finger_link_visual_1'>
          <pose>-0.004086 -0.031486 0 0 -0 0</pose>
          <geometry>
            <mesh>
              <scale>1 1 1</scale>
              <uri>/home/dylan/catkin_ws/src/robotiq/robotiq_description/meshes/visual/robotiq_85_finger_link.dae</uri>
            </mesh>
          </geometry>
        </visual>
        <self_collide>0</self_collide>
        <enable_wind>0</enable_wind>
        <kinematic>0</kinematic>
      </link>
      <plugin name='ros_control' filename='libgazebo_ros_control.so'>
        <robotNamespace>/</robotNamespace>
      </plugin>
      <plugin name='mimic_robotiq_85_1' filename='libgazebo_mimic_joint_plugin.so'>
        <joint>robotiq_85_left_knuckle_joint</joint>
        <mimicJoint>robotiq_85_right_knuckle_joint</mimicJoint>
        <robotNamespace>/</robotNamespace>
      </plugin>
      <plugin name='mimic_robotiq_85_2' filename='libgazebo_mimic_joint_plugin.so'>
        <joint>robotiq_85_left_knuckle_joint</joint>
        <mimicJoint>robotiq_85_left_inner_knuckle_joint</mimicJoint>
        <robotNamespace>/</robotNamespace>
      </plugin>
      <plugin name='mimic_robotiq_85_3' filename='libgazebo_mimic_joint_plugin.so'>
        <joint>robotiq_85_left_knuckle_joint</joint>
        <mimicJoint>robotiq_85_right_inner_knuckle_joint</mimicJoint>
        <robotNamespace>/</robotNamespace>
      </plugin>
      <plugin name='mimic_robotiq_85_4' filename='libgazebo_mimic_joint_plugin.so'>
        <joint>robotiq_85_left_knuckle_joint</joint>
        <mimicJoint>robotiq_85_left_finger_tip_joint</mimicJoint>
        <multiplier>-1.0</multiplier>
        <offset>0.0</offset>
        <robotNamespace>/</robotNamespace>
      </plugin>
      <plugin name='mimic_robotiq_85_5' filename='libgazebo_mimic_joint_plugin.so'>
        <joint>robotiq_85_left_knuckle_joint</joint>
        <mimicJoint>robotiq_85_right_finger_tip_joint</mimicJoint>
        <multiplier>-1.0</multiplier>
        <offset>0.0</offset>
        <robotNamespace>/</robotNamespace>
      </plugin>
      <plugin name='ft_sensor_plugin' filename='libgazebo_ros_ft_sensor.so'>
        <updateRate>250.0</updateRate>
        <topicName>ft_sensor/raw</topicName>
        <gaussianNoise>0.0</gaussianNoise>
        <jointName>wrist_3_joint</jointName>
        <robotNamespace>/</robotNamespace>
      </plugin>
      <static>0</static>
      <gripper name='gazebo_gripper'>
        <grasp_check>
          <attach_steps>2</attach_steps>
          <detach_steps>2</detach_steps>
          <min_contact_count>3</min_contact_count>
        </grasp_check>
        <gripper_link>robotiq_85_left_finger_tip_link</gripper_link>
        <gripper_link>robotiq_85_right_finger_tip_link</gripper_link>
        <palm_link>wrist_3_link</palm_link>
      </gripper>
      <pose>0 0 1.21 0 -0 0</pose>
    </model>
  </world>
</sdf>
