<sdf version='1.7'>
  <world name='default'>
    <light name='sun' type='directional'>
      <cast_shadows>1</cast_shadows>
      <pose>0 0 10 0 -0 0</pose>
      <diffuse>0.8 0.8 0.8 1</diffuse>
      <specular>0.2 0.2 0.2 1</specular>
      <attenuation>
        <range>1000</range>
        <constant>0.9</constant>
        <linear>0.01</linear>
        <quadratic>0.001</quadratic>
      </attenuation>
      <direction>-0.5 0.1 -0.9</direction>
      <spot>
        <inner_angle>0</inner_angle>
        <outer_angle>0</outer_angle>
        <falloff>0</falloff>
      </spot>
    </light>
    <model name='ground_plane'>
      <static>1</static>
      <link name='link'>
        <collision name='collision'>
          <geometry>
            <plane>
              <normal>0 0 1</normal>
              <size>100 100</size>
            </plane>
          </geometry>
          <surface>
            <contact>
              <collide_bitmask>65535</collide_bitmask>
              <ode/>
            </contact>
            <friction>
              <ode>
                <mu>100</mu>
                <mu2>50</mu2>
              </ode>
              <torsional>
                <ode/>
              </torsional>
            </friction>
            <bounce/>
          </surface>
          <max_contacts>10</max_contacts>
        </collision>
        <visual name='visual'>
          <cast_shadows>0</cast_shadows>
          <geometry>
            <plane>
              <normal>0 0 1</normal>
              <size>100 100</size>
            </plane>
          </geometry>
          <material>
            <script>
              <uri>file://media/materials/scripts/gazebo.material</uri>
              <name>Gazebo/Grey</name>
            </script>
          </material>
        </visual>
        <self_collide>0</self_collide>
        <enable_wind>0</enable_wind>
        <kinematic>0</kinematic>
      </link>
    </model>
    <gravity>0 0 -9.8</gravity>
    <magnetic_field>6e-06 2.3e-05 -4.2e-05</magnetic_field>
    <atmosphere type='adiabatic'/>
    <physics name='default_physics' default='0' type='ode'>
      <max_step_size>0.001</max_step_size>
      <real_time_factor>1</real_time_factor>
      <real_time_update_rate>1000</real_time_update_rate>
    </physics>
    <scene>
      <ambient>0.4 0.4 0.4 1</ambient>
      <background>0.7 0.7 0.7 1</background>
      <shadows>1</shadows>
    </scene>
    <audio>
      <device>default</device>
    </audio>
    <wind/>
    <spherical_coordinates>
      <surface_model>EARTH_WGS84</surface_model>
      <latitude_deg>0</latitude_deg>
      <longitude_deg>0</longitude_deg>
      <elevation>0</elevation>
      <heading_deg>0</heading_deg>
    </spherical_coordinates>
    <model name='bowl'>
      <link name='link'>
        <inertial>
          <pose>0 0 0.0175 0 -0 0</pose>
          <mass>0.1</mass>
          <inertia>
            <ixx>0.000250308</ixx>
            <ixy>0</ixy>
            <ixz>0</ixz>
            <iyy>0.000250308</iyy>
            <iyz>0</iyz>
            <izz>0.0004802</izz>
          </inertia>
        </inertial>
        <collision name='collision'>
          <pose>0 0 0.0175 0 -0 0</pose>
          <geometry>
            <cylinder>
              <radius>0.098</radius>
              <length>0.035</length>
            </cylinder>
          </geometry>
          <max_contacts>10</max_contacts>
          <surface>
            <contact>
              <ode/>
            </contact>
            <bounce/>
            <friction>
              <torsional>
                <ode/>
              </torsional>
              <ode/>
            </friction>
          </surface>
        </collision>
        <visual name='visual'>
          <geometry>
            <mesh>
              <uri>model://bowl/meshes/bowl.dae</uri>
            </mesh>
          </geometry>
        </visual>
        <self_collide>0</self_collide>
        <enable_wind>0</enable_wind>
        <kinematic>0</kinematic>
      </link>
      <pose>-0.41352 2.10485 0 0 -0 0</pose>
    </model>
    <state world_name='default'>
      <sim_time>2785 15000000</sim_time>
      <real_time>69 394708951</real_time>
      <wall_time>1695216209 556475589</wall_time>
      <iterations>64219</iterations>
      <model name='bowl'>
        <pose>-0.3 0.5 1.015 0 -0 0.275846</pose>
        <scale>1 1 1</scale>
        <link name='link'>
          <pose>-0.3 0.5 1.015 0 -0 0.275846</pose>
          <velocity>0 0 0 0 -0 0</velocity>
          <acceleration>-0 0 19.6 -3e-06 -1e-06 -0</acceleration>
          <wrench>-0 0 1.96 0 -0 0</wrench>
        </link>
      </model>
      <model name='ground_plane'>
        <pose>0 0 0 0 -0 0</pose>
        <scale>1 1 1</scale>
        <link name='link'>
          <pose>0 0 0 0 -0 0</pose>
          <velocity>0 0 0 0 -0 0</velocity>
          <acceleration>0 0 0 0 -0 0</acceleration>
          <wrench>0 0 0 0 -0 0</wrench>
        </link>
      </model>
      <model name='mug'>
        <pose>0.313997 0.491901 1.01536 -0.000852 -0.00305 0.092833</pose>
        <scale>1 1 1</scale>
        <link name='link'>
          <pose>0.313997 0.491901 1.01536 -0.000852 -0.00305 0.092833</pose>
          <velocity>-1e-06 1.3e-05 -0.002152 -0.036792 -0.002725 0</velocity>
          <acceleration>0 0 -9.8 5e-06 -7.1e-05 -8e-06</acceleration>
          <wrench>0 0 -0.001354 0 -0 0</wrench>
        </link>
      </model>
      <model name='nist_elevated_floor_120'>
        <pose>0.005735 -0.482404 0 0 -0 0</pose>
        <scale>1 1 1</scale>
        <link name='nist_elevated_floor_120'>
          <pose>0.005735 -0.482404 0 0 -0 0</pose>
          <velocity>0 0 0 0 -0 0</velocity>
          <acceleration>0 0 0 0 -0 0</acceleration>
          <wrench>0 0 0 0 -0 0</wrench>
        </link>
      </model>
      <model name='robot'>
        <pose>-0 0 1.21 2.2e-05 -0 0</pose>
        <scale>1 1 1</scale>
        <link name='base_link'>
          <pose>-0 0 1.21 2.2e-05 -0 0</pose>
          <velocity>4e-06 -4e-06 -6e-06 -0.005418 0.000352 0</velocity>
          <acceleration>0.002807 -0.008461 -0.011419 2.16312 0.322083 2e-05</acceleration>
          <wrench>0.011226 -0.033845 -0.045676 0 -0 0</wrench>
        </link>
        <link name='forearm_link'>
          <pose>0.423113 0.014586 1.25856 -3.14079 1.45166 3.13871</pose>
          <velocity>-0.000863 -0.000291 -0.008342 0.023291 0.000849 -0.005442</velocity>
          <acceleration>-1.42874 -1.7858 -16.5655 1.58558 -1.35963 -1.99143</acceleration>
          <wrench>-3.25039 -4.06269 -37.6865 0 -0 0</wrench>
        </link>
        <link name='robotiq_85_left_finger_tip_link'>
          <pose>0.85703 0.302983 1.09271 0.567232 0.00113 1.52958</pose>
          <velocity>-0.003796 0.004326 0.00348 0.055547 0.019784 0.017269</velocity>
          <acceleration>-3.7963 4.32646 3.47966 2.05176 0.584472 -2.23589</acceleration>
          <wrench>-0.074237 0.084604 0.068045 0 -0 0</wrench>
        </link>
        <link name='robotiq_85_left_inner_knuckle_link'>
          <pose>0.827568 0.257286 1.11031 0.564616 -0.05764 1.62206</pose>
          <velocity>-0.002076 0.002921 0.001882 0.055858 0.019856 0.017073</velocity>
          <acceleration>-2.07593 2.92078 1.88227 2.4521 -0.118291 0.152103</acceleration>
          <wrench>-0.062176 0.08748 0.056376 0 -0 0</wrench>
        </link>
        <link name='robotiq_85_left_knuckle_link'>
          <pose>0.842383 0.250143 1.1007 0.564602 -0.057676 1.62196</pose>
          <velocity>-0.002088 0.003702 0.001208 0.001733 0.024768 -0.026736</velocity>
          <acceleration>-5.24512 4.98798 -1.29503 2.64872 -1.02238 -1.76033</acceleration>
          <wrench>-0.240227 0.22845 -0.059312 0 -0 0</wrench>
        </link>
        <link name='robotiq_85_right_finger_tip_link'>
          <pose>0.78057 0.306191 1.14146 -2.57438 0.001125 1.52958</pose>
          <velocity>-0.002822 0.000458 0.005224 0.054455 0.025243 0.018139</velocity>
          <acceleration>-2.82219 0.458328 5.22417 -1.23816 1.51599 1.86645</acceleration>
          <wrench>-0.055188 0.008963 0.102159 0 -0 0</wrench>
        </link>
        <link name='robotiq_85_right_inner_knuckle_link'>
          <pose>0.806164 0.258184 1.12396 -2.5772 0.059886 1.43709</pose>
          <velocity>-0.001802 0.001765 0.002317 0.054758 0.025184 0.017946</velocity>
          <acceleration>-1.80222 1.76513 2.3169 0.579145 -1.34148 0.61843</acceleration>
          <wrench>-0.053978 0.052868 0.069394 0 -0 0</wrench>
        </link>
        <link name='robotiq_85_right_knuckle_link'>
          <pose>0.790811 0.252307 1.13359 -2.57718 0.059819 1.43705</pose>
          <velocity>-0.001423 0.000956 0.002367 0.036479 0.021124 0.029388</velocity>
          <acceleration>-1.21744 0.115676 2.71507 1.23178 0.962651 3.13014</acceleration>
          <wrench>-0.055759 0.005298 0.12435 0 -0 0</wrench>
        </link>
        <link name='shoulder_link'>
          <pose>0 -2e-06 1.29916 -4e-05 1e-06 -0.003681</pose>
          <velocity>-6.4e-05 0.000597 8e-06 0.009787 -0.001106 -0.004541</velocity>
          <acceleration>-0.040267 1.15851 0.014178 -0.11094 -0.936753 -2.46004</acceleration>
          <wrench>-0.14899 4.28648 0.052459 0 -0 0</wrench>
        </link>
        <link name='upper_arm_link'>
          <pose>0.0005 0.135847 1.29915 -3.14087 1.47513 3.13863</pose>
          <velocity>0.00043 0.000613 0.001519 0.017061 0.017523 -0.004291</velocity>
          <acceleration>0.311856 -0.334261 -5.23351 0.066595 0.893824 2.95409</acceleration>
          <wrench>2.61741 -2.80546 -43.9249 0 -0 0</wrench>
        </link>
        <link name='wrist_1_link'>
          <pose>0.81258 0.013151 1.21193 -3.14149 -0.024437 3.13792</pose>
          <velocity>-0.000803 -0.001488 -0.00689 0.025714 -0.028736 -0.006332</velocity>
          <acceleration>-0.417924 -3.1798 -10.965 2.48042 -1.20421 -2.97407</acceleration>
          <wrench>-0.509449 -3.87618 -13.3664 0 -0 0</wrench>
        </link>
        <link name='wrist_2_link'>
          <pose>0.812921 0.106147 1.21192 -3.14055 -0.024415 3.10031</pose>
          <velocity>-0.000179 -0.000791 -0.004341 0.031327 -0.028714 0.02986</velocity>
          <acceleration>4.58011 3.65308 -10.8122 -0.363097 -1.23359 -1.52554</acceleration>
          <wrench>5.58315 4.4531 -13.18 0 -0 0</wrench>
        </link>
        <link name='wrist_3_link'>
          <pose>0.810608 0.106144 1.1173 -3.14034 -0.567229 3.09967</pose>
          <velocity>0.002561 0.002127 -0.003521 0.035972 0.021946 0.029735</velocity>
          <acceleration>-0.254623 3.88003 -3.47019 -2.46276 -1.53819 0.705864</acceleration>
          <wrench>-0.252803 3.85229 -3.44538 0 -0 0</wrench>
        </link>
      </model>
      <model name='table'>
        <pose>1.8e-05 0.659275 0 0 -0 0</pose>
        <scale>1 1 1</scale>
        <link name='link'>
          <pose>1.8e-05 0.659275 0 0 -0 0</pose>
          <velocity>0 0 0 0 -0 0</velocity>
          <acceleration>0 0 0 0 -0 0</acceleration>
          <wrench>0 0 0 0 -0 0</wrench>
        </link>
      </model>
      <light name='sun'>
        <pose>0 0 10 0 -0 0</pose>
      </light>
    </state>
    <gui fullscreen='0'>
      <camera name='user_camera'>
        <pose>0.210587 0.640387 2.95411 0 1.44974 -1.49525</pose>
        <view_controller>orbit</view_controller>
        <projection_type>perspective</projection_type>
      </camera>
    </gui>
    <model name='nist_elevated_floor_120'>
      <static>1</static>
      <link name='nist_elevated_floor_120'>
        <pose>0 0 0 0 -0 0</pose>
        <collision name='collision'>
          <geometry>
            <mesh>
              <uri>model://nist_elevated_floor_120/meshes/nist_elevated_floor_120.dae</uri>
              <scale>1 1 1</scale>
            </mesh>
          </geometry>
          <max_contacts>10</max_contacts>
          <surface>
            <contact>
              <ode/>
            </contact>
            <bounce/>
            <friction>
              <torsional>
                <ode/>
              </torsional>
              <ode/>
            </friction>
          </surface>
        </collision>
        <visual name='visual'>
          <geometry>
            <mesh>
              <uri>model://nist_elevated_floor_120/meshes/nist_elevated_floor_120.dae</uri>
              <scale>1 1 1</scale>
            </mesh>
          </geometry>
        </visual>
        <self_collide>0</self_collide>
        <enable_wind>0</enable_wind>
        <kinematic>0</kinematic>
      </link>
      <pose>0.297914 -0.687027 0 0 -0 0</pose>
    </model>
    <model name='table'>
      <static>1</static>
      <link name='link'>
        <collision name='surface'>
          <pose>0 0 1 0 -0 0</pose>
          <geometry>
            <box>
              <size>1.5 0.8 0.03</size>
            </box>
          </geometry>
          <surface>
            <friction>
              <ode>
                <mu>0.6</mu>
                <mu2>0.6</mu2>
              </ode>
              <torsional>
                <ode/>
              </torsional>
            </friction>
            <contact>
              <ode/>
            </contact>
            <bounce/>
          </surface>
          <max_contacts>10</max_contacts>
        </collision>
        <visual name='visual1'>
          <pose>0 0 1 0 -0 0</pose>
          <geometry>
            <box>
              <size>1.5 0.8 0.03</size>
            </box>
          </geometry>
          <material>
            <script>
              <uri>file://media/materials/scripts/gazebo.material</uri>
              <name>Gazebo/White</name>
            </script>
          </material>
        </visual>
        <collision name='front_left_leg'>
          <pose>0.68 0.38 0.5 0 -0 0</pose>
          <geometry>
            <cylinder>
              <radius>0.02</radius>
              <length>1</length>
            </cylinder>
          </geometry>
          <max_contacts>10</max_contacts>
          <surface>
            <contact>
              <ode/>
            </contact>
            <bounce/>
            <friction>
              <torsional>
                <ode/>
              </torsional>
              <ode/>
            </friction>
          </surface>
        </collision>
        <visual name='front_left_leg'>
          <pose>0.68 0.38 0.5 0 -0 0</pose>
          <geometry>
            <cylinder>
              <radius>0.02</radius>
              <length>1</length>
            </cylinder>
          </geometry>
          <material>
            <script>
              <uri>file://media/materials/scripts/gazebo.material</uri>
              <name>Gazebo/Grey</name>
            </script>
          </material>
        </visual>
        <collision name='front_right_leg'>
          <pose>0.68 -0.38 0.5 0 -0 0</pose>
          <geometry>
            <cylinder>
              <radius>0.02</radius>
              <length>1</length>
            </cylinder>
          </geometry>
          <max_contacts>10</max_contacts>
          <surface>
            <contact>
              <ode/>
            </contact>
            <bounce/>
            <friction>
              <torsional>
                <ode/>
              </torsional>
              <ode/>
            </friction>
          </surface>
        </collision>
        <visual name='front_right_leg'>
          <pose>0.68 -0.38 0.5 0 -0 0</pose>
          <geometry>
            <cylinder>
              <radius>0.02</radius>
              <length>1</length>
            </cylinder>
          </geometry>
          <material>
            <script>
              <uri>file://media/materials/scripts/gazebo.material</uri>
              <name>Gazebo/Grey</name>
            </script>
          </material>
        </visual>
        <collision name='back_right_leg'>
          <pose>-0.68 -0.38 0.5 0 -0 0</pose>
          <geometry>
            <cylinder>
              <radius>0.02</radius>
              <length>1</length>
            </cylinder>
          </geometry>
          <max_contacts>10</max_contacts>
          <surface>
            <contact>
              <ode/>
            </contact>
            <bounce/>
            <friction>
              <torsional>
                <ode/>
              </torsional>
              <ode/>
            </friction>
          </surface>
        </collision>
        <visual name='back_right_leg'>
          <pose>-0.68 -0.38 0.5 0 -0 0</pose>
          <geometry>
            <cylinder>
              <radius>0.02</radius>
              <length>1</length>
            </cylinder>
          </geometry>
          <material>
            <script>
              <uri>file://media/materials/scripts/gazebo.material</uri>
              <name>Gazebo/Grey</name>
            </script>
          </material>
        </visual>
        <collision name='back_left_leg'>
          <pose>-0.68 0.38 0.5 0 -0 0</pose>
          <geometry>
            <cylinder>
              <radius>0.02</radius>
              <length>1</length>
            </cylinder>
          </geometry>
          <max_contacts>10</max_contacts>
          <surface>
            <contact>
              <ode/>
            </contact>
            <bounce/>
            <friction>
              <torsional>
                <ode/>
              </torsional>
              <ode/>
            </friction>
          </surface>
        </collision>
        <visual name='back_left_leg'>
          <pose>-0.68 0.38 0.5 0 -0 0</pose>
          <geometry>
            <cylinder>
              <radius>0.02</radius>
              <length>1</length>
            </cylinder>
          </geometry>
          <material>
            <script>
              <uri>file://media/materials/scripts/gazebo.material</uri>
              <name>Gazebo/Grey</name>
            </script>
          </material>
        </visual>
        <self_collide>0</self_collide>
        <enable_wind>0</enable_wind>
        <kinematic>0</kinematic>
      </link>
      <pose>0.270759 1.80105 0 0 -0 0</pose>
    </model>
    <model name='robot'>
      <joint name='world_joint' type='fixed'>
        <pose relative_to='__model__'>0 0 0 0 -0 0</pose>
        <parent>world</parent>
        <child>base_link</child>
      </joint>
      <link name='base_link'>
        <pose relative_to='world_joint'>0 0 0 0 -0 0</pose>
        <inertial>
          <pose>0 0 0 0 -0 0</pose>
          <mass>4</mass>
          <inertia>
            <ixx>0.00443333</ixx>
            <ixy>0</ixy>
            <ixz>0</ixz>
            <iyy>0.00443333</iyy>
            <iyz>0</iyz>
            <izz>0.0072</izz>
          </inertia>
        </inertial>
        <collision name='base_link_collision'>
          <pose>0 0 0 0 -0 0</pose>
          <geometry>
            <mesh>
              <scale>1 1 1</scale>
              <uri>/home/dylan/catkin_ws/src/universal_robot/ur_description/meshes/ur5/collision/base.stl</uri>
            </mesh>
          </geometry>
          <max_contacts>10</max_contacts>
          <surface>
            <contact>
              <ode/>
            </contact>
            <bounce/>
            <friction>
              <torsional>
                <ode/>
              </torsional>
              <ode/>
            </friction>
          </surface>
        </collision>
        <visual name='base_link_visual'>
          <pose>0 0 0 0 -0 0</pose>
          <geometry>
            <mesh>
              <scale>1 1 1</scale>
              <uri>/home/dylan/catkin_ws/src/universal_robot/ur_description/meshes/ur5/visual/base.dae</uri>
            </mesh>
          </geometry>
        </visual>
        <self_collide>0</self_collide>
        <enable_wind>0</enable_wind>
        <kinematic>0</kinematic>
      </link>
      <joint name='shoulder_pan_joint' type='revolute'>
        <pose relative_to='base_link'>0 0 0.089159 0 -0 0</pose>
        <parent>base_link</parent>
        <child>shoulder_link</child>
        <axis>
          <xyz>0 0 1</xyz>
          <limit>
            <lower>-3.14159</lower>
            <upper>3.14159</upper>
            <effort>150</effort>
            <velocity>3.15</velocity>
          </limit>
          <dynamics>
            <damping>0</damping>
            <friction>0</friction>
            <spring_reference>0</spring_reference>
            <spring_stiffness>0</spring_stiffness>
          </dynamics>
        </axis>
      </joint>
      <link name='shoulder_link'>
        <pose relative_to='shoulder_pan_joint'>0 0 0 0 -0 0</pose>
        <inertial>
          <pose>0 0 0 0 -0 0</pose>
          <mass>3.7</mass>
          <inertia>
            <ixx>0.0102675</ixx>
            <ixy>0</ixy>
            <ixz>0</ixz>
            <iyy>0.0102675</iyy>
            <iyz>0</iyz>
            <izz>0.00666</izz>
          </inertia>
        </inertial>
        <collision name='shoulder_link_collision'>
          <pose>0 0 0 0 -0 0</pose>
          <geometry>
            <mesh>
              <scale>1 1 1</scale>
              <uri>/home/dylan/catkin_ws/src/universal_robot/ur_description/meshes/ur5/collision/shoulder.stl</uri>
            </mesh>
          </geometry>
          <surface>
            <contact>
              <ode/>
            </contact>
            <friction>
              <ode/>
              <torsional>
                <ode/>
              </torsional>
            </friction>
            <bounce/>
          </surface>
          <max_contacts>10</max_contacts>
        </collision>
        <visual name='shoulder_link_visual'>
          <pose>0 0 0 0 -0 0</pose>
          <geometry>
            <mesh>
              <scale>1 1 1</scale>
              <uri>/home/dylan/catkin_ws/src/universal_robot/ur_description/meshes/ur5/visual/shoulder.dae</uri>
            </mesh>
          </geometry>
        </visual>
        <self_collide>1</self_collide>
        <enable_wind>0</enable_wind>
        <kinematic>0</kinematic>
      </link>
      <joint name='shoulder_lift_joint' type='revolute'>
        <pose relative_to='shoulder_link'>0 0.13585 0 3.14159 1.57079 3.14159</pose>
        <parent>shoulder_link</parent>
        <child>upper_arm_link</child>
        <axis>
          <xyz>0 1 0</xyz>
          <limit>
            <lower>-3.14159</lower>
            <upper>3.14159</upper>
            <effort>150</effort>
            <velocity>3.15</velocity>
          </limit>
          <dynamics>
            <damping>0</damping>
            <friction>0</friction>
            <spring_reference>0</spring_reference>
            <spring_stiffness>0</spring_stiffness>
          </dynamics>
        </axis>
      </joint>
      <link name='upper_arm_link'>
        <pose relative_to='shoulder_lift_joint'>0 0 0 0 -0 0</pose>
        <inertial>
          <pose>0 0 0.28 0 -0 0</pose>
          <mass>8.393</mass>
          <inertia>
            <ixx>0.226891</ixx>
            <ixy>0</ixy>
            <ixz>0</ixz>
            <iyy>0.226891</iyy>
            <iyz>0</iyz>
            <izz>0.0151074</izz>
          </inertia>
        </inertial>
        <collision name='upper_arm_link_collision'>
          <pose>0 0 0 0 -0 0</pose>
          <geometry>
            <mesh>
              <scale>1 1 1</scale>
              <uri>/home/dylan/catkin_ws/src/universal_robot/ur_description/meshes/ur5/collision/upperarm.stl</uri>
            </mesh>
          </geometry>
          <surface>
            <contact>
              <ode/>
            </contact>
            <friction>
              <ode/>
              <torsional>
                <ode/>
              </torsional>
            </friction>
            <bounce/>
          </surface>
          <max_contacts>10</max_contacts>
        </collision>
        <visual name='upper_arm_link_visual'>
          <pose>0 0 0 0 -0 0</pose>
          <geometry>
            <mesh>
              <scale>1 1 1</scale>
              <uri>/home/dylan/catkin_ws/src/universal_robot/ur_description/meshes/ur5/visual/upperarm.dae</uri>
            </mesh>
          </geometry>
        </visual>
        <self_collide>1</self_collide>
        <enable_wind>0</enable_wind>
        <kinematic>0</kinematic>
      </link>
      <joint name='elbow_joint' type='revolute'>
        <pose relative_to='upper_arm_link'>0 -0.1197 0.425 0 -0 0</pose>
        <parent>upper_arm_link</parent>
        <child>forearm_link</child>
        <axis>
          <xyz>0 1 0</xyz>
          <limit>
            <lower>-3.14159</lower>
            <upper>3.14159</upper>
            <effort>150</effort>
            <velocity>3.15</velocity>
          </limit>
          <dynamics>
            <damping>0</damping>
            <friction>0</friction>
            <spring_reference>0</spring_reference>
            <spring_stiffness>0</spring_stiffness>
          </dynamics>
        </axis>
      </joint>
      <link name='forearm_link'>
        <pose relative_to='elbow_joint'>0 0 0 0 -0 0</pose>
        <inertial>
          <pose>0 0 0.196125 0 -0 0</pose>
          <mass>2.275</mass>
          <inertia>
            <ixx>0.0312168</ixx>
            <ixy>0</ixy>
            <ixz>0</ixz>
            <iyy>0.0312168</iyy>
            <iyz>0</iyz>
            <izz>0.004095</izz>
          </inertia>
        </inertial>
        <collision name='forearm_link_collision'>
          <pose>0 0 0 0 -0 0</pose>
          <geometry>
            <mesh>
              <scale>1 1 1</scale>
              <uri>/home/dylan/catkin_ws/src/universal_robot/ur_description/meshes/ur5/collision/forearm.stl</uri>
            </mesh>
          </geometry>
          <surface>
            <contact>
              <ode/>
            </contact>
            <friction>
              <ode/>
              <torsional>
                <ode/>
              </torsional>
            </friction>
            <bounce/>
          </surface>
          <max_contacts>10</max_contacts>
        </collision>
        <visual name='forearm_link_visual'>
          <pose>0 0 0 0 -0 0</pose>
          <geometry>
            <mesh>
              <scale>1 1 1</scale>
              <uri>/home/dylan/catkin_ws/src/universal_robot/ur_description/meshes/ur5/visual/forearm.dae</uri>
            </mesh>
          </geometry>
        </visual>
        <self_collide>1</self_collide>
        <enable_wind>0</enable_wind>
        <kinematic>0</kinematic>
      </link>
      <joint name='wrist_1_joint' type='revolute'>
        <pose relative_to='forearm_link'>0 0 0.39225 3.14159 1.57079 3.14159</pose>
        <parent>forearm_link</parent>
        <child>wrist_1_link</child>
        <axis>
          <xyz>0 1 0</xyz>
          <limit>
            <lower>-3.14159</lower>
            <upper>3.14159</upper>
            <effort>28</effort>
            <velocity>3.2</velocity>
          </limit>
          <dynamics>
            <damping>0</damping>
            <friction>0</friction>
            <spring_reference>0</spring_reference>
            <spring_stiffness>0</spring_stiffness>
          </dynamics>
        </axis>
      </joint>
      <link name='wrist_1_link'>
        <pose relative_to='wrist_1_joint'>0 0 0 0 -0 0</pose>
        <inertial>
          <pose>0 0.093 0 0 -0 0</pose>
          <mass>1.219</mass>
          <inertia>
            <ixx>0.0025599</ixx>
            <ixy>0</ixy>
            <ixz>0</ixz>
            <iyy>0.0025599</iyy>
            <iyz>0</iyz>
            <izz>0.0021942</izz>
          </inertia>
        </inertial>
        <collision name='wrist_1_link_collision'>
          <pose>0 0 0 0 -0 0</pose>
          <geometry>
            <mesh>
              <scale>1 1 1</scale>
              <uri>/home/dylan/catkin_ws/src/universal_robot/ur_description/meshes/ur5/collision/wrist1.stl</uri>
            </mesh>
          </geometry>
          <surface>
            <contact>
              <ode/>
            </contact>
            <friction>
              <ode/>
              <torsional>
                <ode/>
              </torsional>
            </friction>
            <bounce/>
          </surface>
          <max_contacts>10</max_contacts>
        </collision>
        <visual name='wrist_1_link_visual'>
          <pose>0 0 0 0 -0 0</pose>
          <geometry>
            <mesh>
              <scale>1 1 1</scale>
              <uri>/home/dylan/catkin_ws/src/universal_robot/ur_description/meshes/ur5/visual/wrist1.dae</uri>
            </mesh>
          </geometry>
        </visual>
        <self_collide>1</self_collide>
        <enable_wind>0</enable_wind>
        <kinematic>0</kinematic>
      </link>
      <joint name='wrist_2_joint' type='revolute'>
        <pose relative_to='wrist_1_link'>0 0.093 0 0 -0 0</pose>
        <parent>wrist_1_link</parent>
        <child>wrist_2_link</child>
        <axis>
          <xyz>0 0 1</xyz>
          <limit>
            <lower>-3.14159</lower>
            <upper>3.14159</upper>
            <effort>28</effort>
            <velocity>3.2</velocity>
          </limit>
          <dynamics>
            <damping>0</damping>
            <friction>0</friction>
            <spring_reference>0</spring_reference>
            <spring_stiffness>0</spring_stiffness>
          </dynamics>
        </axis>
      </joint>
      <link name='wrist_2_link'>
        <pose relative_to='wrist_2_joint'>0 0 0 0 -0 0</pose>
        <inertial>
          <pose>0 0 0.09465 0 -0 0</pose>
          <mass>1.219</mass>
          <inertia>
            <ixx>0.0025599</ixx>
            <ixy>0</ixy>
            <ixz>0</ixz>
            <iyy>0.0025599</iyy>
            <iyz>0</iyz>
            <izz>0.0021942</izz>
          </inertia>
        </inertial>
        <collision name='wrist_2_link_collision'>
          <pose>0 0 0 0 -0 0</pose>
          <geometry>
            <mesh>
              <scale>1 1 1</scale>
              <uri>/home/dylan/catkin_ws/src/universal_robot/ur_description/meshes/ur5/collision/wrist2.stl</uri>
            </mesh>
          </geometry>
          <surface>
            <contact>
              <ode/>
            </contact>
            <friction>
              <ode/>
              <torsional>
                <ode/>
              </torsional>
            </friction>
            <bounce/>
          </surface>
          <max_contacts>10</max_contacts>
        </collision>
        <visual name='wrist_2_link_visual'>
          <pose>0 0 0 0 -0 0</pose>
          <geometry>
            <mesh>
              <scale>1 1 1</scale>
              <uri>/home/dylan/catkin_ws/src/universal_robot/ur_description/meshes/ur5/visual/wrist2.dae</uri>
            </mesh>
          </geometry>
        </visual>
        <self_collide>1</self_collide>
        <enable_wind>0</enable_wind>
        <kinematic>0</kinematic>
      </link>
      <joint name='wrist_3_joint' type='revolute'>
        <pose relative_to='wrist_2_link'>0 0 0.09465 0 -0 0</pose>
        <parent>wrist_2_link</parent>
        <child>wrist_3_link</child>
        <axis>
          <xyz>0 1 0</xyz>
          <limit>
            <lower>-3.14159</lower>
            <upper>3.14159</upper>
            <effort>28</effort>
            <velocity>3.2</velocity>
          </limit>
          <dynamics>
            <damping>0</damping>
            <friction>0</friction>
            <spring_reference>0</spring_reference>
            <spring_stiffness>0</spring_stiffness>
          </dynamics>
        </axis>
        <physics>
          <provide_feedback>1</provide_feedback>
          <ode>
            <limit>
              <cfm>0</cfm>
              <erp>0.2</erp>
            </limit>
            <provide_feedback>1</provide_feedback>
          </ode>
        </physics>
      </joint>
      <link name='wrist_3_link'>
        <pose relative_to='wrist_3_joint'>0 0 0 0 -0 0</pose>
        <inertial>
          <pose>0.000246 0.084658 4e-06 1.5708 -0 0</pose>
          <mass>0.992851</mass>
          <inertia>
            <ixx>0.00136577</ixx>
            <ixy>1.01149e-09</ixy>
            <ixz>-4.09903e-07</ixz>
            <iyy>0.00141553</iyy>
            <iyz>2.93103e-08</iyz>
            <izz>0.000654232</izz>
          </inertia>
        </inertial>
        <collision name='wrist_3_link_collision'>
          <pose>0 0 0 0 -0 0</pose>
          <geometry>
            <mesh>
              <scale>1 1 1</scale>
              <uri>/home/dylan/catkin_ws/src/universal_robot/ur_description/meshes/ur5/collision/wrist3.stl</uri>
            </mesh>
          </geometry>
          <surface>
            <contact>
              <ode/>
            </contact>
            <friction>
              <ode/>
              <torsional>
                <ode/>
              </torsional>
            </friction>
            <bounce/>
          </surface>
          <max_contacts>10</max_contacts>
        </collision>
        <collision name='wrist_3_link_fixed_joint_lump__ee_link_collision_1'>
          <pose>-0 0.0723 0 0 -0 1.5708</pose>
          <geometry>
            <box>
              <size>0.01 0.01 0.01</size>
            </box>
          </geometry>
          <surface>
            <contact>
              <ode/>
            </contact>
            <friction>
              <ode/>
              <torsional>
                <ode/>
              </torsional>
            </friction>
            <bounce/>
          </surface>
          <max_contacts>10</max_contacts>
        </collision>
        <collision name='wrist_3_link_fixed_joint_lump__robotiq_coupler_collision_2'>
          <pose>0 0.0863 0 1.57079 -1.57079 3.14159</pose>
          <geometry>
            <mesh>
              <scale>1 1 1</scale>
              <uri>/home/dylan/catkin_ws/src/robotiq/robotiq_description/meshes/robotiq_85_coupler.stl</uri>
            </mesh>
          </geometry>
          <surface>
            <contact>
              <ode/>
            </contact>
            <friction>
              <ode>
                <mu>0.9</mu>
                <mu2>0.9</mu2>
              </ode>
              <torsional>
                <ode/>
              </torsional>
            </friction>
            <bounce/>
          </surface>
          <max_contacts>10</max_contacts>
        </collision>
        <collision name='wrist_3_link_fixed_joint_lump__robotiq_85_base_link_collision_3'>
          <pose>0 0.0903 0 0 -0 1.5708</pose>
          <geometry>
            <mesh>
              <scale>1 1 1</scale>
              <uri>/home/dylan/catkin_ws/src/robotiq/robotiq_description/meshes/collision/robotiq_85_base_link.stl</uri>
            </mesh>
          </geometry>
          <max_contacts>10</max_contacts>
          <surface>
            <contact>
              <ode/>
            </contact>
            <bounce/>
            <friction>
              <torsional>
                <ode/>
              </torsional>
              <ode/>
            </friction>
          </surface>
        </collision>
        <visual name='wrist_3_link_visual'>
          <pose>0 0 0 0 -0 0</pose>
          <geometry>
            <mesh>
              <scale>1 1 1</scale>
              <uri>/home/dylan/catkin_ws/src/universal_robot/ur_description/meshes/ur5/visual/wrist3.dae</uri>
            </mesh>
          </geometry>
        </visual>
        <visual name='wrist_3_link_fixed_joint_lump__robotiq_coupler_visual_1'>
          <pose>0 0.0863 0 1.57079 -1.57079 3.14159</pose>
          <geometry>
            <mesh>
              <scale>1 1 1</scale>
              <uri>/home/dylan/catkin_ws/src/robotiq/robotiq_description/meshes/robotiq_85_coupler.stl</uri>
            </mesh>
          </geometry>
          <material>
            <script>
              <name>Gazebo/FlatBlack</name>
              <uri>file://media/materials/scripts/gazebo.material</uri>
            </script>
          </material>
        </visual>
        <visual name='wrist_3_link_fixed_joint_lump__robotiq_85_base_link_visual_2'>
          <pose>0 0.0903 0 0 -0 1.5708</pose>
          <geometry>
            <mesh>
              <scale>1 1 1</scale>
              <uri>/home/dylan/catkin_ws/src/robotiq/robotiq_description/meshes/visual/robotiq_85_base_link.dae</uri>
            </mesh>
          </geometry>
        </visual>
        <self_collide>1</self_collide>
        <enable_wind>0</enable_wind>
        <kinematic>0</kinematic>
      </link>
      <joint name='robotiq_85_left_inner_knuckle_joint' type='revolute'>
        <pose relative_to='wrist_3_link'>-0.0127 0.15172 0 3.14159 -0 1.5708</pose>
        <parent>wrist_3_link</parent>
        <child>robotiq_85_left_inner_knuckle_link</child>
        <axis>
          <xyz>0 0 1</xyz>
          <limit>
            <effort>0.1</effort>
            <velocity>100</velocity>
            <lower>-1e+16</lower>
            <upper>1e+16</upper>
          </limit>
          <dynamics>
            <spring_reference>0</spring_reference>
            <spring_stiffness>0</spring_stiffness>
          </dynamics>
        </axis>
      </joint>
      <link name='robotiq_85_left_inner_knuckle_link'>
        <pose relative_to='robotiq_85_left_inner_knuckle_joint'>0 0 0 0 -0 0</pose>
        <inertial>
          <pose>0 0 0 0 -0 0</pose>
          <mass>0.029951</mass>
          <inertia>
            <ixx>3.9e-05</ixx>
            <ixy>0</ixy>
            <ixz>0</ixz>
            <iyy>5e-06</iyy>
            <iyz>0</iyz>
            <izz>3.5e-05</izz>
          </inertia>
        </inertial>
        <collision name='robotiq_85_left_inner_knuckle_link_collision'>
          <pose>0 0 0 0 -0 0</pose>
          <geometry>
            <mesh>
              <scale>1 1 1</scale>
              <uri>/home/dylan/catkin_ws/src/robotiq/robotiq_description/meshes/collision/robotiq_85_inner_knuckle_link.stl</uri>
            </mesh>
          </geometry>
          <max_contacts>10</max_contacts>
          <surface>
            <contact>
              <ode/>
            </contact>
            <bounce/>
            <friction>
              <torsional>
                <ode/>
              </torsional>
              <ode/>
            </friction>
          </surface>
        </collision>
        <visual name='robotiq_85_left_inner_knuckle_link_visual'>
          <pose>0 0 0 0 -0 0</pose>
          <geometry>
            <mesh>
              <scale>1 1 1</scale>
              <uri>/home/dylan/catkin_ws/src/robotiq/robotiq_description/meshes/visual/robotiq_85_inner_knuckle_link.dae</uri>
            </mesh>
          </geometry>
        </visual>
        <self_collide>0</self_collide>
        <enable_wind>0</enable_wind>
        <kinematic>0</kinematic>
      </link>
      <joint name='robotiq_85_left_finger_tip_joint' type='revolute'>
        <pose relative_to='robotiq_85_left_inner_knuckle_link'>0.04304 -0.037599 0 0 -0 0</pose>
        <parent>robotiq_85_left_inner_knuckle_link</parent>
        <child>robotiq_85_left_finger_tip_link</child>
        <axis>
          <xyz>0 0 1</xyz>
          <limit>
            <effort>0.1</effort>
            <velocity>100</velocity>
            <lower>-1e+16</lower>
            <upper>1e+16</upper>
          </limit>
          <dynamics>
            <spring_reference>0</spring_reference>
            <spring_stiffness>0</spring_stiffness>
          </dynamics>
        </axis>
      </joint>
      <link name='robotiq_85_left_finger_tip_link'>
        <pose relative_to='robotiq_85_left_finger_tip_joint'>0 0 0 0 -0 0</pose>
        <inertial>
          <pose>0 0 0 0 -0 0</pose>
          <mass>0.019555</mass>
          <inertia>
            <ixx>2e-06</ixx>
            <ixy>0</ixy>
            <ixz>0</ixz>
            <iyy>5e-06</iyy>
            <iyz>0</iyz>
            <izz>6e-06</izz>
          </inertia>
        </inertial>
        <collision name='robotiq_85_left_finger_tip_link_collision'>
          <pose>0 0 0 0 -0 0</pose>
          <geometry>
            <mesh>
              <scale>1 1 1</scale>
              <uri>/home/dylan/catkin_ws/src/robotiq/robotiq_description/meshes/collision/robotiq_85_finger_tip_link.stl</uri>
            </mesh>
          </geometry>
          <surface>
            <contact>
              <ode>
                <kp>1e+06</kp>
                <kd>1</kd>
                <min_depth>0.001</min_depth>
              </ode>
            </contact>
            <friction>
              <ode>
                <mu>1</mu>
                <mu2>1</mu2>
              </ode>
              <torsional>
                <ode/>
              </torsional>
            </friction>
            <bounce/>
          </surface>
          <max_contacts>10</max_contacts>
        </collision>
        <visual name='robotiq_85_left_finger_tip_link_visual'>
          <pose>0 0 0 0 -0 0</pose>
          <geometry>
            <mesh>
              <scale>1 1 1</scale>
              <uri>/home/dylan/catkin_ws/src/robotiq/robotiq_description/meshes/visual/robotiq_85_finger_tip_link.dae</uri>
            </mesh>
          </geometry>
        </visual>
        <self_collide>0</self_collide>
        <enable_wind>0</enable_wind>
        <kinematic>0</kinematic>
      </link>
      <joint name='robotiq_85_left_knuckle_joint' type='revolute'>
        <pose relative_to='wrist_3_link'>-0.030601 0.145205 0 3.14159 -0 1.5708</pose>
        <parent>wrist_3_link</parent>
        <child>robotiq_85_left_knuckle_link</child>
        <axis>
          <xyz>0 0 1</xyz>
          <limit>
            <lower>0</lower>
            <upper>0.80285</upper>
            <effort>1000</effort>
            <velocity>0.5</velocity>
          </limit>
          <dynamics>
            <spring_reference>0</spring_reference>
            <spring_stiffness>0</spring_stiffness>
          </dynamics>
        </axis>
      </joint>
      <link name='robotiq_85_left_knuckle_link'>
        <pose relative_to='robotiq_85_left_knuckle_joint'>0 0 0 0 -0 0</pose>
        <inertial>
          <pose>-0.002436 -0.018774 0 0 -0 0</pose>
          <mass>0.0458</mass>
          <inertia>
            <ixx>2.29304e-05</ixx>
            <ixy>-4.4183e-06</ixy>
            <ixz>0</ixz>
            <iyy>2.2184e-05</iyy>
            <iyz>0</iyz>
            <izz>4.11145e-05</izz>
          </inertia>
        </inertial>
        <collision name='robotiq_85_left_knuckle_link_collision'>
          <pose>0 0 0 0 -0 0</pose>
          <geometry>
            <mesh>
              <scale>1 1 1</scale>
              <uri>/home/dylan/catkin_ws/src/robotiq/robotiq_description/meshes/collision/robotiq_85_knuckle_link.stl</uri>
            </mesh>
          </geometry>
          <max_contacts>10</max_contacts>
          <surface>
            <contact>
              <ode/>
            </contact>
            <bounce/>
            <friction>
              <torsional>
                <ode/>
              </torsional>
              <ode/>
            </friction>
          </surface>
        </collision>
        <collision name='robotiq_85_left_knuckle_link_fixed_joint_lump__robotiq_85_left_finger_link_collision_1'>
          <pose>-0.004086 -0.031486 0 0 -0 0</pose>
          <geometry>
            <mesh>
              <scale>1 1 1</scale>
              <uri>/home/dylan/catkin_ws/src/robotiq/robotiq_description/meshes/collision/robotiq_85_finger_link.stl</uri>
            </mesh>
          </geometry>
          <max_contacts>10</max_contacts>
          <surface>
            <contact>
              <ode/>
            </contact>
            <bounce/>
            <friction>
              <torsional>
                <ode/>
              </torsional>
              <ode/>
            </friction>
          </surface>
        </collision>
        <visual name='robotiq_85_left_knuckle_link_visual'>
          <pose>0 0 0 0 -0 0</pose>
          <geometry>
            <mesh>
              <scale>1 1 1</scale>
              <uri>/home/dylan/catkin_ws/src/robotiq/robotiq_description/meshes/visual/robotiq_85_knuckle_link.dae</uri>
            </mesh>
          </geometry>
        </visual>
        <visual name='robotiq_85_left_knuckle_link_fixed_joint_lump__robotiq_85_left_finger_link_visual_1'>
          <pose>-0.004086 -0.031486 0 0 -0 0</pose>
          <geometry>
            <mesh>
              <scale>1 1 1</scale>
              <uri>/home/dylan/catkin_ws/src/robotiq/robotiq_description/meshes/visual/robotiq_85_finger_link.dae</uri>
            </mesh>
          </geometry>
        </visual>
        <self_collide>0</self_collide>
        <enable_wind>0</enable_wind>
        <kinematic>0</kinematic>
      </link>
      <joint name='robotiq_85_right_inner_knuckle_joint' type='revolute'>
        <pose relative_to='wrist_3_link'>0.0127 0.15172 0 0 -0 1.5708</pose>
        <parent>wrist_3_link</parent>
        <child>robotiq_85_right_inner_knuckle_link</child>
        <axis>
          <xyz>0 0 1</xyz>
          <limit>
            <effort>0.1</effort>
            <velocity>100</velocity>
            <lower>-1e+16</lower>
            <upper>1e+16</upper>
          </limit>
          <dynamics>
            <spring_reference>0</spring_reference>
            <spring_stiffness>0</spring_stiffness>
          </dynamics>
        </axis>
      </joint>
      <link name='robotiq_85_right_inner_knuckle_link'>
        <pose relative_to='robotiq_85_right_inner_knuckle_joint'>0 0 0 0 -0 0</pose>
        <inertial>
          <pose>0 0 0 0 -0 0</pose>
          <mass>0.029951</mass>
          <inertia>
            <ixx>3.9e-05</ixx>
            <ixy>0</ixy>
            <ixz>0</ixz>
            <iyy>5e-06</iyy>
            <iyz>0</iyz>
            <izz>3.5e-05</izz>
          </inertia>
        </inertial>
        <collision name='robotiq_85_right_inner_knuckle_link_collision'>
          <pose>0 0 0 0 -0 0</pose>
          <geometry>
            <mesh>
              <scale>1 1 1</scale>
              <uri>/home/dylan/catkin_ws/src/robotiq/robotiq_description/meshes/collision/robotiq_85_inner_knuckle_link.stl</uri>
            </mesh>
          </geometry>
          <max_contacts>10</max_contacts>
          <surface>
            <contact>
              <ode/>
            </contact>
            <bounce/>
            <friction>
              <torsional>
                <ode/>
              </torsional>
              <ode/>
            </friction>
          </surface>
        </collision>
        <visual name='robotiq_85_right_inner_knuckle_link_visual'>
          <pose>0 0 0 0 -0 0</pose>
          <geometry>
            <mesh>
              <scale>1 1 1</scale>
              <uri>/home/dylan/catkin_ws/src/robotiq/robotiq_description/meshes/visual/robotiq_85_inner_knuckle_link.dae</uri>
            </mesh>
          </geometry>
        </visual>
        <self_collide>0</self_collide>
        <enable_wind>0</enable_wind>
        <kinematic>0</kinematic>
      </link>
      <joint name='robotiq_85_right_finger_tip_joint' type='revolute'>
        <pose relative_to='robotiq_85_right_inner_knuckle_link'>0.04304 -0.037599 0 0 -0 0</pose>
        <parent>robotiq_85_right_inner_knuckle_link</parent>
        <child>robotiq_85_right_finger_tip_link</child>
        <axis>
          <xyz>0 0 1</xyz>
          <limit>
            <effort>0.1</effort>
            <velocity>100</velocity>
            <lower>-1e+16</lower>
            <upper>1e+16</upper>
          </limit>
          <dynamics>
            <spring_reference>0</spring_reference>
            <spring_stiffness>0</spring_stiffness>
          </dynamics>
        </axis>
      </joint>
      <link name='robotiq_85_right_finger_tip_link'>
        <pose relative_to='robotiq_85_right_finger_tip_joint'>0 0 0 0 -0 0</pose>
        <inertial>
          <pose>0 0 0 0 -0 0</pose>
          <mass>0.019555</mass>
          <inertia>
            <ixx>2e-06</ixx>
            <ixy>0</ixy>
            <ixz>0</ixz>
            <iyy>5e-06</iyy>
            <iyz>0</iyz>
            <izz>6e-06</izz>
          </inertia>
        </inertial>
        <collision name='robotiq_85_right_finger_tip_link_collision'>
          <pose>0 0 0 0 -0 0</pose>
          <geometry>
            <mesh>
              <scale>1 1 1</scale>
              <uri>/home/dylan/catkin_ws/src/robotiq/robotiq_description/meshes/collision/robotiq_85_finger_tip_link.stl</uri>
            </mesh>
          </geometry>
          <surface>
            <contact>
              <ode>
                <kp>1e+06</kp>
                <kd>1</kd>
                <min_depth>0.001</min_depth>
              </ode>
            </contact>
            <friction>
              <ode>
                <mu>1</mu>
                <mu2>1</mu2>
              </ode>
              <torsional>
                <ode/>
              </torsional>
            </friction>
            <bounce/>
          </surface>
          <max_contacts>10</max_contacts>
        </collision>
        <visual name='robotiq_85_right_finger_tip_link_visual'>
          <pose>0 0 0 0 -0 0</pose>
          <geometry>
            <mesh>
              <scale>1 1 1</scale>
              <uri>/home/dylan/catkin_ws/src/robotiq/robotiq_description/meshes/visual/robotiq_85_finger_tip_link.dae</uri>
            </mesh>
          </geometry>
        </visual>
        <self_collide>0</self_collide>
        <enable_wind>0</enable_wind>
        <kinematic>0</kinematic>
      </link>
      <joint name='robotiq_85_right_knuckle_joint' type='revolute'>
        <pose relative_to='wrist_3_link'>0.030601 0.145205 0 0 -0 1.5708</pose>
        <parent>wrist_3_link</parent>
        <child>robotiq_85_right_knuckle_link</child>
        <axis>
          <xyz>0 0 1</xyz>
          <limit>
            <effort>1000</effort>
            <velocity>100</velocity>
            <lower>-1e+16</lower>
            <upper>1e+16</upper>
          </limit>
          <dynamics>
            <spring_reference>0</spring_reference>
            <spring_stiffness>0</spring_stiffness>
          </dynamics>
        </axis>
      </joint>
      <link name='robotiq_85_right_knuckle_link'>
        <pose relative_to='robotiq_85_right_knuckle_joint'>0 0 0 0 -0 0</pose>
        <inertial>
          <pose>-0.002436 -0.018774 0 0 -0 0</pose>
          <mass>0.0458</mass>
          <inertia>
            <ixx>2.29304e-05</ixx>
            <ixy>-4.4183e-06</ixy>
            <ixz>0</ixz>
            <iyy>2.2184e-05</iyy>
            <iyz>0</iyz>
            <izz>4.11145e-05</izz>
          </inertia>
        </inertial>
        <collision name='robotiq_85_right_knuckle_link_collision'>
          <pose>0 0 0 0 -0 0</pose>
          <geometry>
            <mesh>
              <scale>1 1 1</scale>
              <uri>/home/dylan/catkin_ws/src/robotiq/robotiq_description/meshes/collision/robotiq_85_knuckle_link.stl</uri>
            </mesh>
          </geometry>
          <max_contacts>10</max_contacts>
          <surface>
            <contact>
              <ode/>
            </contact>
            <bounce/>
            <friction>
              <torsional>
                <ode/>
              </torsional>
              <ode/>
            </friction>
          </surface>
        </collision>
        <collision name='robotiq_85_right_knuckle_link_fixed_joint_lump__robotiq_85_right_finger_link_collision_1'>
          <pose>-0.004086 -0.031486 0 0 -0 0</pose>
          <geometry>
            <mesh>
              <scale>1 1 1</scale>
              <uri>/home/dylan/catkin_ws/src/robotiq/robotiq_description/meshes/collision/robotiq_85_finger_link.stl</uri>
            </mesh>
          </geometry>
          <max_contacts>10</max_contacts>
          <surface>
            <contact>
              <ode/>
            </contact>
            <bounce/>
            <friction>
              <torsional>
                <ode/>
              </torsional>
              <ode/>
            </friction>
          </surface>
        </collision>
        <visual name='robotiq_85_right_knuckle_link_visual'>
          <pose>0 0 0 0 -0 0</pose>
          <geometry>
            <mesh>
              <scale>1 1 1</scale>
              <uri>/home/dylan/catkin_ws/src/robotiq/robotiq_description/meshes/visual/robotiq_85_knuckle_link.dae</uri>
            </mesh>
          </geometry>
        </visual>
        <visual name='robotiq_85_right_knuckle_link_fixed_joint_lump__robotiq_85_right_finger_link_visual_1'>
          <pose>-0.004086 -0.031486 0 0 -0 0</pose>
          <geometry>
            <mesh>
              <scale>1 1 1</scale>
              <uri>/home/dylan/catkin_ws/src/robotiq/robotiq_description/meshes/visual/robotiq_85_finger_link.dae</uri>
            </mesh>
          </geometry>
        </visual>
        <self_collide>0</self_collide>
        <enable_wind>0</enable_wind>
        <kinematic>0</kinematic>
      </link>
      <plugin name='ros_control' filename='libgazebo_ros_control.so'>
        <robotNamespace>/</robotNamespace>
      </plugin>
      <plugin name='mimic_robotiq_85_1' filename='libgazebo_mimic_joint_plugin.so'>
        <joint>robotiq_85_left_knuckle_joint</joint>
        <mimicJoint>robotiq_85_right_knuckle_joint</mimicJoint>
        <robotNamespace>/</robotNamespace>
      </plugin>
      <plugin name='mimic_robotiq_85_2' filename='libgazebo_mimic_joint_plugin.so'>
        <joint>robotiq_85_left_knuckle_joint</joint>
        <mimicJoint>robotiq_85_left_inner_knuckle_joint</mimicJoint>
        <robotNamespace>/</robotNamespace>
      </plugin>
      <plugin name='mimic_robotiq_85_3' filename='libgazebo_mimic_joint_plugin.so'>
        <joint>robotiq_85_left_knuckle_joint</joint>
        <mimicJoint>robotiq_85_right_inner_knuckle_joint</mimicJoint>
        <robotNamespace>/</robotNamespace>
      </plugin>
      <plugin name='mimic_robotiq_85_4' filename='libgazebo_mimic_joint_plugin.so'>
        <joint>robotiq_85_left_knuckle_joint</joint>
        <mimicJoint>robotiq_85_left_finger_tip_joint</mimicJoint>
        <multiplier>-1.0</multiplier>
        <offset>0.0</offset>
        <robotNamespace>/</robotNamespace>
      </plugin>
      <plugin name='mimic_robotiq_85_5' filename='libgazebo_mimic_joint_plugin.so'>
        <joint>robotiq_85_left_knuckle_joint</joint>
        <mimicJoint>robotiq_85_right_finger_tip_joint</mimicJoint>
        <multiplier>-1.0</multiplier>
        <offset>0.0</offset>
        <robotNamespace>/</robotNamespace>
      </plugin>
      <plugin name='ft_sensor_plugin' filename='libgazebo_ros_ft_sensor.so'>
        <updateRate>250.0</updateRate>
        <topicName>ft_sensor/raw</topicName>
        <gaussianNoise>0.0</gaussianNoise>
        <jointName>wrist_3_joint</jointName>
        <robotNamespace>/</robotNamespace>
      </plugin>
      <static>0</static>
      <gripper name='gazebo_gripper'>
        <grasp_check>
          <attach_steps>2</attach_steps>
          <detach_steps>2</detach_steps>
          <min_contact_count>3</min_contact_count>
        </grasp_check>
        <gripper_link>robotiq_85_left_finger_tip_link</gripper_link>
        <gripper_link>robotiq_85_right_finger_tip_link</gripper_link>
        <palm_link>wrist_3_link</palm_link>
      </gripper>
      <pose>0 0 1.21 0 -0 0</pose>
    </model>
    <model name='mug'>
      <static>0</static>
      <link name='link'>
        <inertial>
          <pose>-0.018859 0.016573 0.026899 2.21834 -1.46895 -2.2505</pose>
          <mass>0.000138121</mass>
          <inertia>
            <ixx>1.7286e-07</ixx>
            <ixy>-4.38059e-23</ixy>
            <ixz>4.73972e-24</ixz>
            <iyy>1.35071e-07</iyy>
            <iyz>-1.3956e-24</iyz>
            <izz>1.18795e-07</izz>
          </inertia>
        </inertial>
        <collision name='collision'>
          <geometry>
            <mesh>
              <uri>model://025_mug/google_16k/textured.obj</uri>
              <scale>0.7 0.7 0.7</scale>
            </mesh>
          </geometry>
          <surface>
            <contact>
              <ode/>
            </contact>
            <bounce/>
            <friction>
              <torsional>
                <ode/>
              </torsional>
              <ode/>
            </friction>
          </surface>
          <max_contacts>10</max_contacts>
        </collision>
        <visual name='visual'>
          <geometry>
            <mesh>
              <uri>model://025_mug/google_16k/textured.obj</uri>
              <scale>0.7 0.7 0.7</scale>
            </mesh>
          </geometry>
          <material>
            <script>
              <uri>model://025_mug/mug.material</uri>
              <name>mug</name>
            </script>
          </material>
        </visual>
        <self_collide>0</self_collide>
        <enable_wind>0</enable_wind>
        <kinematic>0</kinematic>
      </link>
      <pose>1.81428 -1.25492 0 0 -0 0</pose>
    </model>
  </world>
</sdf>
