<sdf version='1.7'>
  <world name='default'>
    <light name='sun' type='directional'>
      <cast_shadows>1</cast_shadows>
      <pose>0 0 10 0 -0 0</pose>
      <diffuse>0.8 0.8 0.8 1</diffuse>
      <specular>0.2 0.2 0.2 1</specular>
      <attenuation>
        <range>1000</range>
        <constant>0.9</constant>
        <linear>0.01</linear>
        <quadratic>0.001</quadratic>
      </attenuation>
      <direction>-0.5 0.1 -0.9</direction>
      <spot>
        <inner_angle>0</inner_angle>
        <outer_angle>0</outer_angle>
        <falloff>0</falloff>
      </spot>
    </light>
    <model name='ground_plane'>
      <static>1</static>
      <link name='link'>
        <collision name='collision'>
          <geometry>
            <plane>
              <normal>0 0 1</normal>
              <size>100 100</size>
            </plane>
          </geometry>
          <surface>
            <contact>
              <collide_bitmask>65535</collide_bitmask>
              <ode/>
            </contact>
            <friction>
              <ode>
                <mu>100</mu>
                <mu2>50</mu2>
              </ode>
              <torsional>
                <ode/>
              </torsional>
            </friction>
            <bounce/>
          </surface>
          <max_contacts>10</max_contacts>
        </collision>
        <visual name='visual'>
          <cast_shadows>0</cast_shadows>
          <geometry>
            <plane>
              <normal>0 0 1</normal>
              <size>100 100</size>
            </plane>
          </geometry>
          <material>
            <script>
              <uri>file://media/materials/scripts/gazebo.material</uri>
              <name>Gazebo/Grey</name>
            </script>
          </material>
        </visual>
        <self_collide>0</self_collide>
        <enable_wind>0</enable_wind>
        <kinematic>0</kinematic>
      </link>
    </model>
    <gravity>0 0 -9.8</gravity>
    <magnetic_field>6e-06 2.3e-05 -4.2e-05</magnetic_field>
    <atmosphere type='adiabatic'/>
    <physics name='default_physics' default='0' type='ode'>
      <max_step_size>0.001</max_step_size>
      <real_time_factor>1</real_time_factor>
      <real_time_update_rate>1000</real_time_update_rate>
    </physics>
    <scene>
      <ambient>0.4 0.4 0.4 1</ambient>
      <background>0.7 0.7 0.7 1</background>
      <shadows>1</shadows>
    </scene>
    <audio>
      <device>default</device>
    </audio>
    <wind/>
    <spherical_coordinates>
      <surface_model>EARTH_WGS84</surface_model>
      <latitude_deg>0</latitude_deg>
      <longitude_deg>0</longitude_deg>
      <elevation>0</elevation>
      <heading_deg>0</heading_deg>
    </spherical_coordinates>
    <state world_name='default'>
      <sim_time>2315 617000000</sim_time>
      <real_time>61 492565111</real_time>
      <wall_time>1695248431 89535419</wall_time>
      <iterations>51688</iterations>
      <model name='ground_plane'>
        <pose>0 0 0 0 -0 0</pose>
        <scale>1 1 1</scale>
        <link name='link'>
          <pose>0 0 0 0 -0 0</pose>
          <velocity>0 0 0 0 -0 0</velocity>
          <acceleration>0 0 0 0 -0 0</acceleration>
          <wrench>0 0 0 0 -0 0</wrench>
        </link>
      </model>
      <model name='nist_elevated_floor_120'>
        <pose>0.005735 -0.482404 0 0 -0 0</pose>
        <scale>1 1 1</scale>
        <link name='nist_elevated_floor_120'>
          <pose>0.005735 -0.482404 0 0 -0 0</pose>
          <velocity>0 0 0 0 -0 0</velocity>
          <acceleration>0 0 0 0 -0 0</acceleration>
          <wrench>0 0 0 0 -0 0</wrench>
        </link>
      </model>
      <model name='phillips_screwdriver'>
        <pose>0.080634 0.667648 1.01575 -0.019499 -0.010784 0.0146</pose>
        <scale>1.5 1.5 1.5</scale>
        <link name='link'>
          <pose>0.080634 0.667648 1.01575 -0.019499 -0.010784 0.0146</pose>
          <velocity>5e-05 -6.8e-05 -0.001303 0.090338 0.068092 -5.5e-05</velocity>
          <acceleration>-0.106999 0.042434 -7.28937 3.03717 -0.572316 -0.116251</acceleration>
          <wrench>-8e-06 3e-06 -0.000561 0 -0 0</wrench>
        </link>
      </model>
      <model name='robot'>
        <pose>-0 0 1.21 0 -0 0</pose>
        <scale>1 1 1</scale>
        <link name='base_link'>
          <pose>-0 0 1.21 2.8e-05 -1e-06 -0</pose>
          <velocity>-2e-06 4e-06 6e-06 0.005361 -0.000211 -0</velocity>
          <acceleration>-0.00486 0.007177 0.011968 -1.84554 -0.426863 -2.4e-05</acceleration>
          <wrench>-0.019441 0.028708 0.047871 0 -0 0</wrench>
        </link>
        <link name='camera_rgb_frame'>
          <pose>0 0.2 2.01 0 1.25 1.5708</pose>
          <velocity>0 0 -0 0 -0 0</velocity>
          <acceleration>0 0 0 0 -0 0</acceleration>
          <wrench>0 0 0 0 -0 0</wrench>
        </link>
        <link name='forearm_link'>
          <pose>0.423173 0.016644 1.26 -3.14069 1.44369 -3.1395</pose>
          <velocity>0.00062 0.00045 0.006963 -0.022315 -0.007023 0.005741</velocity>
          <acceleration>1.58364 2.15273 16.6496 -0.658822 -1.31768 -1.96741</acceleration>
          <wrench>3.60277 4.89746 37.8779 0 -0 0</wrench>
        </link>
        <link name='robotiq_85_left_finger_tip_link'>
          <pose>0.849713 0.310637 1.09189 0.602853 0.000123 1.56106</pose>
          <velocity>0.005759 -0.004215 -0.001771 -0.053814 -0.03472 -0.031707</velocity>
          <acceleration>5.7586 -4.21531 -1.77056 0.909887 0.823301 -0.671959</acceleration>
          <wrench>0.11261 -0.08243 -0.034623 0 -0 0</wrench>
        </link>
        <link name='robotiq_85_left_inner_knuckle_link'>
          <pose>0.825252 0.261695 1.1084 0.594985 -0.103544 1.71279</pose>
          <velocity>0.003069 -0.002643 -0.000319 -0.05417 -0.03482 -0.031662</velocity>
          <acceleration>3.06901 -2.64264 -0.318533 2.71762 -1.03531 0.66477</acceleration>
          <wrench>0.09192 -0.07915 -0.00954 0 -0 0</wrench>
        </link>
        <link name='robotiq_85_left_knuckle_link'>
          <pose>0.839933 0.255035 1.09825 0.594945 -0.103695 1.71284</pose>
          <velocity>0.003199 -0.003524 0.000534 0.035176 -0.039034 0.06273</velocity>
          <acceleration>7.07161 -3.92436 2.35613 0.868877 0.777318 -2.93691</acceleration>
          <wrench>0.32388 -0.179736 0.107911 0 -0 0</wrench>
        </link>
        <link name='robotiq_85_right_finger_tip_link'>
          <pose>0.780833 0.311312 1.1393 -2.53876 0.000118 1.56106</pose>
          <velocity>0.003986 0.000153 -0.004208 -0.051928 -0.039925 -0.030829</velocity>
          <acceleration>3.98556 0.152971 -4.2078 1.46299 0.389262 0.199913</acceleration>
          <wrench>0.077938 0.002991 -0.082284 0 -0 0</wrench>
        </link>
        <link name='robotiq_85_right_inner_knuckle_link'>
          <pose>0.804331 0.2619 1.1228 -2.54667 0.103781 1.40932</pose>
          <velocity>0.00254 -0.001346 -0.001032 -0.052282 -0.039822 -0.030787</velocity>
          <acceleration>2.5401 -1.34558 -1.03247 0.068472 -0.162447 -0.458411</acceleration>
          <wrench>0.076079 -0.040302 -0.030924 0 -0 0</wrench>
        </link>
        <link name='robotiq_85_right_knuckle_link'>
          <pose>0.789522 0.25553 1.13295 -2.54664 0.103702 1.40928</pose>
          <velocity>0.001925 -0.000442 -0.001295 -0.033499 -0.036234 -0.038295</velocity>
          <acceleration>1.58194 0.51259 -1.89836 1.66839 0.581042 2.95093</acceleration>
          <wrench>0.072453 0.023477 -0.086945 0 -0 0</wrench>
        </link>
        <link name='shoulder_link'>
          <pose>0 -3e-06 1.29916 -5.1e-05 3e-06 0.001185</pose>
          <velocity>4.2e-05 -0.000577 -7e-06 -0.009746 0.00068 0.004698</velocity>
          <acceleration>0.083718 -1.15453 -0.014861 -0.641416 1.36678 -2.96623</acceleration>
          <wrench>0.309757 -4.27177 -0.054986 0 -0 0</wrench>
        </link>
        <link name='upper_arm_link'>
          <pose>-0.00016 0.135847 1.29915 -3.14065 1.47851 -3.13947</pose>
          <velocity>-0.000524 -0.000597 -0.001509 -0.016816 -0.014296 0.004555</velocity>
          <acceleration>-0.342093 0.536197 4.94416 -2.81403 0.87102 -3.12656</acceleration>
          <wrench>-2.87119 4.5003 41.4963 0 -0 0</wrench>
        </link>
        <link name='wrist_1_link'>
          <pose>0.812258 0.017102 1.21026 -3.14146 0.012252 -3.1404</pose>
          <velocity>0.00091 0.001666 0.00791 -0.025297 0.034451 0.006619</velocity>
          <acceleration>0.564744 3.49843 11.1226 0.018613 -0.26055 0.978994</acceleration>
          <wrench>0.688424 4.26459 13.5584 0 -0 0</wrench>
        </link>
        <link name='wrist_2_link'>
          <pose>0.812147 0.110098 1.21025 -3.14157 0.012253 3.1318</pose>
          <velocity>0.00029 0.000956 0.005418 -0.029506 0.03441 -0.037964</velocity>
          <acceleration>-5.95266 -3.59057 10.7584 -2.69738 -0.340172 -0.224445</acceleration>
          <wrench>-7.2563 -4.37691 13.1144 0 -0 0</wrench>
        </link>
        <link name='wrist_3_link'>
          <pose>0.813306 0.110085 1.1156 -3.14155 -0.602846 3.13178</pose>
          <velocity>-0.002961 -0.001908 0.004524 -0.032682 -0.03699 -0.037991</velocity>
          <acceleration>0.46683 -3.68514 3.56114 -0.380906 0.697924 -0.237411</acceleration>
          <wrench>0.463493 -3.6588 3.53568 0 -0 0</wrench>
        </link>
      </model>
      <model name='table'>
        <pose>1.8e-05 0.659275 0 0 -0 0</pose>
        <scale>1 1 1</scale>
        <link name='link'>
          <pose>1.8e-05 0.659275 0 0 -0 0</pose>
          <velocity>0 0 0 0 -0 0</velocity>
          <acceleration>0 0 0 0 -0 0</acceleration>
          <wrench>0 0 0 0 -0 0</wrench>
        </link>
      </model>
      <light name='sun'>
        <pose>0 0 10 0 -0 0</pose>
      </light>
    </state>
    <gui fullscreen='0'>
      <camera name='user_camera'>
        <pose>0.562086 2.59331 3.92489 0 0.913738 -1.78727</pose>
        <view_controller>orbit</view_controller>
        <projection_type>perspective</projection_type>
      </camera>
    </gui>
    <model name='nist_elevated_floor_120'>
      <static>1</static>
      <link name='nist_elevated_floor_120'>
        <pose>0 0 0 0 -0 0</pose>
        <collision name='collision'>
          <geometry>
            <mesh>
              <uri>model://nist_elevated_floor_120/meshes/nist_elevated_floor_120.dae</uri>
              <scale>1 1 1</scale>
            </mesh>
          </geometry>
          <max_contacts>10</max_contacts>
          <surface>
            <contact>
              <ode/>
            </contact>
            <bounce/>
            <friction>
              <torsional>
                <ode/>
              </torsional>
              <ode/>
            </friction>
          </surface>
        </collision>
        <visual name='visual'>
          <geometry>
            <mesh>
              <uri>model://nist_elevated_floor_120/meshes/nist_elevated_floor_120.dae</uri>
              <scale>1 1 1</scale>
            </mesh>
          </geometry>
        </visual>
        <self_collide>0</self_collide>
        <enable_wind>0</enable_wind>
        <kinematic>0</kinematic>
      </link>
      <pose>0.297914 -0.687027 0 0 -0 0</pose>
    </model>
    <model name='table'>
      <static>1</static>
      <link name='link'>
        <collision name='surface'>
          <pose>0 0 1 0 -0 0</pose>
          <geometry>
            <box>
              <size>1.5 0.8 0.03</size>
            </box>
          </geometry>
          <surface>
            <friction>
              <ode>
                <mu>0.6</mu>
                <mu2>0.6</mu2>
              </ode>
              <torsional>
                <ode/>
              </torsional>
            </friction>
            <contact>
              <ode/>
            </contact>
            <bounce/>
          </surface>
          <max_contacts>10</max_contacts>
        </collision>
        <visual name='visual1'>
          <pose>0 0 1 0 -0 0</pose>
          <geometry>
            <box>
              <size>1.5 0.8 0.03</size>
            </box>
          </geometry>
          <material>
            <script>
              <uri>file://media/materials/scripts/gazebo.material</uri>
              <name>Gazebo/White</name>
            </script>
          </material>
        </visual>
        <collision name='front_left_leg'>
          <pose>0.68 0.38 0.5 0 -0 0</pose>
          <geometry>
            <cylinder>
              <radius>0.02</radius>
              <length>1</length>
            </cylinder>
          </geometry>
          <max_contacts>10</max_contacts>
          <surface>
            <contact>
              <ode/>
            </contact>
            <bounce/>
            <friction>
              <torsional>
                <ode/>
              </torsional>
              <ode/>
            </friction>
          </surface>
        </collision>
        <visual name='front_left_leg'>
          <pose>0.68 0.38 0.5 0 -0 0</pose>
          <geometry>
            <cylinder>
              <radius>0.02</radius>
              <length>1</length>
            </cylinder>
          </geometry>
          <material>
            <script>
              <uri>file://media/materials/scripts/gazebo.material</uri>
              <name>Gazebo/Grey</name>
            </script>
          </material>
        </visual>
        <collision name='front_right_leg'>
          <pose>0.68 -0.38 0.5 0 -0 0</pose>
          <geometry>
            <cylinder>
              <radius>0.02</radius>
              <length>1</length>
            </cylinder>
          </geometry>
          <max_contacts>10</max_contacts>
          <surface>
            <contact>
              <ode/>
            </contact>
            <bounce/>
            <friction>
              <torsional>
                <ode/>
              </torsional>
              <ode/>
            </friction>
          </surface>
        </collision>
        <visual name='front_right_leg'>
          <pose>0.68 -0.38 0.5 0 -0 0</pose>
          <geometry>
            <cylinder>
              <radius>0.02</radius>
              <length>1</length>
            </cylinder>
          </geometry>
          <material>
            <script>
              <uri>file://media/materials/scripts/gazebo.material</uri>
              <name>Gazebo/Grey</name>
            </script>
          </material>
        </visual>
        <collision name='back_right_leg'>
          <pose>-0.68 -0.38 0.5 0 -0 0</pose>
          <geometry>
            <cylinder>
              <radius>0.02</radius>
              <length>1</length>
            </cylinder>
          </geometry>
          <max_contacts>10</max_contacts>
          <surface>
            <contact>
              <ode/>
            </contact>
            <bounce/>
            <friction>
              <torsional>
                <ode/>
              </torsional>
              <ode/>
            </friction>
          </surface>
        </collision>
        <visual name='back_right_leg'>
          <pose>-0.68 -0.38 0.5 0 -0 0</pose>
          <geometry>
            <cylinder>
              <radius>0.02</radius>
              <length>1</length>
            </cylinder>
          </geometry>
          <material>
            <script>
              <uri>file://media/materials/scripts/gazebo.material</uri>
              <name>Gazebo/Grey</name>
            </script>
          </material>
        </visual>
        <collision name='back_left_leg'>
          <pose>-0.68 0.38 0.5 0 -0 0</pose>
          <geometry>
            <cylinder>
              <radius>0.02</radius>
              <length>1</length>
            </cylinder>
          </geometry>
          <max_contacts>10</max_contacts>
          <surface>
            <contact>
              <ode/>
            </contact>
            <bounce/>
            <friction>
              <torsional>
                <ode/>
              </torsional>
              <ode/>
            </friction>
          </surface>
        </collision>
        <visual name='back_left_leg'>
          <pose>-0.68 0.38 0.5 0 -0 0</pose>
          <geometry>
            <cylinder>
              <radius>0.02</radius>
              <length>1</length>
            </cylinder>
          </geometry>
          <material>
            <script>
              <uri>file://media/materials/scripts/gazebo.material</uri>
              <name>Gazebo/Grey</name>
            </script>
          </material>
        </visual>
        <self_collide>0</self_collide>
        <enable_wind>0</enable_wind>
        <kinematic>0</kinematic>
      </link>
      <pose>0.270759 1.80105 0 0 -0 0</pose>
    </model>
    <model name='robot'>
      <joint name='camera_rgb_joint' type='fixed'>
        <pose relative_to='__model__'>0 0.2 0.8 0 1.25 1.5708</pose>
        <parent>world</parent>
        <child>camera_rgb_frame</child>
      </joint>
      <link name='camera_rgb_frame'>
        <pose relative_to='camera_rgb_joint'>0 0 0 0 -0 0</pose>
        <inertial>
          <pose>-0.0062 0 -0.0032 0 -0 0</pose>
          <mass>0.005</mass>
          <inertia>
            <ixx>0.000500205</ixx>
            <ixy>0</ixy>
            <ixz>-3.968e-07</ixz>
            <iyy>0.000500974</iyy>
            <iyz>0</iyz>
            <izz>0.000500769</izz>
          </inertia>
        </inertial>
        <collision name='camera_rgb_frame_fixed_joint_lump__camera_link_collision'>
          <pose>-0.031 0 -0.016 0 -0 0</pose>
          <geometry>
            <box>
              <size>0.07271 0.27794 0.073</size>
            </box>
          </geometry>
          <max_contacts>10</max_contacts>
          <surface>
            <contact>
              <ode/>
            </contact>
            <bounce/>
            <friction>
              <torsional>
                <ode/>
              </torsional>
              <ode/>
            </friction>
          </surface>
        </collision>
        <visual name='camera_rgb_frame_fixed_joint_lump__camera_link_visual'>
          <pose>-0.031 0 -0.016 0 -0 1.5708</pose>
          <geometry>
            <mesh>
              <scale>1 1 1</scale>
              <uri>/home/dylan/catkin_ws/src/common-sensors/common_sensors/meshes/sensors/kinect.dae</uri>
            </mesh>
          </geometry>
        </visual>
        <sensor name='camera1' type='depth'>
          <always_on>1</always_on>
          <update_rate>20</update_rate>
          <camera>
            <horizontal_fov>1.0472</horizontal_fov>
            <image>
              <format>R8G8B8</format>
              <width>640</width>
              <height>480</height>
            </image>
            <clip>
              <near>0.05</near>
              <far>8</far>
            </clip>
          </camera>
          <plugin name='camera_depth_frame_kinect_controller' filename='libgazebo_ros_openni_kinect.so'>
            <baseline>0.1</baseline>
            <alwaysOn>1</alwaysOn>
            <updateRate>10</updateRate>
            <cameraName>camera1</cameraName>
            <imageTopicName>rgb/image_raw</imageTopicName>
            <cameraInfoTopicName>rgb/camera_info</cameraInfoTopicName>
            <depthImageTopicName>depth/image_raw</depthImageTopicName>
            <depthImageCameraInfoTopicName>depth/camera_info</depthImageCameraInfoTopicName>
            <frameName>camera_depth_optical_frame</frameName>
            <pointCloudCutoff>0.3</pointCloudCutoff>
            <distortion_k1>0.0</distortion_k1>
            <distortion_k2>0.0</distortion_k2>
            <distortion_k3>0.0</distortion_k3>
            <distortion_t1>0.0</distortion_t1>
            <distortion_t2>0.0</distortion_t2>
            <robotNamespace>/</robotNamespace>
          </plugin>
          <pose>0 0 0 0 -0 0</pose>
        </sensor>
        <self_collide>0</self_collide>
        <enable_wind>0</enable_wind>
        <kinematic>0</kinematic>
      </link>
      <joint name='world_joint' type='fixed'>
        <pose relative_to='__model__'>0 0 0 0 -0 0</pose>
        <parent>world</parent>
        <child>base_link</child>
      </joint>
      <link name='base_link'>
        <pose relative_to='world_joint'>0 0 0 0 -0 0</pose>
        <inertial>
          <pose>0 0 0 0 -0 0</pose>
          <mass>4</mass>
          <inertia>
            <ixx>0.00443333</ixx>
            <ixy>0</ixy>
            <ixz>0</ixz>
            <iyy>0.00443333</iyy>
            <iyz>0</iyz>
            <izz>0.0072</izz>
          </inertia>
        </inertial>
        <collision name='base_link_collision'>
          <pose>0 0 0 0 -0 0</pose>
          <geometry>
            <mesh>
              <scale>1 1 1</scale>
              <uri>/home/dylan/catkin_ws/src/universal_robot/ur_description/meshes/ur5/collision/base.stl</uri>
            </mesh>
          </geometry>
          <max_contacts>10</max_contacts>
          <surface>
            <contact>
              <ode/>
            </contact>
            <bounce/>
            <friction>
              <torsional>
                <ode/>
              </torsional>
              <ode/>
            </friction>
          </surface>
        </collision>
        <visual name='base_link_visual'>
          <pose>0 0 0 0 -0 0</pose>
          <geometry>
            <mesh>
              <scale>1 1 1</scale>
              <uri>/home/dylan/catkin_ws/src/universal_robot/ur_description/meshes/ur5/visual/base.dae</uri>
            </mesh>
          </geometry>
        </visual>
        <self_collide>0</self_collide>
        <enable_wind>0</enable_wind>
        <kinematic>0</kinematic>
      </link>
      <joint name='shoulder_pan_joint' type='revolute'>
        <pose relative_to='base_link'>0 0 0.089159 0 -0 0</pose>
        <parent>base_link</parent>
        <child>shoulder_link</child>
        <axis>
          <xyz>0 0 1</xyz>
          <limit>
            <lower>-3.14159</lower>
            <upper>3.14159</upper>
            <effort>150</effort>
            <velocity>3.15</velocity>
          </limit>
          <dynamics>
            <damping>0</damping>
            <friction>0</friction>
            <spring_reference>0</spring_reference>
            <spring_stiffness>0</spring_stiffness>
          </dynamics>
        </axis>
      </joint>
      <link name='shoulder_link'>
        <pose relative_to='shoulder_pan_joint'>0 0 0 0 -0 0</pose>
        <inertial>
          <pose>0 0 0 0 -0 0</pose>
          <mass>3.7</mass>
          <inertia>
            <ixx>0.0102675</ixx>
            <ixy>0</ixy>
            <ixz>0</ixz>
            <iyy>0.0102675</iyy>
            <iyz>0</iyz>
            <izz>0.00666</izz>
          </inertia>
        </inertial>
        <collision name='shoulder_link_collision'>
          <pose>0 0 0 0 -0 0</pose>
          <geometry>
            <mesh>
              <scale>1 1 1</scale>
              <uri>/home/dylan/catkin_ws/src/universal_robot/ur_description/meshes/ur5/collision/shoulder.stl</uri>
            </mesh>
          </geometry>
          <surface>
            <contact>
              <ode/>
            </contact>
            <friction>
              <ode/>
              <torsional>
                <ode/>
              </torsional>
            </friction>
            <bounce/>
          </surface>
          <max_contacts>10</max_contacts>
        </collision>
        <visual name='shoulder_link_visual'>
          <pose>0 0 0 0 -0 0</pose>
          <geometry>
            <mesh>
              <scale>1 1 1</scale>
              <uri>/home/dylan/catkin_ws/src/universal_robot/ur_description/meshes/ur5/visual/shoulder.dae</uri>
            </mesh>
          </geometry>
        </visual>
        <self_collide>1</self_collide>
        <enable_wind>0</enable_wind>
        <kinematic>0</kinematic>
      </link>
      <joint name='shoulder_lift_joint' type='revolute'>
        <pose relative_to='shoulder_link'>0 0.13585 0 3.14159 1.57079 3.14159</pose>
        <parent>shoulder_link</parent>
        <child>upper_arm_link</child>
        <axis>
          <xyz>0 1 0</xyz>
          <limit>
            <lower>-3.14159</lower>
            <upper>3.14159</upper>
            <effort>150</effort>
            <velocity>3.15</velocity>
          </limit>
          <dynamics>
            <damping>0</damping>
            <friction>0</friction>
            <spring_reference>0</spring_reference>
            <spring_stiffness>0</spring_stiffness>
          </dynamics>
        </axis>
      </joint>
      <link name='upper_arm_link'>
        <pose relative_to='shoulder_lift_joint'>0 0 0 0 -0 0</pose>
        <inertial>
          <pose>0 0 0.28 0 -0 0</pose>
          <mass>8.393</mass>
          <inertia>
            <ixx>0.226891</ixx>
            <ixy>0</ixy>
            <ixz>0</ixz>
            <iyy>0.226891</iyy>
            <iyz>0</iyz>
            <izz>0.0151074</izz>
          </inertia>
        </inertial>
        <collision name='upper_arm_link_collision'>
          <pose>0 0 0 0 -0 0</pose>
          <geometry>
            <mesh>
              <scale>1 1 1</scale>
              <uri>/home/dylan/catkin_ws/src/universal_robot/ur_description/meshes/ur5/collision/upperarm.stl</uri>
            </mesh>
          </geometry>
          <surface>
            <contact>
              <ode/>
            </contact>
            <friction>
              <ode/>
              <torsional>
                <ode/>
              </torsional>
            </friction>
            <bounce/>
          </surface>
          <max_contacts>10</max_contacts>
        </collision>
        <visual name='upper_arm_link_visual'>
          <pose>0 0 0 0 -0 0</pose>
          <geometry>
            <mesh>
              <scale>1 1 1</scale>
              <uri>/home/dylan/catkin_ws/src/universal_robot/ur_description/meshes/ur5/visual/upperarm.dae</uri>
            </mesh>
          </geometry>
        </visual>
        <self_collide>1</self_collide>
        <enable_wind>0</enable_wind>
        <kinematic>0</kinematic>
      </link>
      <joint name='elbow_joint' type='revolute'>
        <pose relative_to='upper_arm_link'>0 -0.1197 0.425 0 -0 0</pose>
        <parent>upper_arm_link</parent>
        <child>forearm_link</child>
        <axis>
          <xyz>0 1 0</xyz>
          <limit>
            <lower>-3.14159</lower>
            <upper>3.14159</upper>
            <effort>150</effort>
            <velocity>3.15</velocity>
          </limit>
          <dynamics>
            <damping>0</damping>
            <friction>0</friction>
            <spring_reference>0</spring_reference>
            <spring_stiffness>0</spring_stiffness>
          </dynamics>
        </axis>
      </joint>
      <link name='forearm_link'>
        <pose relative_to='elbow_joint'>0 0 0 0 -0 0</pose>
        <inertial>
          <pose>0 0 0.196125 0 -0 0</pose>
          <mass>2.275</mass>
          <inertia>
            <ixx>0.0312168</ixx>
            <ixy>0</ixy>
            <ixz>0</ixz>
            <iyy>0.0312168</iyy>
            <iyz>0</iyz>
            <izz>0.004095</izz>
          </inertia>
        </inertial>
        <collision name='forearm_link_collision'>
          <pose>0 0 0 0 -0 0</pose>
          <geometry>
            <mesh>
              <scale>1 1 1</scale>
              <uri>/home/dylan/catkin_ws/src/universal_robot/ur_description/meshes/ur5/collision/forearm.stl</uri>
            </mesh>
          </geometry>
          <surface>
            <contact>
              <ode/>
            </contact>
            <friction>
              <ode/>
              <torsional>
                <ode/>
              </torsional>
            </friction>
            <bounce/>
          </surface>
          <max_contacts>10</max_contacts>
        </collision>
        <visual name='forearm_link_visual'>
          <pose>0 0 0 0 -0 0</pose>
          <geometry>
            <mesh>
              <scale>1 1 1</scale>
              <uri>/home/dylan/catkin_ws/src/universal_robot/ur_description/meshes/ur5/visual/forearm.dae</uri>
            </mesh>
          </geometry>
        </visual>
        <self_collide>1</self_collide>
        <enable_wind>0</enable_wind>
        <kinematic>0</kinematic>
      </link>
      <joint name='wrist_1_joint' type='revolute'>
        <pose relative_to='forearm_link'>0 0 0.39225 3.14159 1.57079 3.14159</pose>
        <parent>forearm_link</parent>
        <child>wrist_1_link</child>
        <axis>
          <xyz>0 1 0</xyz>
          <limit>
            <lower>-3.14159</lower>
            <upper>3.14159</upper>
            <effort>28</effort>
            <velocity>3.2</velocity>
          </limit>
          <dynamics>
            <damping>0</damping>
            <friction>0</friction>
            <spring_reference>0</spring_reference>
            <spring_stiffness>0</spring_stiffness>
          </dynamics>
        </axis>
      </joint>
      <link name='wrist_1_link'>
        <pose relative_to='wrist_1_joint'>0 0 0 0 -0 0</pose>
        <inertial>
          <pose>0 0.093 0 0 -0 0</pose>
          <mass>1.219</mass>
          <inertia>
            <ixx>0.0025599</ixx>
            <ixy>0</ixy>
            <ixz>0</ixz>
            <iyy>0.0025599</iyy>
            <iyz>0</iyz>
            <izz>0.0021942</izz>
          </inertia>
        </inertial>
        <collision name='wrist_1_link_collision'>
          <pose>0 0 0 0 -0 0</pose>
          <geometry>
            <mesh>
              <scale>1 1 1</scale>
              <uri>/home/dylan/catkin_ws/src/universal_robot/ur_description/meshes/ur5/collision/wrist1.stl</uri>
            </mesh>
          </geometry>
          <surface>
            <contact>
              <ode/>
            </contact>
            <friction>
              <ode/>
              <torsional>
                <ode/>
              </torsional>
            </friction>
            <bounce/>
          </surface>
          <max_contacts>10</max_contacts>
        </collision>
        <visual name='wrist_1_link_visual'>
          <pose>0 0 0 0 -0 0</pose>
          <geometry>
            <mesh>
              <scale>1 1 1</scale>
              <uri>/home/dylan/catkin_ws/src/universal_robot/ur_description/meshes/ur5/visual/wrist1.dae</uri>
            </mesh>
          </geometry>
        </visual>
        <self_collide>1</self_collide>
        <enable_wind>0</enable_wind>
        <kinematic>0</kinematic>
      </link>
      <joint name='wrist_2_joint' type='revolute'>
        <pose relative_to='wrist_1_link'>0 0.093 0 0 -0 0</pose>
        <parent>wrist_1_link</parent>
        <child>wrist_2_link</child>
        <axis>
          <xyz>0 0 1</xyz>
          <limit>
            <lower>-3.14159</lower>
            <upper>3.14159</upper>
            <effort>28</effort>
            <velocity>3.2</velocity>
          </limit>
          <dynamics>
            <damping>0</damping>
            <friction>0</friction>
            <spring_reference>0</spring_reference>
            <spring_stiffness>0</spring_stiffness>
          </dynamics>
        </axis>
      </joint>
      <link name='wrist_2_link'>
        <pose relative_to='wrist_2_joint'>0 0 0 0 -0 0</pose>
        <inertial>
          <pose>0 0 0.09465 0 -0 0</pose>
          <mass>1.219</mass>
          <inertia>
            <ixx>0.0025599</ixx>
            <ixy>0</ixy>
            <ixz>0</ixz>
            <iyy>0.0025599</iyy>
            <iyz>0</iyz>
            <izz>0.0021942</izz>
          </inertia>
        </inertial>
        <collision name='wrist_2_link_collision'>
          <pose>0 0 0 0 -0 0</pose>
          <geometry>
            <mesh>
              <scale>1 1 1</scale>
              <uri>/home/dylan/catkin_ws/src/universal_robot/ur_description/meshes/ur5/collision/wrist2.stl</uri>
            </mesh>
          </geometry>
          <surface>
            <contact>
              <ode/>
            </contact>
            <friction>
              <ode/>
              <torsional>
                <ode/>
              </torsional>
            </friction>
            <bounce/>
          </surface>
          <max_contacts>10</max_contacts>
        </collision>
        <visual name='wrist_2_link_visual'>
          <pose>0 0 0 0 -0 0</pose>
          <geometry>
            <mesh>
              <scale>1 1 1</scale>
              <uri>/home/dylan/catkin_ws/src/universal_robot/ur_description/meshes/ur5/visual/wrist2.dae</uri>
            </mesh>
          </geometry>
        </visual>
        <self_collide>1</self_collide>
        <enable_wind>0</enable_wind>
        <kinematic>0</kinematic>
      </link>
      <joint name='wrist_3_joint' type='revolute'>
        <pose relative_to='wrist_2_link'>0 0 0.09465 0 -0 0</pose>
        <parent>wrist_2_link</parent>
        <child>wrist_3_link</child>
        <axis>
          <xyz>0 1 0</xyz>
          <limit>
            <lower>-3.14159</lower>
            <upper>3.14159</upper>
            <effort>28</effort>
            <velocity>3.2</velocity>
          </limit>
          <dynamics>
            <damping>0</damping>
            <friction>0</friction>
            <spring_reference>0</spring_reference>
            <spring_stiffness>0</spring_stiffness>
          </dynamics>
        </axis>
        <physics>
          <provide_feedback>1</provide_feedback>
          <ode>
            <limit>
              <cfm>0</cfm>
              <erp>0.2</erp>
            </limit>
            <provide_feedback>1</provide_feedback>
          </ode>
        </physics>
      </joint>
      <link name='wrist_3_link'>
        <pose relative_to='wrist_3_joint'>0 0 0 0 -0 0</pose>
        <inertial>
          <pose>0.000246 0.084658 4e-06 1.5708 -0 0</pose>
          <mass>0.992851</mass>
          <inertia>
            <ixx>0.00136577</ixx>
            <ixy>1.01149e-09</ixy>
            <ixz>-4.09903e-07</ixz>
            <iyy>0.00141553</iyy>
            <iyz>2.93103e-08</iyz>
            <izz>0.000654232</izz>
          </inertia>
        </inertial>
        <collision name='wrist_3_link_collision'>
          <pose>0 0 0 0 -0 0</pose>
          <geometry>
            <mesh>
              <scale>1 1 1</scale>
              <uri>/home/dylan/catkin_ws/src/universal_robot/ur_description/meshes/ur5/collision/wrist3.stl</uri>
            </mesh>
          </geometry>
          <surface>
            <contact>
              <ode/>
            </contact>
            <friction>
              <ode/>
              <torsional>
                <ode/>
              </torsional>
            </friction>
            <bounce/>
          </surface>
          <max_contacts>10</max_contacts>
        </collision>
        <collision name='wrist_3_link_fixed_joint_lump__ee_link_collision_1'>
          <pose>-0 0.0723 0 0 -0 1.5708</pose>
          <geometry>
            <box>
              <size>0.01 0.01 0.01</size>
            </box>
          </geometry>
          <surface>
            <contact>
              <ode/>
            </contact>
            <friction>
              <ode/>
              <torsional>
                <ode/>
              </torsional>
            </friction>
            <bounce/>
          </surface>
          <max_contacts>10</max_contacts>
        </collision>
        <collision name='wrist_3_link_fixed_joint_lump__robotiq_coupler_collision_2'>
          <pose>0 0.0863 0 1.57079 -1.57079 3.14159</pose>
          <geometry>
            <mesh>
              <scale>1 1 1</scale>
              <uri>/home/dylan/catkin_ws/src/robotiq/robotiq_description/meshes/robotiq_85_coupler.stl</uri>
            </mesh>
          </geometry>
          <surface>
            <contact>
              <ode/>
            </contact>
            <friction>
              <ode>
                <mu>0.9</mu>
                <mu2>0.9</mu2>
              </ode>
              <torsional>
                <ode/>
              </torsional>
            </friction>
            <bounce/>
          </surface>
          <max_contacts>10</max_contacts>
        </collision>
        <collision name='wrist_3_link_fixed_joint_lump__robotiq_85_base_link_collision_3'>
          <pose>0 0.0903 0 0 -0 1.5708</pose>
          <geometry>
            <mesh>
              <scale>1 1 1</scale>
              <uri>/home/dylan/catkin_ws/src/robotiq/robotiq_description/meshes/collision/robotiq_85_base_link.stl</uri>
            </mesh>
          </geometry>
          <max_contacts>10</max_contacts>
          <surface>
            <contact>
              <ode/>
            </contact>
            <bounce/>
            <friction>
              <torsional>
                <ode/>
              </torsional>
              <ode/>
            </friction>
          </surface>
        </collision>
        <visual name='wrist_3_link_visual'>
          <pose>0 0 0 0 -0 0</pose>
          <geometry>
            <mesh>
              <scale>1 1 1</scale>
              <uri>/home/dylan/catkin_ws/src/universal_robot/ur_description/meshes/ur5/visual/wrist3.dae</uri>
            </mesh>
          </geometry>
        </visual>
        <visual name='wrist_3_link_fixed_joint_lump__robotiq_coupler_visual_1'>
          <pose>0 0.0863 0 1.57079 -1.57079 3.14159</pose>
          <geometry>
            <mesh>
              <scale>1 1 1</scale>
              <uri>/home/dylan/catkin_ws/src/robotiq/robotiq_description/meshes/robotiq_85_coupler.stl</uri>
            </mesh>
          </geometry>
          <material>
            <script>
              <name>Gazebo/FlatBlack</name>
              <uri>file://media/materials/scripts/gazebo.material</uri>
            </script>
          </material>
        </visual>
        <visual name='wrist_3_link_fixed_joint_lump__robotiq_85_base_link_visual_2'>
          <pose>0 0.0903 0 0 -0 1.5708</pose>
          <geometry>
            <mesh>
              <scale>1 1 1</scale>
              <uri>/home/dylan/catkin_ws/src/robotiq/robotiq_description/meshes/visual/robotiq_85_base_link.dae</uri>
            </mesh>
          </geometry>
        </visual>
        <self_collide>1</self_collide>
        <enable_wind>0</enable_wind>
        <kinematic>0</kinematic>
      </link>
      <joint name='robotiq_85_left_inner_knuckle_joint' type='revolute'>
        <pose relative_to='wrist_3_link'>-0.0127 0.15172 0 3.14159 -0 1.5708</pose>
        <parent>wrist_3_link</parent>
        <child>robotiq_85_left_inner_knuckle_link</child>
        <axis>
          <xyz>0 0 1</xyz>
          <limit>
            <effort>0.1</effort>
            <velocity>100</velocity>
            <lower>-1e+16</lower>
            <upper>1e+16</upper>
          </limit>
          <dynamics>
            <spring_reference>0</spring_reference>
            <spring_stiffness>0</spring_stiffness>
          </dynamics>
        </axis>
      </joint>
      <link name='robotiq_85_left_inner_knuckle_link'>
        <pose relative_to='robotiq_85_left_inner_knuckle_joint'>0 0 0 0 -0 0</pose>
        <inertial>
          <pose>0 0 0 0 -0 0</pose>
          <mass>0.029951</mass>
          <inertia>
            <ixx>3.9e-05</ixx>
            <ixy>0</ixy>
            <ixz>0</ixz>
            <iyy>5e-06</iyy>
            <iyz>0</iyz>
            <izz>3.5e-05</izz>
          </inertia>
        </inertial>
        <collision name='robotiq_85_left_inner_knuckle_link_collision'>
          <pose>0 0 0 0 -0 0</pose>
          <geometry>
            <mesh>
              <scale>1 1 1</scale>
              <uri>/home/dylan/catkin_ws/src/robotiq/robotiq_description/meshes/collision/robotiq_85_inner_knuckle_link.stl</uri>
            </mesh>
          </geometry>
          <max_contacts>10</max_contacts>
          <surface>
            <contact>
              <ode/>
            </contact>
            <bounce/>
            <friction>
              <torsional>
                <ode/>
              </torsional>
              <ode/>
            </friction>
          </surface>
        </collision>
        <visual name='robotiq_85_left_inner_knuckle_link_visual'>
          <pose>0 0 0 0 -0 0</pose>
          <geometry>
            <mesh>
              <scale>1 1 1</scale>
              <uri>/home/dylan/catkin_ws/src/robotiq/robotiq_description/meshes/visual/robotiq_85_inner_knuckle_link.dae</uri>
            </mesh>
          </geometry>
        </visual>
        <self_collide>0</self_collide>
        <enable_wind>0</enable_wind>
        <kinematic>0</kinematic>
      </link>
      <joint name='robotiq_85_left_finger_tip_joint' type='revolute'>
        <pose relative_to='robotiq_85_left_inner_knuckle_link'>0.04304 -0.037599 0 0 -0 0</pose>
        <parent>robotiq_85_left_inner_knuckle_link</parent>
        <child>robotiq_85_left_finger_tip_link</child>
        <axis>
          <xyz>0 0 1</xyz>
          <limit>
            <effort>0.1</effort>
            <velocity>100</velocity>
            <lower>-1e+16</lower>
            <upper>1e+16</upper>
          </limit>
          <dynamics>
            <spring_reference>0</spring_reference>
            <spring_stiffness>0</spring_stiffness>
          </dynamics>
        </axis>
      </joint>
      <link name='robotiq_85_left_finger_tip_link'>
        <pose relative_to='robotiq_85_left_finger_tip_joint'>0 0 0 0 -0 0</pose>
        <inertial>
          <pose>0 0 0 0 -0 0</pose>
          <mass>0.019555</mass>
          <inertia>
            <ixx>2e-06</ixx>
            <ixy>0</ixy>
            <ixz>0</ixz>
            <iyy>5e-06</iyy>
            <iyz>0</iyz>
            <izz>6e-06</izz>
          </inertia>
        </inertial>
        <collision name='robotiq_85_left_finger_tip_link_collision'>
          <pose>0 0 0 0 -0 0</pose>
          <geometry>
            <mesh>
              <scale>1 1 1</scale>
              <uri>/home/dylan/catkin_ws/src/robotiq/robotiq_description/meshes/collision/robotiq_85_finger_tip_link.stl</uri>
            </mesh>
          </geometry>
          <surface>
            <contact>
              <ode>
                <kp>1e+06</kp>
                <kd>1</kd>
                <min_depth>0.001</min_depth>
              </ode>
            </contact>
            <friction>
              <ode>
                <mu>1</mu>
                <mu2>1</mu2>
              </ode>
              <torsional>
                <ode/>
              </torsional>
            </friction>
            <bounce/>
          </surface>
          <max_contacts>10</max_contacts>
        </collision>
        <visual name='robotiq_85_left_finger_tip_link_visual'>
          <pose>0 0 0 0 -0 0</pose>
          <geometry>
            <mesh>
              <scale>1 1 1</scale>
              <uri>/home/dylan/catkin_ws/src/robotiq/robotiq_description/meshes/visual/robotiq_85_finger_tip_link.dae</uri>
            </mesh>
          </geometry>
        </visual>
        <self_collide>0</self_collide>
        <enable_wind>0</enable_wind>
        <kinematic>0</kinematic>
      </link>
      <joint name='robotiq_85_left_knuckle_joint' type='revolute'>
        <pose relative_to='wrist_3_link'>-0.030601 0.145205 0 3.14159 -0 1.5708</pose>
        <parent>wrist_3_link</parent>
        <child>robotiq_85_left_knuckle_link</child>
        <axis>
          <xyz>0 0 1</xyz>
          <limit>
            <lower>0</lower>
            <upper>0.80285</upper>
            <effort>1000</effort>
            <velocity>0.5</velocity>
          </limit>
          <dynamics>
            <spring_reference>0</spring_reference>
            <spring_stiffness>0</spring_stiffness>
          </dynamics>
        </axis>
      </joint>
      <link name='robotiq_85_left_knuckle_link'>
        <pose relative_to='robotiq_85_left_knuckle_joint'>0 0 0 0 -0 0</pose>
        <inertial>
          <pose>-0.002436 -0.018774 0 0 -0 0</pose>
          <mass>0.0458</mass>
          <inertia>
            <ixx>2.29304e-05</ixx>
            <ixy>-4.4183e-06</ixy>
            <ixz>0</ixz>
            <iyy>2.2184e-05</iyy>
            <iyz>0</iyz>
            <izz>4.11145e-05</izz>
          </inertia>
        </inertial>
        <collision name='robotiq_85_left_knuckle_link_collision'>
          <pose>0 0 0 0 -0 0</pose>
          <geometry>
            <mesh>
              <scale>1 1 1</scale>
              <uri>/home/dylan/catkin_ws/src/robotiq/robotiq_description/meshes/collision/robotiq_85_knuckle_link.stl</uri>
            </mesh>
          </geometry>
          <max_contacts>10</max_contacts>
          <surface>
            <contact>
              <ode/>
            </contact>
            <bounce/>
            <friction>
              <torsional>
                <ode/>
              </torsional>
              <ode/>
            </friction>
          </surface>
        </collision>
        <collision name='robotiq_85_left_knuckle_link_fixed_joint_lump__robotiq_85_left_finger_link_collision_1'>
          <pose>-0.004086 -0.031486 0 0 -0 0</pose>
          <geometry>
            <mesh>
              <scale>1 1 1</scale>
              <uri>/home/dylan/catkin_ws/src/robotiq/robotiq_description/meshes/collision/robotiq_85_finger_link.stl</uri>
            </mesh>
          </geometry>
          <max_contacts>10</max_contacts>
          <surface>
            <contact>
              <ode/>
            </contact>
            <bounce/>
            <friction>
              <torsional>
                <ode/>
              </torsional>
              <ode/>
            </friction>
          </surface>
        </collision>
        <visual name='robotiq_85_left_knuckle_link_visual'>
          <pose>0 0 0 0 -0 0</pose>
          <geometry>
            <mesh>
              <scale>1 1 1</scale>
              <uri>/home/dylan/catkin_ws/src/robotiq/robotiq_description/meshes/visual/robotiq_85_knuckle_link.dae</uri>
            </mesh>
          </geometry>
        </visual>
        <visual name='robotiq_85_left_knuckle_link_fixed_joint_lump__robotiq_85_left_finger_link_visual_1'>
          <pose>-0.004086 -0.031486 0 0 -0 0</pose>
          <geometry>
            <mesh>
              <scale>1 1 1</scale>
              <uri>/home/dylan/catkin_ws/src/robotiq/robotiq_description/meshes/visual/robotiq_85_finger_link.dae</uri>
            </mesh>
          </geometry>
        </visual>
        <self_collide>0</self_collide>
        <enable_wind>0</enable_wind>
        <kinematic>0</kinematic>
      </link>
      <joint name='robotiq_85_right_inner_knuckle_joint' type='revolute'>
        <pose relative_to='wrist_3_link'>0.0127 0.15172 0 0 -0 1.5708</pose>
        <parent>wrist_3_link</parent>
        <child>robotiq_85_right_inner_knuckle_link</child>
        <axis>
          <xyz>0 0 1</xyz>
          <limit>
            <effort>0.1</effort>
            <velocity>100</velocity>
            <lower>-1e+16</lower>
            <upper>1e+16</upper>
          </limit>
          <dynamics>
            <spring_reference>0</spring_reference>
            <spring_stiffness>0</spring_stiffness>
          </dynamics>
        </axis>
      </joint>
      <link name='robotiq_85_right_inner_knuckle_link'>
        <pose relative_to='robotiq_85_right_inner_knuckle_joint'>0 0 0 0 -0 0</pose>
        <inertial>
          <pose>0 0 0 0 -0 0</pose>
          <mass>0.029951</mass>
          <inertia>
            <ixx>3.9e-05</ixx>
            <ixy>0</ixy>
            <ixz>0</ixz>
            <iyy>5e-06</iyy>
            <iyz>0</iyz>
            <izz>3.5e-05</izz>
          </inertia>
        </inertial>
        <collision name='robotiq_85_right_inner_knuckle_link_collision'>
          <pose>0 0 0 0 -0 0</pose>
          <geometry>
            <mesh>
              <scale>1 1 1</scale>
              <uri>/home/dylan/catkin_ws/src/robotiq/robotiq_description/meshes/collision/robotiq_85_inner_knuckle_link.stl</uri>
            </mesh>
          </geometry>
          <max_contacts>10</max_contacts>
          <surface>
            <contact>
              <ode/>
            </contact>
            <bounce/>
            <friction>
              <torsional>
                <ode/>
              </torsional>
              <ode/>
            </friction>
          </surface>
        </collision>
        <visual name='robotiq_85_right_inner_knuckle_link_visual'>
          <pose>0 0 0 0 -0 0</pose>
          <geometry>
            <mesh>
              <scale>1 1 1</scale>
              <uri>/home/dylan/catkin_ws/src/robotiq/robotiq_description/meshes/visual/robotiq_85_inner_knuckle_link.dae</uri>
            </mesh>
          </geometry>
        </visual>
        <self_collide>0</self_collide>
        <enable_wind>0</enable_wind>
        <kinematic>0</kinematic>
      </link>
      <joint name='robotiq_85_right_finger_tip_joint' type='revolute'>
        <pose relative_to='robotiq_85_right_inner_knuckle_link'>0.04304 -0.037599 0 0 -0 0</pose>
        <parent>robotiq_85_right_inner_knuckle_link</parent>
        <child>robotiq_85_right_finger_tip_link</child>
        <axis>
          <xyz>0 0 1</xyz>
          <limit>
            <effort>0.1</effort>
            <velocity>100</velocity>
            <lower>-1e+16</lower>
            <upper>1e+16</upper>
          </limit>
          <dynamics>
            <spring_reference>0</spring_reference>
            <spring_stiffness>0</spring_stiffness>
          </dynamics>
        </axis>
      </joint>
      <link name='robotiq_85_right_finger_tip_link'>
        <pose relative_to='robotiq_85_right_finger_tip_joint'>0 0 0 0 -0 0</pose>
        <inertial>
          <pose>0 0 0 0 -0 0</pose>
          <mass>0.019555</mass>
          <inertia>
            <ixx>2e-06</ixx>
            <ixy>0</ixy>
            <ixz>0</ixz>
            <iyy>5e-06</iyy>
            <iyz>0</iyz>
            <izz>6e-06</izz>
          </inertia>
        </inertial>
        <collision name='robotiq_85_right_finger_tip_link_collision'>
          <pose>0 0 0 0 -0 0</pose>
          <geometry>
            <mesh>
              <scale>1 1 1</scale>
              <uri>/home/dylan/catkin_ws/src/robotiq/robotiq_description/meshes/collision/robotiq_85_finger_tip_link.stl</uri>
            </mesh>
          </geometry>
          <surface>
            <contact>
              <ode>
                <kp>1e+06</kp>
                <kd>1</kd>
                <min_depth>0.001</min_depth>
              </ode>
            </contact>
            <friction>
              <ode>
                <mu>1</mu>
                <mu2>1</mu2>
              </ode>
              <torsional>
                <ode/>
              </torsional>
            </friction>
            <bounce/>
          </surface>
          <max_contacts>10</max_contacts>
        </collision>
        <visual name='robotiq_85_right_finger_tip_link_visual'>
          <pose>0 0 0 0 -0 0</pose>
          <geometry>
            <mesh>
              <scale>1 1 1</scale>
              <uri>/home/dylan/catkin_ws/src/robotiq/robotiq_description/meshes/visual/robotiq_85_finger_tip_link.dae</uri>
            </mesh>
          </geometry>
        </visual>
        <self_collide>0</self_collide>
        <enable_wind>0</enable_wind>
        <kinematic>0</kinematic>
      </link>
      <joint name='robotiq_85_right_knuckle_joint' type='revolute'>
        <pose relative_to='wrist_3_link'>0.030601 0.145205 0 0 -0 1.5708</pose>
        <parent>wrist_3_link</parent>
        <child>robotiq_85_right_knuckle_link</child>
        <axis>
          <xyz>0 0 1</xyz>
          <limit>
            <effort>1000</effort>
            <velocity>100</velocity>
            <lower>-1e+16</lower>
            <upper>1e+16</upper>
          </limit>
          <dynamics>
            <spring_reference>0</spring_reference>
            <spring_stiffness>0</spring_stiffness>
          </dynamics>
        </axis>
      </joint>
      <link name='robotiq_85_right_knuckle_link'>
        <pose relative_to='robotiq_85_right_knuckle_joint'>0 0 0 0 -0 0</pose>
        <inertial>
          <pose>-0.002436 -0.018774 0 0 -0 0</pose>
          <mass>0.0458</mass>
          <inertia>
            <ixx>2.29304e-05</ixx>
            <ixy>-4.4183e-06</ixy>
            <ixz>0</ixz>
            <iyy>2.2184e-05</iyy>
            <iyz>0</iyz>
            <izz>4.11145e-05</izz>
          </inertia>
        </inertial>
        <collision name='robotiq_85_right_knuckle_link_collision'>
          <pose>0 0 0 0 -0 0</pose>
          <geometry>
            <mesh>
              <scale>1 1 1</scale>
              <uri>/home/dylan/catkin_ws/src/robotiq/robotiq_description/meshes/collision/robotiq_85_knuckle_link.stl</uri>
            </mesh>
          </geometry>
          <max_contacts>10</max_contacts>
          <surface>
            <contact>
              <ode/>
            </contact>
            <bounce/>
            <friction>
              <torsional>
                <ode/>
              </torsional>
              <ode/>
            </friction>
          </surface>
        </collision>
        <collision name='robotiq_85_right_knuckle_link_fixed_joint_lump__robotiq_85_right_finger_link_collision_1'>
          <pose>-0.004086 -0.031486 0 0 -0 0</pose>
          <geometry>
            <mesh>
              <scale>1 1 1</scale>
              <uri>/home/dylan/catkin_ws/src/robotiq/robotiq_description/meshes/collision/robotiq_85_finger_link.stl</uri>
            </mesh>
          </geometry>
          <max_contacts>10</max_contacts>
          <surface>
            <contact>
              <ode/>
            </contact>
            <bounce/>
            <friction>
              <torsional>
                <ode/>
              </torsional>
              <ode/>
            </friction>
          </surface>
        </collision>
        <visual name='robotiq_85_right_knuckle_link_visual'>
          <pose>0 0 0 0 -0 0</pose>
          <geometry>
            <mesh>
              <scale>1 1 1</scale>
              <uri>/home/dylan/catkin_ws/src/robotiq/robotiq_description/meshes/visual/robotiq_85_knuckle_link.dae</uri>
            </mesh>
          </geometry>
        </visual>
        <visual name='robotiq_85_right_knuckle_link_fixed_joint_lump__robotiq_85_right_finger_link_visual_1'>
          <pose>-0.004086 -0.031486 0 0 -0 0</pose>
          <geometry>
            <mesh>
              <scale>1 1 1</scale>
              <uri>/home/dylan/catkin_ws/src/robotiq/robotiq_description/meshes/visual/robotiq_85_finger_link.dae</uri>
            </mesh>
          </geometry>
        </visual>
        <self_collide>0</self_collide>
        <enable_wind>0</enable_wind>
        <kinematic>0</kinematic>
      </link>
      <plugin name='ros_control' filename='libgazebo_ros_control.so'>
        <robotNamespace>/</robotNamespace>
      </plugin>
      <plugin name='mimic_robotiq_85_1' filename='libgazebo_mimic_joint_plugin.so'>
        <joint>robotiq_85_left_knuckle_joint</joint>
        <mimicJoint>robotiq_85_right_knuckle_joint</mimicJoint>
        <robotNamespace>/</robotNamespace>
      </plugin>
      <plugin name='mimic_robotiq_85_2' filename='libgazebo_mimic_joint_plugin.so'>
        <joint>robotiq_85_left_knuckle_joint</joint>
        <mimicJoint>robotiq_85_left_inner_knuckle_joint</mimicJoint>
        <robotNamespace>/</robotNamespace>
      </plugin>
      <plugin name='mimic_robotiq_85_3' filename='libgazebo_mimic_joint_plugin.so'>
        <joint>robotiq_85_left_knuckle_joint</joint>
        <mimicJoint>robotiq_85_right_inner_knuckle_joint</mimicJoint>
        <robotNamespace>/</robotNamespace>
      </plugin>
      <plugin name='mimic_robotiq_85_4' filename='libgazebo_mimic_joint_plugin.so'>
        <joint>robotiq_85_left_knuckle_joint</joint>
        <mimicJoint>robotiq_85_left_finger_tip_joint</mimicJoint>
        <multiplier>-1.0</multiplier>
        <offset>0.0</offset>
        <robotNamespace>/</robotNamespace>
      </plugin>
      <plugin name='mimic_robotiq_85_5' filename='libgazebo_mimic_joint_plugin.so'>
        <joint>robotiq_85_left_knuckle_joint</joint>
        <mimicJoint>robotiq_85_right_finger_tip_joint</mimicJoint>
        <multiplier>-1.0</multiplier>
        <offset>0.0</offset>
        <robotNamespace>/</robotNamespace>
      </plugin>
      <plugin name='ft_sensor_plugin' filename='libgazebo_ros_ft_sensor.so'>
        <updateRate>250.0</updateRate>
        <topicName>ft_sensor/raw</topicName>
        <gaussianNoise>0.0</gaussianNoise>
        <jointName>wrist_3_joint</jointName>
        <robotNamespace>/</robotNamespace>
      </plugin>
      <static>0</static>
      <gripper name='gazebo_gripper'>
        <grasp_check>
          <attach_steps>2</attach_steps>
          <detach_steps>2</detach_steps>
          <min_contact_count>3</min_contact_count>
        </grasp_check>
        <gripper_link>robotiq_85_left_finger_tip_link</gripper_link>
        <gripper_link>robotiq_85_right_finger_tip_link</gripper_link>
        <palm_link>wrist_3_link</palm_link>
      </gripper>
      <pose>0 0 1.21 0 -0 0</pose>
    </model>
    <model name='phillips_screwdriver'>
      <static>0</static>
      <link name='link'>
        <inertial>
          <pose>0.002663 0.022224 0.016372 1.65222 -1.00568 -1.17449</pose>
          <mass>7.70055e-05</mass>
          <inertia>
            <ixx>1.08681e-07</ixx>
            <ixy>-8.47264e-24</ixy>
            <ixz>4.22641e-24</ixz>
            <iyy>1.08634e-07</iyy>
            <iyz>-1.00542e-23</iyz>
            <izz>8.53822e-09</izz>
          </inertia>
        </inertial>
        <collision name='collision'>
          <geometry>
            <mesh>
              <uri>model://043_phillips_screwdriver/google_16k/textured.obj</uri>
            </mesh>
          </geometry>
          <surface>
            <contact>
              <ode/>
            </contact>
            <bounce/>
            <friction>
              <torsional>
                <ode/>
              </torsional>
              <ode/>
            </friction>
          </surface>
          <max_contacts>10</max_contacts>
        </collision>
        <visual name='visual'>
          <geometry>
            <mesh>
              <uri>model://043_phillips_screwdriver/google_16k/textured.obj</uri>
            </mesh>
          </geometry>
          <material>
            <script>
              <uri>model://043_phillips_screwdriver/phillips_screwdriver.material</uri>
              <name>phillips_screwdriver</name>
            </script>
          </material>
        </visual>
        <self_collide>0</self_collide>
        <enable_wind>0</enable_wind>
        <kinematic>0</kinematic>
      </link>
      <pose>-0.237107 0.645908 0 0 -0 0</pose>
    </model>
  </world>
</sdf>
